Workbook
Name _10A_61: #N/A
Name _10A_62: #N/A
Name _10A_63: #N/A
Name _10A_64: #N/A
Name _10A_65: #N/A
Name _10A_66: #N/A
Name _10A_67: #N/A
Name _10A_68: #N/A
Name _10A_69: #N/A
Name _10A_70: #N/A
Name _10A_71: #N/A
Name _10A_72: #N/A
Name _10A_73: #N/A
Name _10A_74: #N/A
Name _10A_75: #N/A
Name _10A_76: #N/A
Name _10A_77: #N/A
Name _10A_78: #N/A
Name _10A_79: #N/A
Name _10A_80: #N/A
Name _10A_81: #N/A
Name _10A_82: #N/A
Name _10A_83: #N/A
Name _10A_84: #N/A
Name _10A_85: #N/A
Name _10A_86: #N/A
Name _10A_87: #N/A
Name _10A_88: #N/A
Name _10A_89: #N/A
Name _10A_90: #N/A
Name _10B_61: #N/A
Name _10B_62: #N/A
Name _10B_63: #N/A
Name _10B_64: #N/A
Name _10B_65: #N/A
Name _10B_66: #N/A
Name _10B_67: #N/A
Name _10B_68: #N/A
Name _10B_69: #N/A
Name _10B_70: #N/A
Name _10B_71: #N/A
Name _10B_72: #N/A
Name _10B_73: #N/A
Name _10B_74: #N/A
Name _10B_75: #N/A
Name _10B_76: #N/A
Name _10B_77: #N/A
Name _10B_78: #N/A
Name _10B_79: #N/A
Name _10B_80: #N/A
Name _10B_81: #N/A
Name _10B_82: #N/A
Name _10B_83: #N/A
Name _10B_84: #N/A
Name _10B_85: #N/A
Name _10B_86: #N/A
Name _10B_87: #N/A
Name _10B_88: #N/A
Name _10B_89: #N/A
Name _10B_90: #N/A

Sheet 운영현황
A1: 2026
A2: 2025년 운영 현황
A4: 수질 | N4: 대기
A6: 총 상수도 사용 | D6: 순수 생산량 | G6: 방류수 | J6: 총 전력 사용 | N6: CHP 가동시간 | Q6: LNG 사용량 | T6: PLB#1 가동시간 | W6: LNG 사용량
A7: =월별!R17 -> -232220 | D7: =월별!D17+월별!F17 -> 37650 | G7: =월별!P17 -> 25486 | J7: =월별!N17 -> 262.2 | N7: =월별!AF17 -> 2211 | Q7: =월별!Z17 -> 14906252 | T7: =월별!AG17 -> 0 | W7: =월별!AA17 -> 591
A8: ㎥ | D8: ㎥ | G8: ㎥ | J8: Kwh | N8: hr | Q8: N㎥ | T8: hr | W8: N㎥
A9: 💧 | D9: 💧 | G9: ♻️ | J9: ⚡ | N9: ⏰ | Q9: ⛽ | T9: ⏰ | W9: ⛽

Sheet 일일 가동현황
A1: 2026
A2: =TODAY()-2 -> 46117 | I2: 가동 현황
B4: 용수사용량 | I4: CHP | Q4: 금일 : | R4: 검정
B5: 시수 | C5: =일별!Q2 -> 17 | D5: 생황용수 | E5: =일별!I2 -> 9 | F5: 1차냉각수 | G5: =일별!K2 -> 11 | I5: 가동시간 | J5: =일별!AD2 -> 30 | K5: LNG 사용량 | L5: =일별!X2 -> 24 | M5: 열생산량 | N5: =일별!AX2 -> 50 | O5: 부하율 | P5: 45 | Q5: 작일 : | R5: 회색
B6: =VLOOKUP($A$2,일별!$A$5:$BG$370,C5,0) -> #N/A | C6: =B6-B7 -> #N/A | D6: =VLOOKUP($A$2,일별!$A$5:$BG$370,E5,0) -> #N/A | E6: =D6-D7 -> #N/A | F6: =VLOOKUP($A$2,일별!$A$5:$BG$370,G5,0) -> #N/A | G6: =F6-F7 -> #N/A | I6: =VLOOKUP($A$2,일별!$A$5:$BG$370,J5,0) -> #N/A | J6: =I6-I7 -> #N/A | K6: =VLOOKUP($A$2,일별!$A$5:$BG$370,L5,0) -> #N/A | L6: =K6-K7 -> #N/A | M6: =VLOOKUP($A$2,일별!$A$5:$BG$370,N5,0) -> #N/A | N6: =M6-M7 -> #N/A | O6: =VLOOKUP($A$2,일별!$A$5:$BG$370,P5,0) -> #N/A
B7: =VLOOKUP($A$2-1,일별!$A$5:$BG$370,C5,0) -> #N/A | D7: =VLOOKUP($A$2-1,일별!$A$5:$BG$370,E5,0) -> #N/A | F7: =VLOOKUP($A$2-1,일별!$A$5:$BG$370,G5,0) -> #N/A | I7: =VLOOKUP($A$2-1,일별!$A$5:$BG$370,J5,0) -> #N/A | K7: =VLOOKUP($A$2-1,일별!$A$5:$BG$370,L5,0) -> #N/A | M7: =VLOOKUP($A$2-1,일별!$A$5:$BG$370,N5,0) -> #N/A | O7: =VLOOKUP($A$2-1,일별!$A$5:$BG$370,P5,0) -> #N/A
B9: 순수탱크 | D9: 순수제조량 | I9: PLB#1
B10: LIT | C10: =일별!W2 -> 23 | D10: A | E10: =일별!E2 -> 5 | F10: B | G10: =일별!G2 -> 7 | I10: 가동시간 | J10: =일별!AE2 -> 31 | K10: LNG 사용량 | L10: =일별!Y2 -> 25 | M10: 열생산량 | N10: =일별!AY2 -> 51 | O10: 부하율 | P10: 47
B11: =VLOOKUP($A$2,일별!$A$5:$BG$370,C10,0) -> #N/A | C11: =B11-B12 -> #N/A | D11: =VLOOKUP($A$2,일별!$A$5:$BG$370,E10,0) -> #N/A | E11: =D11-D12 -> #N/A | F11: =VLOOKUP($A$2,일별!$A$5:$BG$370,G10,0) -> #N/A | G11: =F11-F12 -> #N/A | I11: =VLOOKUP($A$2,일별!$A$5:$BG$370,J10,0) -> #N/A | J11: =I11-I12 -> #N/A | K11: =VLOOKUP($A$2,일별!$A$5:$BG$370,L10,0) -> #N/A | L11: =K11-K12 -> #N/A | M11: =VLOOKUP($A$2,일별!$A$5:$BG$370,N10,0) -> #N/A | N11: =M11-M12 -> #N/A | O11: =VLOOKUP($A$2,일별!$A$5:$BG$370,P10,0) -> #N/A
B12: =VLOOKUP($A$2-1,일별!$A$5:$BG$370,C10,0) -> #N/A | D12: =VLOOKUP($A$2-1,일별!$A$5:$BG$370,E10,0) -> #N/A | F12: =VLOOKUP($A$2-1,일별!$A$5:$BG$370,G10,0) -> #N/A | I12: =VLOOKUP($A$2-1,일별!$A$5:$BG$370,J10,0) -> #N/A | K12: =VLOOKUP($A$2-1,일별!$A$5:$BG$370,L10,0) -> #N/A | M12: =VLOOKUP($A$2-1,일별!$A$5:$BG$370,N10,0) -> #N/A | O12: =VLOOKUP($A$2-1,일별!$A$5:$BG$370,P10,0) -> #N/A
B14: 폐수처리 | I14: PLB#2
B15: 방류수 | C15: =일별!O2 -> 15 | D15: 전력량 | E15: =일별!M2 -> 13 | I15: 가동시간 | J15: =일별!AF2 -> 32 | K15: LNG 사용량 | L15: =일별!Z2 -> 26 | M15: 열생산량 | O15: 부하율
B16: =VLOOKUP($A$2,일별!$A$5:$BG$370,C15,0) -> #N/A | C16: =B16-B17 -> #N/A | D16: =VLOOKUP($A$2,일별!$A$5:$BG$370,E15,0) -> #N/A | E16: =D16-D17 -> #N/A | I16: =VLOOKUP($A$2,일별!$A$5:$BG$370,J15,0) -> #N/A | K16: =VLOOKUP($A$2,일별!$A$5:$BG$370,L15,0) -> #N/A | M16: - | O16: -
B17: =VLOOKUP($A$2-1,일별!$A$5:$BG$370,C15,0) -> #N/A | D17: =VLOOKUP($A$2-1,일별!$A$5:$BG$370,E15,0) -> #N/A | I17: =VLOOKUP($A$2-1,일별!$A$5:$BG$370,J15,0) -> #N/A | K17: =VLOOKUP($A$2-1,일별!$A$5:$BG$370,L15,0) -> #N/A | M17: - | O17: -
B19: ACC | I19: PLB#3
B20: WIT | C20: =일별!T2 -> 20 | D20: LIT | E20: =일별!R2 -> 18 | F20: 충수량 | G20: =일별!C2 -> 3 | I20: 가동시간 | J20: =일별!AG2 -> 33 | K20: LNG 사용량 | L20: =일별!AA2 -> 27 | M20: 열생산량 | N20: 40 | O20: 부하율
B21: =VLOOKUP($A$2,일별!$A$5:$BG$370,C20,0) -> #N/A | C21: =B21-B22 -> #N/A | D21: =VLOOKUP($A$2,일별!$A$5:$BG$370,E20,0) -> #N/A | E21: =D21-D22 -> #N/A | F21: =VLOOKUP($A$2,일별!$A$5:$BG$370,G20,0) -> #N/A | G21: =F21-F22 -> #N/A | I21: =VLOOKUP($A$2,일별!$A$5:$BG$370,J20,0) -> #N/A | K21: =VLOOKUP($A$2,일별!$A$5:$BG$370,L20,0) -> #N/A | M21: - | O21: -
B22: =VLOOKUP($A$2-1,일별!$A$5:$BG$370,C20,0) -> #N/A | D22: =VLOOKUP($A$2-1,일별!$A$5:$BG$370,E20,0) -> #N/A | F22: =VLOOKUP($A$2-1,일별!$A$5:$BG$370,G20,0) -> #N/A | I22: =VLOOKUP($A$2-1,일별!$A$5:$BG$370,J20,0) -> #N/A | K22: =VLOOKUP($A$2-1,일별!$A$5:$BG$370,L20,0) -> #N/A | M22: - | O22: -

Sheet 월별
B2: 합계 | C2: 평균
A3: 단위 | B3: ACC 충수 | D3: A Train 생산 | F3: B Train 생산 | H3: 순수생산 | J3: 생활용수 | L3: 1차 냉각수 | N3: 폐수 전력 | P3: 방류수 | R3: 용수사용량 | T3: ACC LIT | V3: ACC WIT | X3: 순수 LIT | Z3: LNG사용량 | AF3: 운전시간 | AJ3: 생산량 | AP3: 연료전지 (22기) | AV3: 연료전지 기기별 가동시간 | BR3: 연료전지 기기별 LNG 사용량 | CN3: 연료전지 기기별 발전량
A4: 46388 | B4: ㎥ | C4: ㎥/d | D4: ㎥ | E4: ㎥/d | F4: ㎥ | G4: ㎥/d | J4: ㎥ | K4: ㎥/d | L4: ㎥ | M4: ㎥/d | N4: Kwh | P4: ㎥ | Q4: ㎥/d | R4: ㎥ | S4: ㎥/d | Z4: W_CHP(사용량) | AA4: #1 PLB(L) | AB4: #2 PLB(L) | AC4: #3 PLB(L) | AD4: PLB가스 사용량오차 | AE4: W_PLB(사용량) | AF4: 주보일러 | AG4: PLB#1 | AH4: PLB#2 | AI4: PLB#3 | AJ4: W_CHP(H생산) | AK4: #1 PLB | AL4: #2 PLB | AM4: #3 PLB | AN4: W_PLB(H생산) | AO4: 자체생산 | AP4: 가동시간 | AQ4: 평균 | AR4: LNG 사용량 | AS4: 평균 | AT4: 발전량 | AU4: 평균 | AV4: 1 | AW4: 2 | AX4: 3 | AY4: 4 | AZ4: 5 | BA4: 6 | BB4: 7 | BC4: 8 | BD4: 9 | BE4: 10 | BF4: 11 | BG4: 12 | BH4: 13 | BI4: 14 | BJ4: 15 | BK4: 16 | BL4: 17 | BM4: 18 | BN4: 19 | BO4: 20 | BP4: 21 | BQ4: 22 | BR4: 1 | BS4: 2 | BT4: 3 | BU4: 4 | BV4: 5 | BW4: 6 | BX4: 7 | BY4: 8 | BZ4: 9 | CA4: 10 | CB4: 11 | CC4: 12 | CD4: 13 | CE4: 14 | CF4: 15 | CG4: 16 | CH4: 17 | CI4: 18 | CJ4: 19 | CK4: 20 | CL4: 21 | CM4: 22 | CN4: 1 | CO4: 2 | CP4: 3 | CQ4: 4 | CR4: 5 | CS4: 6 | CT4: 7 | CU4: 8 | CV4: 9 | CW4: 10 | CX4: 11 | CY4: 12 | CZ4: 13 | DA4: 14 | DB4: 15 | DC4: 16 | DD4: 17 | DE4: 18 | DF4: 19 | DG4: 20 | DH4: 21 | DI4: 22
A5: 45658 | B5: =SUMIFS(일별!C:C, 일별!$A:$A, ">="&월별!$A5, 일별!$A:$A, "<"&월별!$A6) -> 816 | C5: =B5/(월별!$A6 - 월별!$A5) -> 26.322581 | D5: =SUMIFS(일별!E:E, 일별!$A:$A, ">="&월별!$A5, 일별!$A:$A, "<"&월별!$A6) -> 2540 | E5: =D5/(월별!$A6 - 월별!$A5) -> 81.935484 | F5: =SUMIFS(일별!G:G, 일별!$A:$A, ">="&월별!$A5, 일별!$A:$A, "<"&월별!$A6) -> 2588 | G5: =F5/(월별!$A6 - 월별!$A5) -> 83.483871 | H5: =D5+F5 -> 5128 | I5: =E5+G5 -> 165.41935 | J5: =SUMIFS(일별!I:I, 일별!$A:$A, ">="&월별!$A5, 일별!$A:$A, "<"&월별!$A6) -> 100 | K5: =J5/(월별!$A6 - 월별!$A5) -> 3.2258065 | L5: =SUMIFS(일별!K:K, 일별!$A:$A, ">="&월별!$A5, 일별!$A:$A, "<"&월별!$A6) -> 100 | M5: =L5/(월별!$A6 - 월별!$A5) -> 3.2258065 | N5: =SUMIFS(일별!M:M, 일별!$A:$A, ">="&월별!$A5, 일별!$A:$A, "<"&월별!$A6) -> 25.2 | O5: =N5/(월별!$A6 - 월별!$A5) -> 0.81290323 | P5: =SUMIFS(일별!O:O, 일별!$A:$A, ">="&월별!$A5, 일별!$A:$A, "<"&월별!$A6) -> 2483 | Q5: =P5/(월별!$A6 - 월별!$A5) -> 80.096774 | R5: =SUMIFS(일별!Q:Q, 일별!$A:$A, ">="&월별!$A5, 일별!$A:$A, "<"&월별!$A6) -> 6661 | S5: =R5/(월별!$A6 - 월별!$A5) -> 214.87097 | T5: =SUMIFS(일별!S:S, 일별!$A:$A, ">="&월별!$A5, 일별!$A:$A, "<"&월별!$A6) -> -0.6 | U5: =T5/(월별!$A6 - 월별!$A5) -> -0.019354839 | V5: =SUMIFS(일별!U:U, 일별!$A:$A, ">="&월별!$A5, 일별!$A:$A, "<"&월별!$A6) -> 0.583 | W5: =V5/(월별!$A6 - 월별!$A5) -> 0.018806452 | X5: =SUMIFS(일별!W:W, 일별!$A:$A, ">="&월별!$A5, 일별!$A:$A, "<"&월별!$A6) -> 0 | Y5: =X5/(월별!$A6 - 월별!$A5) -> 0 | Z5: =SUMIFS(일별!X:X, 일별!$A:$A, ">="&월별!$A5, 일별!$A:$A, "<"&월별!$A6) -> 1684005.7 | AA5: =SUMIFS(일별!Y:Y, 일별!$A:$A, ">="&월별!$A5, 일별!$A:$A, "<"&월별!$A6) -> 0 | AB5: =SUMIFS(일별!Z:Z, 일별!$A:$A, ">="&월별!$A5, 일별!$A:$A, "<"&월별!$A6) -> 0 | AC5: =SUMIFS(일별!AA:AA, 일별!$A:$A, ">="&월별!$A5, 일별!$A:$A, "<"&월별!$A6) -> 140277 | AD5: =SUMIFS(일별!AB:AB, 일별!$A:$A, ">="&월별!$A5, 일별!$A:$A, "<"&월별!$A6) -> 0 | AE5: =SUMIFS(일별!AC:AC, 일별!$A:$A, ">="&월별!$A5, 일별!$A:$A, "<"&월별!$A6) -> 140277 | AF5: =SUMIFS(일별!AD:AD, 일별!$A:$A, ">="&월별!$A5, 일별!$A:$A, "<"&월별!$A6) -> 239 | AG5: =SUMIFS(일별!AE:AE, 일별!$A:$A, ">="&월별!$A5, 일별!$A:$A, "<"&월별!$A6) -> 0 | AH5: =SUMIFS(일별!AF:AF, 일별!$A:$A, ">="&월별!$A5, 일별!$A:$A, "<"&월별!$A6) -> 0 | AI5: =SUMIFS(일별!AG:AG, 일별!$A:$A, ">="&월별!$A5, 일별!$A:$A, "<"&월별!$A6) -> 25.5 | AJ5: =SUMIFS(일별!AX:AX, 일별!$A:$A, ">="&월별!$A5, 일별!$A:$A, "<"&월별!$A6) -> 10762 | AK5: =SUMIFS(일별!AY:AY, 일별!$A:$A, ">="&월별!$A5, 일별!$A:$A, "<"&월별!$A6) -> 0 | AL5: =SUMIFS(일별!AZ:AZ, 일별!$A:$A, ">="&월별!$A5, 일별!$A:$A, "<"&월별!$A6) -> 0 | AM5: =SUMIFS(일별!BA:BA, 일별!$A:$A, ">="&월별!$A5, 일별!$A:$A, "<"&월별!$A6) -> 1245 | AN5: =SUMIFS(일별!BB:BB, 일별!$A:$A, ">="&월별!$A5, 일별!$A:$A, "<"&월별!$A6) -> 1245 | AO5: =SUMIFS(일별!BC:BC, 일별!$A:$A, ">="&월별!$A5, 일별!$A:$A, "<"&월별!$A6) -> 12007 | AP5: {=SUM(_xlfn._xlws.FILTER(일별!#REF!, (일별!$A:$A >= 월별!$A5) * (일별!$A:$A < 월별!$A6), 0))} -> #REF! | AQ5: =AP5/(월별!$A6 - 월별!$A5) -> #REF! | AR5: {=SUM(_xlfn._xlws.FILTER(일별!#REF!, (일별!$A:$A >= 월별!$A5) * (일별!$A:$A < 월별!$A6), 0))} -> #REF! | AS5: =AR5/(월별!$A6 - 월별!$A5) -> #REF! | AT5: {=SUM(_xlfn._xlws.FILTER(일별!#REF!, (일별!$A:$A >= 월별!$A5) * (일별!$A:$A < 월별!$A6), 0))} -> #REF! | AU5: =AT5/(월별!$A6 - 월별!$A5) -> #REF! | AV5: {=SUM(_xlfn._xlws.FILTER(일별!#REF!, (일별!$A:$A >= 월별!$A5) * (일별!$A:$A < 월별!$A6), 0))} -> #REF! | AW5: {=SUM(_xlfn._xlws.FILTER(일별!#REF!, (일별!$A:$A >= 월별!$A5) * (일별!$A:$A < 월별!$A6), 0))} -> #REF! | AX5: {=SUM(_xlfn._xlws.FILTER(일별!#REF!, (일별!$A:$A >= 월별!$A5) * (일별!$A:$A < 월별!$A6), 0))} -> #REF! | AY5: {=SUM(_xlfn._xlws.FILTER(일별!#REF!, (일별!$A:$A >= 월별!$A5) * (일별!$A:$A < 월별!$A6), 0))} -> #REF! | AZ5: {=SUM(_xlfn._xlws.FILTER(일별!#REF!, (일별!$A:$A >= 월별!$A5) * (일별!$A:$A < 월별!$A6), 0))} -> #REF! | BA5: {=SUM(_xlfn._xlws.FILTER(일별!#REF!, (일별!$A:$A >= 월별!$A5) * (일별!$A:$A < 월별!$A6), 0))} -> #REF! | BB5: {=SUM(_xlfn._xlws.FILTER(일별!#REF!, (일별!$A:$A >= 월별!$A5) * (일별!$A:$A < 월별!$A6), 0))} -> #REF! | BC5: {=SUM(_xlfn._xlws.FILTER(일별!#REF!, (일별!$A:$A >= 월별!$A5) * (일별!$A:$A < 월별!$A6), 0))} -> #REF! | ... DI5: {=SUM(_xlfn._xlws.FILTER(일별!#REF!, (일별!$A:$A >= 월별!$A5) * (일별!$A:$A < 월별!$A6), 0))} -> #REF!
A6: 45689 | B6: =SUMIFS(일별!$C:$C, 일별!$A:$A, ">="&월별!$A6, 일별!$A:$A, "<"&월별!$A7) -> 660 | C6: =B6/(월별!$A7 - 월별!$A6) -> 23.571429 | D6: =SUMIFS(일별!E:E, 일별!$A:$A, ">="&월별!$A6, 일별!$A:$A, "<"&월별!$A7) -> 2251 | E6: =D6/(월별!$A7 - 월별!$A6) -> 80.392857 | F6: =SUMIFS(일별!G:G, 일별!$A:$A, ">="&월별!$A6, 일별!$A:$A, "<"&월별!$A7) -> 2332 | G6: =F6/(월별!$A7 - 월별!$A6) -> 83.285714 | H6: =D6+F6 -> 4583 | I6: =E6+G6 -> 163.67857 | J6: =SUMIFS(일별!I:I, 일별!$A:$A, ">="&월별!$A6, 일별!$A:$A, "<"&월별!$A7) -> 109 | K6: =J6/(월별!$A7 - 월별!$A6) -> 3.8928571 | L6: =SUMIFS(일별!K:K, 일별!$A:$A, ">="&월별!$A6, 일별!$A:$A, "<"&월별!$A7) -> 109 | M6: =L6/(월별!$A7 - 월별!$A6) -> 3.8928571 | N6: =SUMIFS(일별!M:M, 일별!$A:$A, ">="&월별!$A6, 일별!$A:$A, "<"&월별!$A7) -> 25.2 | O6: =N6/(월별!$A7 - 월별!$A6) -> 0.9 | P6: =SUMIFS(일별!O:O, 일별!$A:$A, ">="&월별!$A6, 일별!$A:$A, "<"&월별!$A7) -> 2754 | Q6: =P6/(월별!$A7 - 월별!$A6) -> 98.357143 | R6: =SUMIFS(일별!Q:Q, 일별!$A:$A, ">="&월별!$A6, 일별!$A:$A, "<"&월별!$A7) -> 6425 | S6: =R6/(월별!$A7 - 월별!$A6) -> 229.46429 | T6: =SUMIFS(일별!S:S, 일별!$A:$A, ">="&월별!$A6, 일별!$A:$A, "<"&월별!$A7) -> 0.36 | U6: =T6/(월별!$A7 - 월별!$A6) -> 0.012857143 | V6: =SUMIFS(일별!U:U, 일별!$A:$A, ">="&월별!$A6, 일별!$A:$A, "<"&월별!$A7) -> -0.53 | W6: =V6/(월별!$A7 - 월별!$A6) -> -0.018928571 | X6: =SUMIFS(일별!W:W, 일별!$A:$A, ">="&월별!$A6, 일별!$A:$A, "<"&월별!$A7) -> 0 | Y6: =X6/(월별!$A7 - 월별!$A6) -> 0 | Z6: =SUMIFS(일별!X:X, 일별!$A:$A, ">="&월별!$A6, 일별!$A:$A, "<"&월별!$A7) -> 3558570 | AA6: =SUMIFS(일별!Y:Y, 일별!$A:$A, ">="&월별!$A6, 일별!$A:$A, "<"&월별!$A7) -> 188 | AB6: =SUMIFS(일별!Z:Z, 일별!$A:$A, ">="&월별!$A6, 일별!$A:$A, "<"&월별!$A7) -> 0 | AC6: =SUMIFS(일별!AA:AA, 일별!$A:$A, ">="&월별!$A6, 일별!$A:$A, "<"&월별!$A7) -> 0 | AD6: =SUMIFS(일별!AB:AB, 일별!$A:$A, ">="&월별!$A6, 일별!$A:$A, "<"&월별!$A7) -> 0 | AE6: =SUMIFS(일별!AC:AC, 일별!$A:$A, ">="&월별!$A6, 일별!$A:$A, "<"&월별!$A7) -> 188 | AF6: =SUMIFS(일별!AD:AD, 일별!$A:$A, ">="&월별!$A6, 일별!$A:$A, "<"&월별!$A7) -> 454 | AG6: =SUMIFS(일별!AE:AE, 일별!$A:$A, ">="&월별!$A6, 일별!$A:$A, "<"&월별!$A7) -> 0 | AH6: =SUMIFS(일별!AF:AF, 일별!$A:$A, ">="&월별!$A6, 일별!$A:$A, "<"&월별!$A7) -> 0 | AI6: =SUMIFS(일별!AG:AG, 일별!$A:$A, ">="&월별!$A6, 일별!$A:$A, "<"&월별!$A7) -> 0 | AJ6: =SUMIFS(일별!AX:AX, 일별!$A:$A, ">="&월별!$A6, 일별!$A:$A, "<"&월별!$A7) -> 22695.8 | AK6: =SUMIFS(일별!AY:AY, 일별!$A:$A, ">="&월별!$A6, 일별!$A:$A, "<"&월별!$A7) -> 0 | AL6: =SUMIFS(일별!AZ:AZ, 일별!$A:$A, ">="&월별!$A6, 일별!$A:$A, "<"&월별!$A7) -> 0 | AM6: =SUMIFS(일별!BA:BA, 일별!$A:$A, ">="&월별!$A6, 일별!$A:$A, "<"&월별!$A7) -> 0 | AN6: =SUMIFS(일별!BB:BB, 일별!$A:$A, ">="&월별!$A6, 일별!$A:$A, "<"&월별!$A7) -> 0 | AO6: =SUMIFS(일별!BC:BC, 일별!$A:$A, ">="&월별!$A6, 일별!$A:$A, "<"&월별!$A7) -> 22695.8 | AP6: {=SUM(_xlfn._xlws.FILTER(일별!#REF!, (일별!$A:$A >= 월별!$A6) * (일별!$A:$A < 월별!$A7), 0))} -> #REF! | AQ6: =AP6/(월별!$A7 - 월별!$A6) -> #REF! | AR6: {=SUM(_xlfn._xlws.FILTER(일별!#REF!, (일별!$A:$A >= 월별!$A6) * (일별!$A:$A < 월별!$A7), 0))} -> #REF! | AS6: =AR6/(월별!$A7 - 월별!$A6) -> #REF! | AT6: {=SUM(_xlfn._xlws.FILTER(일별!#REF!, (일별!$A:$A >= 월별!$A6) * (일별!$A:$A < 월별!$A7), 0))} -> #REF! | AU6: =AT6/(월별!$A7 - 월별!$A6) -> #REF! | AV6: {=SUM(_xlfn._xlws.FILTER(일별!#REF!, (일별!$A:$A >= 월별!$A6) * (일별!$A:$A < 월별!$A7), 0))} -> #REF! | AW6: {=SUM(_xlfn._xlws.FILTER(일별!#REF!, (일별!$A:$A >= 월별!$A6) * (일별!$A:$A < 월별!$A7), 0))} -> #REF! | AX6: {=SUM(_xlfn._xlws.FILTER(일별!#REF!, (일별!$A:$A >= 월별!$A6) * (일별!$A:$A < 월별!$A7), 0))} -> #REF! | AY6: {=SUM(_xlfn._xlws.FILTER(일별!#REF!, (일별!$A:$A >= 월별!$A6) * (일별!$A:$A < 월별!$A7), 0))} -> #REF! | AZ6: {=SUM(_xlfn._xlws.FILTER(일별!#REF!, (일별!$A:$A >= 월별!$A6) * (일별!$A:$A < 월별!$A7), 0))} -> #REF! | BA6: {=SUM(_xlfn._xlws.FILTER(일별!#REF!, (일별!$A:$A >= 월별!$A6) * (일별!$A:$A < 월별!$A7), 0))} -> #REF! | BB6: {=SUM(_xlfn._xlws.FILTER(일별!#REF!, (일별!$A:$A >= 월별!$A6) * (일별!$A:$A < 월별!$A7), 0))} -> #REF! | BC6: {=SUM(_xlfn._xlws.FILTER(일별!#REF!, (일별!$A:$A >= 월별!$A6) * (일별!$A:$A < 월별!$A7), 0))} -> #REF! | ... DI6: {=SUM(_xlfn._xlws.FILTER(일별!#REF!, (일별!$A:$A >= 월별!$A6) * (일별!$A:$A < 월별!$A7), 0))} -> #REF!
A7: 45717 | B7: =SUMIFS(일별!$C:$C, 일별!$A:$A, ">="&월별!$A7, 일별!$A:$A, "<"&월별!$A8) -> 713 | C7: =B7/(월별!$A8 - 월별!$A7) -> 23 | D7: =SUMIFS(일별!E:E, 일별!$A:$A, ">="&월별!$A7, 일별!$A:$A, "<"&월별!$A8) -> 2134 | E7: =D7/(월별!$A8 - 월별!$A7) -> 68.83871 | F7: =SUMIFS(일별!G:G, 일별!$A:$A, ">="&월별!$A7, 일별!$A:$A, "<"&월별!$A8) -> 2103 | G7: =F7/(월별!$A8 - 월별!$A7) -> 67.83871 | H7: =D7+F7 -> 4237 | I7: =E7+G7 -> 136.67742 | J7: =SUMIFS(일별!I:I, 일별!$A:$A, ">="&월별!$A7, 일별!$A:$A, "<"&월별!$A8) -> 149 | K7: =J7/(월별!$A8 - 월별!$A7) -> 4.8064516 | L7: =SUMIFS(일별!K:K, 일별!$A:$A, ">="&월별!$A7, 일별!$A:$A, "<"&월별!$A8) -> 149 | M7: =L7/(월별!$A8 - 월별!$A7) -> 4.8064516 | N7: =SUMIFS(일별!M:M, 일별!$A:$A, ">="&월별!$A7, 일별!$A:$A, "<"&월별!$A8) -> 27.6 | O7: =N7/(월별!$A8 - 월별!$A7) -> 0.89032258 | P7: =SUMIFS(일별!O:O, 일별!$A:$A, ">="&월별!$A7, 일별!$A:$A, "<"&월별!$A8) -> 2418 | Q7: =P7/(월별!$A8 - 월별!$A7) -> 78 | R7: =SUMIFS(일별!Q:Q, 일별!$A:$A, ">="&월별!$A7, 일별!$A:$A, "<"&월별!$A8) -> 7085 | S7: =R7/(월별!$A8 - 월별!$A7) -> 228.54839 | T7: =SUMIFS(일별!S:S, 일별!$A:$A, ">="&월별!$A7, 일별!$A:$A, "<"&월별!$A8) -> -0.36 | U7: =T7/(월별!$A8 - 월별!$A7) -> -0.011612903 | V7: =SUMIFS(일별!U:U, 일별!$A:$A, ">="&월별!$A7, 일별!$A:$A, "<"&월별!$A8) -> -0.37 | W7: =V7/(월별!$A8 - 월별!$A7) -> -0.011935484 | X7: =SUMIFS(일별!W:W, 일별!$A:$A, ">="&월별!$A7, 일별!$A:$A, "<"&월별!$A8) -> 0 | Y7: =X7/(월별!$A8 - 월별!$A7) -> 0 | Z7: =SUMIFS(일별!X:X, 일별!$A:$A, ">="&월별!$A7, 일별!$A:$A, "<"&월별!$A8) -> 1865810 | AA7: =SUMIFS(일별!Y:Y, 일별!$A:$A, ">="&월별!$A7, 일별!$A:$A, "<"&월별!$A8) -> 403 | AB7: =SUMIFS(일별!Z:Z, 일별!$A:$A, ">="&월별!$A7, 일별!$A:$A, "<"&월별!$A8) -> 0 | AC7: =SUMIFS(일별!AA:AA, 일별!$A:$A, ">="&월별!$A7, 일별!$A:$A, "<"&월별!$A8) -> 0 | AD7: =SUMIFS(일별!AB:AB, 일별!$A:$A, ">="&월별!$A7, 일별!$A:$A, "<"&월별!$A8) -> 0 | AE7: =SUMIFS(일별!AC:AC, 일별!$A:$A, ">="&월별!$A7, 일별!$A:$A, "<"&월별!$A8) -> 403 | AF7: =SUMIFS(일별!AD:AD, 일별!$A:$A, ">="&월별!$A7, 일별!$A:$A, "<"&월별!$A8) -> 278 | AG7: =SUMIFS(일별!AE:AE, 일별!$A:$A, ">="&월별!$A7, 일별!$A:$A, "<"&월별!$A8) -> 0 | AH7: =SUMIFS(일별!AF:AF, 일별!$A:$A, ">="&월별!$A7, 일별!$A:$A, "<"&월별!$A8) -> 0 | AI7: =SUMIFS(일별!AG:AG, 일별!$A:$A, ">="&월별!$A7, 일별!$A:$A, "<"&월별!$A8) -> 0 | AJ7: =SUMIFS(일별!AX:AX, 일별!$A:$A, ">="&월별!$A7, 일별!$A:$A, "<"&월별!$A8) -> 11730.3 | AK7: =SUMIFS(일별!AY:AY, 일별!$A:$A, ">="&월별!$A7, 일별!$A:$A, "<"&월별!$A8) -> 0 | AL7: =SUMIFS(일별!AZ:AZ, 일별!$A:$A, ">="&월별!$A7, 일별!$A:$A, "<"&월별!$A8) -> 0 | AM7: =SUMIFS(일별!BA:BA, 일별!$A:$A, ">="&월별!$A7, 일별!$A:$A, "<"&월별!$A8) -> 0 | AN7: =SUMIFS(일별!BB:BB, 일별!$A:$A, ">="&월별!$A7, 일별!$A:$A, "<"&월별!$A8) -> 0 | AO7: =SUMIFS(일별!BC:BC, 일별!$A:$A, ">="&월별!$A7, 일별!$A:$A, "<"&월별!$A8) -> 11730.3 | AP7: {=SUM(_xlfn._xlws.FILTER(일별!#REF!, (일별!$A:$A >= 월별!$A7) * (일별!$A:$A < 월별!$A8), 0))} -> #REF! | AQ7: =AP7/(월별!$A8 - 월별!$A7) -> #REF! | AR7: {=SUM(_xlfn._xlws.FILTER(일별!#REF!, (일별!$A:$A >= 월별!$A7) * (일별!$A:$A < 월별!$A8), 0))} -> #REF! | AS7: =AR7/(월별!$A8 - 월별!$A7) -> #REF! | AT7: {=SUM(_xlfn._xlws.FILTER(일별!#REF!, (일별!$A:$A >= 월별!$A7) * (일별!$A:$A < 월별!$A8), 0))} -> #REF! | AU7: =AT7/(월별!$A8 - 월별!$A7) -> #REF! | AV7: {=SUM(_xlfn._xlws.FILTER(일별!#REF!, (일별!$A:$A >= 월별!$A7) * (일별!$A:$A < 월별!$A8), 0))} -> #REF! | AW7: {=SUM(_xlfn._xlws.FILTER(일별!#REF!, (일별!$A:$A >= 월별!$A7) * (일별!$A:$A < 월별!$A8), 0))} -> #REF! | AX7: {=SUM(_xlfn._xlws.FILTER(일별!#REF!, (일별!$A:$A >= 월별!$A7) * (일별!$A:$A < 월별!$A8), 0))} -> #REF! | AY7: {=SUM(_xlfn._xlws.FILTER(일별!#REF!, (일별!$A:$A >= 월별!$A7) * (일별!$A:$A < 월별!$A8), 0))} -> #REF! | AZ7: {=SUM(_xlfn._xlws.FILTER(일별!#REF!, (일별!$A:$A >= 월별!$A7) * (일별!$A:$A < 월별!$A8), 0))} -> #REF! | BA7: {=SUM(_xlfn._xlws.FILTER(일별!#REF!, (일별!$A:$A >= 월별!$A7) * (일별!$A:$A < 월별!$A8), 0))} -> #REF! | BB7: {=SUM(_xlfn._xlws.FILTER(일별!#REF!, (일별!$A:$A >= 월별!$A7) * (일별!$A:$A < 월별!$A8), 0))} -> #REF! | BC7: {=SUM(_xlfn._xlws.FILTER(일별!#REF!, (일별!$A:$A >= 월별!$A7) * (일별!$A:$A < 월별!$A8), 0))} -> #REF! | ... DI7: {=SUM(_xlfn._xlws.FILTER(일별!#REF!, (일별!$A:$A >= 월별!$A7) * (일별!$A:$A < 월별!$A8), 0))} -> #REF!
A8: 45748 | B8: =SUMIFS(일별!$C:$C, 일별!$A:$A, ">="&월별!$A8, 일별!$A:$A, "<"&월별!$A9) -> 524 | C8: =B8/(월별!$A9 - 월별!$A8) -> 17.466667 | D8: =SUMIFS(일별!E:E, 일별!$A:$A, ">="&월별!$A8, 일별!$A:$A, "<"&월별!$A9) -> 2218 | E8: =D8/(월별!$A9 - 월별!$A8) -> 73.933333 | F8: =SUMIFS(일별!G:G, 일별!$A:$A, ">="&월별!$A8, 일별!$A:$A, "<"&월별!$A9) -> 2162 | G8: =F8/(월별!$A9 - 월별!$A8) -> 72.066667 | H8: =D8+F8 -> 4380 | I8: =E8+G8 -> 146 | J8: =SUMIFS(일별!I:I, 일별!$A:$A, ">="&월별!$A8, 일별!$A:$A, "<"&월별!$A9) -> 138 | K8: =J8/(월별!$A9 - 월별!$A8) -> 4.6 | L8: =SUMIFS(일별!K:K, 일별!$A:$A, ">="&월별!$A8, 일별!$A:$A, "<"&월별!$A9) -> 138 | M8: =L8/(월별!$A9 - 월별!$A8) -> 4.6 | N8: =SUMIFS(일별!M:M, 일별!$A:$A, ">="&월별!$A8, 일별!$A:$A, "<"&월별!$A9) -> 25.4 | O8: =N8/(월별!$A9 - 월별!$A8) -> 0.84666667 | P8: =SUMIFS(일별!O:O, 일별!$A:$A, ">="&월별!$A8, 일별!$A:$A, "<"&월별!$A9) -> 2425 | Q8: =P8/(월별!$A9 - 월별!$A8) -> 80.833333 | R8: =SUMIFS(일별!Q:Q, 일별!$A:$A, ">="&월별!$A8, 일별!$A:$A, "<"&월별!$A9) -> 6806 | S8: =R8/(월별!$A9 - 월별!$A8) -> 226.86667 | T8: =SUMIFS(일별!S:S, 일별!$A:$A, ">="&월별!$A8, 일별!$A:$A, "<"&월별!$A9) -> 1 | U8: =T8/(월별!$A9 - 월별!$A8) -> 0.033333333 | V8: =SUMIFS(일별!U:U, 일별!$A:$A, ">="&월별!$A8, 일별!$A:$A, "<"&월별!$A9) -> 0.93 | W8: =V8/(월별!$A9 - 월별!$A8) -> 0.031 | X8: =SUMIFS(일별!W:W, 일별!$A:$A, ">="&월별!$A8, 일별!$A:$A, "<"&월별!$A9) -> 0 | Y8: =X8/(월별!$A9 - 월별!$A8) -> 0 | Z8: =SUMIFS(일별!X:X, 일별!$A:$A, ">="&월별!$A8, 일별!$A:$A, "<"&월별!$A9) -> 1268588 | AA8: =SUMIFS(일별!Y:Y, 일별!$A:$A, ">="&월별!$A8, 일별!$A:$A, "<"&월별!$A9) -> 0 | AB8: =SUMIFS(일별!Z:Z, 일별!$A:$A, ">="&월별!$A8, 일별!$A:$A, "<"&월별!$A9) -> 0 | AC8: =SUMIFS(일별!AA:AA, 일별!$A:$A, ">="&월별!$A8, 일별!$A:$A, "<"&월별!$A9) -> 0 | AD8: =SUMIFS(일별!AB:AB, 일별!$A:$A, ">="&월별!$A8, 일별!$A:$A, "<"&월별!$A9) -> 0 | AE8: =SUMIFS(일별!AC:AC, 일별!$A:$A, ">="&월별!$A8, 일별!$A:$A, "<"&월별!$A9) -> 0 | AF8: =SUMIFS(일별!AD:AD, 일별!$A:$A, ">="&월별!$A8, 일별!$A:$A, "<"&월별!$A9) -> 201 | AG8: =SUMIFS(일별!AE:AE, 일별!$A:$A, ">="&월별!$A8, 일별!$A:$A, "<"&월별!$A9) -> 0 | AH8: =SUMIFS(일별!AF:AF, 일별!$A:$A, ">="&월별!$A8, 일별!$A:$A, "<"&월별!$A9) -> 0 | AI8: =SUMIFS(일별!AG:AG, 일별!$A:$A, ">="&월별!$A8, 일별!$A:$A, "<"&월별!$A9) -> 0 | AJ8: =SUMIFS(일별!AX:AX, 일별!$A:$A, ">="&월별!$A8, 일별!$A:$A, "<"&월별!$A9) -> 7975 | AK8: =SUMIFS(일별!AY:AY, 일별!$A:$A, ">="&월별!$A8, 일별!$A:$A, "<"&월별!$A9) -> 0 | AL8: =SUMIFS(일별!AZ:AZ, 일별!$A:$A, ">="&월별!$A8, 일별!$A:$A, "<"&월별!$A9) -> 0 | AM8: =SUMIFS(일별!BA:BA, 일별!$A:$A, ">="&월별!$A8, 일별!$A:$A, "<"&월별!$A9) -> 0 | AN8: =SUMIFS(일별!BB:BB, 일별!$A:$A, ">="&월별!$A8, 일별!$A:$A, "<"&월별!$A9) -> 0 | AO8: =SUMIFS(일별!BC:BC, 일별!$A:$A, ">="&월별!$A8, 일별!$A:$A, "<"&월별!$A9) -> 7975 | AP8: {=SUM(_xlfn._xlws.FILTER(일별!#REF!, (일별!$A:$A >= 월별!$A8) * (일별!$A:$A < 월별!$A9), 0))} -> #REF! | AQ8: =AP8/(월별!$A9 - 월별!$A8) -> #REF! | AR8: {=SUM(_xlfn._xlws.FILTER(일별!#REF!, (일별!$A:$A >= 월별!$A8) * (일별!$A:$A < 월별!$A9), 0))} -> #REF! | AS8: =AR8/(월별!$A9 - 월별!$A8) -> #REF! | AT8: {=SUM(_xlfn._xlws.FILTER(일별!#REF!, (일별!$A:$A >= 월별!$A8) * (일별!$A:$A < 월별!$A9), 0))} -> #REF! | AU8: =AT8/(월별!$A9 - 월별!$A8) -> #REF! | AV8: {=SUM(_xlfn._xlws.FILTER(일별!#REF!, (일별!$A:$A >= 월별!$A8) * (일별!$A:$A < 월별!$A9), 0))} -> #REF! | AW8: {=SUM(_xlfn._xlws.FILTER(일별!#REF!, (일별!$A:$A >= 월별!$A8) * (일별!$A:$A < 월별!$A9), 0))} -> #REF! | AX8: {=SUM(_xlfn._xlws.FILTER(일별!#REF!, (일별!$A:$A >= 월별!$A8) * (일별!$A:$A < 월별!$A9), 0))} -> #REF! | AY8: {=SUM(_xlfn._xlws.FILTER(일별!#REF!, (일별!$A:$A >= 월별!$A8) * (일별!$A:$A < 월별!$A9), 0))} -> #REF! | AZ8: {=SUM(_xlfn._xlws.FILTER(일별!#REF!, (일별!$A:$A >= 월별!$A8) * (일별!$A:$A < 월별!$A9), 0))} -> #REF! | BA8: {=SUM(_xlfn._xlws.FILTER(일별!#REF!, (일별!$A:$A >= 월별!$A8) * (일별!$A:$A < 월별!$A9), 0))} -> #REF! | BB8: {=SUM(_xlfn._xlws.FILTER(일별!#REF!, (일별!$A:$A >= 월별!$A8) * (일별!$A:$A < 월별!$A9), 0))} -> #REF! | BC8: {=SUM(_xlfn._xlws.FILTER(일별!#REF!, (일별!$A:$A >= 월별!$A8) * (일별!$A:$A < 월별!$A9), 0))} -> #REF! | ... DI8: {=SUM(_xlfn._xlws.FILTER(일별!#REF!, (일별!$A:$A >= 월별!$A8) * (일별!$A:$A < 월별!$A9), 0))} -> #REF!
A9: 45778 | B9: =SUMIFS(일별!$C:$C, 일별!$A:$A, ">="&월별!$A9, 일별!$A:$A, "<"&월별!$A10) -> 436 | C9: =B9/(월별!$A10 - 월별!$A9) -> 14.064516 | D9: =SUMIFS(일별!E:E, 일별!$A:$A, ">="&월별!$A9, 일별!$A:$A, "<"&월별!$A10) -> 1758 | E9: =D9/(월별!$A10 - 월별!$A9) -> 56.709677 | F9: =SUMIFS(일별!G:G, 일별!$A:$A, ">="&월별!$A9, 일별!$A:$A, "<"&월별!$A10) -> 1324 | G9: =F9/(월별!$A10 - 월별!$A9) -> 42.709677 | H9: =D9+F9 -> 3082 | I9: =E9+G9 -> 99.419355 | J9: =SUMIFS(일별!I:I, 일별!$A:$A, ">="&월별!$A9, 일별!$A:$A, "<"&월별!$A10) -> 170 | K9: =J9/(월별!$A10 - 월별!$A9) -> 5.483871 | L9: =SUMIFS(일별!K:K, 일별!$A:$A, ">="&월별!$A9, 일별!$A:$A, "<"&월별!$A10) -> 170 | M9: =L9/(월별!$A10 - 월별!$A9) -> 5.483871 | N9: =SUMIFS(일별!M:M, 일별!$A:$A, ">="&월별!$A9, 일별!$A:$A, "<"&월별!$A10) -> 18.1 | O9: =N9/(월별!$A10 - 월별!$A9) -> 0.58387097 | P9: =SUMIFS(일별!O:O, 일별!$A:$A, ">="&월별!$A9, 일별!$A:$A, "<"&월별!$A10) -> 2380 | Q9: =P9/(월별!$A10 - 월별!$A9) -> 76.774194 | R9: =SUMIFS(일별!Q:Q, 일별!$A:$A, ">="&월별!$A9, 일별!$A:$A, "<"&월별!$A10) -> 4929 | S9: =R9/(월별!$A10 - 월별!$A9) -> 159 | T9: =SUMIFS(일별!S:S, 일별!$A:$A, ">="&월별!$A9, 일별!$A:$A, "<"&월별!$A10) -> 0.75 | U9: =T9/(월별!$A10 - 월별!$A9) -> 0.024193548 | V9: =SUMIFS(일별!U:U, 일별!$A:$A, ">="&월별!$A9, 일별!$A:$A, "<"&월별!$A10) -> 1.14 | W9: =V9/(월별!$A10 - 월별!$A9) -> 0.036774194 | X9: =SUMIFS(일별!W:W, 일별!$A:$A, ">="&월별!$A9, 일별!$A:$A, "<"&월별!$A10) -> 0 | Y9: =X9/(월별!$A10 - 월별!$A9) -> 0 | Z9: =SUMIFS(일별!X:X, 일별!$A:$A, ">="&월별!$A9, 일별!$A:$A, "<"&월별!$A10) -> 477928 | AA9: =SUMIFS(일별!Y:Y, 일별!$A:$A, ">="&월별!$A9, 일별!$A:$A, "<"&월별!$A10) -> 0 | AB9: =SUMIFS(일별!Z:Z, 일별!$A:$A, ">="&월별!$A9, 일별!$A:$A, "<"&월별!$A10) -> 0 | AC9: =SUMIFS(일별!AA:AA, 일별!$A:$A, ">="&월별!$A9, 일별!$A:$A, "<"&월별!$A10) -> 0 | AD9: =SUMIFS(일별!AB:AB, 일별!$A:$A, ">="&월별!$A9, 일별!$A:$A, "<"&월별!$A10) -> 0 | AE9: =SUMIFS(일별!AC:AC, 일별!$A:$A, ">="&월별!$A9, 일별!$A:$A, "<"&월별!$A10) -> 0 | AF9: =SUMIFS(일별!AD:AD, 일별!$A:$A, ">="&월별!$A9, 일별!$A:$A, "<"&월별!$A10) -> 105 | AG9: =SUMIFS(일별!AE:AE, 일별!$A:$A, ">="&월별!$A9, 일별!$A:$A, "<"&월별!$A10) -> 0 | AH9: =SUMIFS(일별!AF:AF, 일별!$A:$A, ">="&월별!$A9, 일별!$A:$A, "<"&월별!$A10) -> 0 | AI9: =SUMIFS(일별!AG:AG, 일별!$A:$A, ">="&월별!$A9, 일별!$A:$A, "<"&월별!$A10) -> 0 | AJ9: =SUMIFS(일별!AX:AX, 일별!$A:$A, ">="&월별!$A9, 일별!$A:$A, "<"&월별!$A10) -> 3004 | AK9: =SUMIFS(일별!AY:AY, 일별!$A:$A, ">="&월별!$A9, 일별!$A:$A, "<"&월별!$A10) -> 0 | AL9: =SUMIFS(일별!AZ:AZ, 일별!$A:$A, ">="&월별!$A9, 일별!$A:$A, "<"&월별!$A10) -> 0 | AM9: =SUMIFS(일별!BA:BA, 일별!$A:$A, ">="&월별!$A9, 일별!$A:$A, "<"&월별!$A10) -> 0 | AN9: =SUMIFS(일별!BB:BB, 일별!$A:$A, ">="&월별!$A9, 일별!$A:$A, "<"&월별!$A10) -> 0 | AO9: =SUMIFS(일별!BC:BC, 일별!$A:$A, ">="&월별!$A9, 일별!$A:$A, "<"&월별!$A10) -> 3004 | AP9: {=SUM(_xlfn._xlws.FILTER(일별!#REF!, (일별!$A:$A >= 월별!$A9) * (일별!$A:$A < 월별!$A10), 0))} -> #REF! | AQ9: =AP9/(월별!$A10 - 월별!$A9) -> #REF! | AR9: {=SUM(_xlfn._xlws.FILTER(일별!#REF!, (일별!$A:$A >= 월별!$A9) * (일별!$A:$A < 월별!$A10), 0))} -> #REF! | AS9: =AR9/(월별!$A10 - 월별!$A9) -> #REF! | AT9: {=SUM(_xlfn._xlws.FILTER(일별!#REF!, (일별!$A:$A >= 월별!$A9) * (일별!$A:$A < 월별!$A10), 0))} -> #REF! | AU9: =AT9/(월별!$A10 - 월별!$A9) -> #REF! | AV9: {=SUM(_xlfn._xlws.FILTER(일별!#REF!, (일별!$A:$A >= 월별!$A9) * (일별!$A:$A < 월별!$A10), 0))} -> #REF! | AW9: {=SUM(_xlfn._xlws.FILTER(일별!#REF!, (일별!$A:$A >= 월별!$A9) * (일별!$A:$A < 월별!$A10), 0))} -> #REF! | AX9: {=SUM(_xlfn._xlws.FILTER(일별!#REF!, (일별!$A:$A >= 월별!$A9) * (일별!$A:$A < 월별!$A10), 0))} -> #REF! | AY9: {=SUM(_xlfn._xlws.FILTER(일별!#REF!, (일별!$A:$A >= 월별!$A9) * (일별!$A:$A < 월별!$A10), 0))} -> #REF! | AZ9: {=SUM(_xlfn._xlws.FILTER(일별!#REF!, (일별!$A:$A >= 월별!$A9) * (일별!$A:$A < 월별!$A10), 0))} -> #REF! | BA9: {=SUM(_xlfn._xlws.FILTER(일별!#REF!, (일별!$A:$A >= 월별!$A9) * (일별!$A:$A < 월별!$A10), 0))} -> #REF! | BB9: {=SUM(_xlfn._xlws.FILTER(일별!#REF!, (일별!$A:$A >= 월별!$A9) * (일별!$A:$A < 월별!$A10), 0))} -> #REF! | BC9: {=SUM(_xlfn._xlws.FILTER(일별!#REF!, (일별!$A:$A >= 월별!$A9) * (일별!$A:$A < 월별!$A10), 0))} -> #REF! | ... DI9: {=SUM(_xlfn._xlws.FILTER(일별!#REF!, (일별!$A:$A >= 월별!$A9) * (일별!$A:$A < 월별!$A10), 0))} -> #REF!
A10: 45809 | B10: =SUMIFS(일별!$C:$C, 일별!$A:$A, ">="&월별!$A10, 일별!$A:$A, "<"&월별!$A11) -> 391 | C10: =B10/(월별!$A11 - 월별!$A10) -> 13.033333 | D10: =SUMIFS(일별!E:E, 일별!$A:$A, ">="&월별!$A10, 일별!$A:$A, "<"&월별!$A11) -> 1024 | E10: =D10/(월별!$A11 - 월별!$A10) -> 34.133333 | F10: =SUMIFS(일별!G:G, 일별!$A:$A, ">="&월별!$A10, 일별!$A:$A, "<"&월별!$A11) -> 916 | G10: =F10/(월별!$A11 - 월별!$A10) -> 30.533333 | H10: =D10+F10 -> 1940 | I10: =E10+G10 -> 64.666667 | J10: =SUMIFS(일별!I:I, 일별!$A:$A, ">="&월별!$A10, 일별!$A:$A, "<"&월별!$A11) -> 195.33 | K10: =J10/(월별!$A11 - 월별!$A10) -> 6.511 | L10: =SUMIFS(일별!K:K, 일별!$A:$A, ">="&월별!$A10, 일별!$A:$A, "<"&월별!$A11) -> 195.33 | M10: =L10/(월별!$A11 - 월별!$A10) -> 6.511 | N10: =SUMIFS(일별!M:M, 일별!$A:$A, ">="&월별!$A10, 일별!$A:$A, "<"&월별!$A11) -> 16.5 | O10: =N10/(월별!$A11 - 월별!$A10) -> 0.55 | P10: =SUMIFS(일별!O:O, 일별!$A:$A, ">="&월별!$A10, 일별!$A:$A, "<"&월별!$A11) -> 1072 | Q10: =P10/(월별!$A11 - 월별!$A10) -> 35.733333 | R10: =SUMIFS(일별!Q:Q, 일별!$A:$A, ">="&월별!$A10, 일별!$A:$A, "<"&월별!$A11) -> 3810 | S10: =R10/(월별!$A11 - 월별!$A10) -> 127 | T10: =SUMIFS(일별!S:S, 일별!$A:$A, ">="&월별!$A10, 일별!$A:$A, "<"&월별!$A11) -> 1.35 | U10: =T10/(월별!$A11 - 월별!$A10) -> 0.045 | V10: =SUMIFS(일별!U:U, 일별!$A:$A, ">="&월별!$A10, 일별!$A:$A, "<"&월별!$A11) -> 1.41 | W10: =V10/(월별!$A11 - 월별!$A10) -> 0.047 | X10: =SUMIFS(일별!W:W, 일별!$A:$A, ">="&월별!$A10, 일별!$A:$A, "<"&월별!$A11) -> 8685 | Y10: =X10/(월별!$A11 - 월별!$A10) -> 289.5 | Z10: =SUMIFS(일별!X:X, 일별!$A:$A, ">="&월별!$A10, 일별!$A:$A, "<"&월별!$A11) -> 0 | AA10: =SUMIFS(일별!Y:Y, 일별!$A:$A, ">="&월별!$A10, 일별!$A:$A, "<"&월별!$A11) -> 0 | AB10: =SUMIFS(일별!Z:Z, 일별!$A:$A, ">="&월별!$A10, 일별!$A:$A, "<"&월별!$A11) -> 0 | AC10: =SUMIFS(일별!AA:AA, 일별!$A:$A, ">="&월별!$A10, 일별!$A:$A, "<"&월별!$A11) -> 0 | AD10: =SUMIFS(일별!AB:AB, 일별!$A:$A, ">="&월별!$A10, 일별!$A:$A, "<"&월별!$A11) -> 0 | AE10: =SUMIFS(일별!AC:AC, 일별!$A:$A, ">="&월별!$A10, 일별!$A:$A, "<"&월별!$A11) -> 0 | AF10: =SUMIFS(일별!AD:AD, 일별!$A:$A, ">="&월별!$A10, 일별!$A:$A, "<"&월별!$A11) -> 0 | AG10: =SUMIFS(일별!AE:AE, 일별!$A:$A, ">="&월별!$A10, 일별!$A:$A, "<"&월별!$A11) -> 0 | AH10: =SUMIFS(일별!AF:AF, 일별!$A:$A, ">="&월별!$A10, 일별!$A:$A, "<"&월별!$A11) -> 0 | AI10: =SUMIFS(일별!AG:AG, 일별!$A:$A, ">="&월별!$A10, 일별!$A:$A, "<"&월별!$A11) -> 0 | AJ10: =SUMIFS(일별!AX:AX, 일별!$A:$A, ">="&월별!$A10, 일별!$A:$A, "<"&월별!$A11) -> 0 | AK10: =SUMIFS(일별!AY:AY, 일별!$A:$A, ">="&월별!$A10, 일별!$A:$A, "<"&월별!$A11) -> 0 | AL10: =SUMIFS(일별!AZ:AZ, 일별!$A:$A, ">="&월별!$A10, 일별!$A:$A, "<"&월별!$A11) -> 0 | AM10: =SUMIFS(일별!BA:BA, 일별!$A:$A, ">="&월별!$A10, 일별!$A:$A, "<"&월별!$A11) -> 0 | AN10: =SUMIFS(일별!BB:BB, 일별!$A:$A, ">="&월별!$A10, 일별!$A:$A, "<"&월별!$A11) -> 0 | AO10: =SUMIFS(일별!BC:BC, 일별!$A:$A, ">="&월별!$A10, 일별!$A:$A, "<"&월별!$A11) -> 0 | AP10: {=SUM(_xlfn._xlws.FILTER(일별!#REF!, (일별!$A:$A >= 월별!$A10) * (일별!$A:$A < 월별!$A11), 0))} -> #REF! | AQ10: =AP10/(월별!$A11 - 월별!$A10) -> #REF! | AR10: {=SUM(_xlfn._xlws.FILTER(일별!#REF!, (일별!$A:$A >= 월별!$A10) * (일별!$A:$A < 월별!$A11), 0))} -> #REF! | AS10: =AR10/(월별!$A11 - 월별!$A10) -> #REF! | AT10: {=SUM(_xlfn._xlws.FILTER(일별!#REF!, (일별!$A:$A >= 월별!$A10) * (일별!$A:$A < 월별!$A11), 0))} -> #REF! | AU10: =AT10/(월별!$A11 - 월별!$A10) -> #REF! | AV10: {=SUM(_xlfn._xlws.FILTER(일별!#REF!, (일별!$A:$A >= 월별!$A10) * (일별!$A:$A < 월별!$A11), 0))} -> #REF! | AW10: {=SUM(_xlfn._xlws.FILTER(일별!#REF!, (일별!$A:$A >= 월별!$A10) * (일별!$A:$A < 월별!$A11), 0))} -> #REF! | AX10: {=SUM(_xlfn._xlws.FILTER(일별!#REF!, (일별!$A:$A >= 월별!$A10) * (일별!$A:$A < 월별!$A11), 0))} -> #REF! | AY10: {=SUM(_xlfn._xlws.FILTER(일별!#REF!, (일별!$A:$A >= 월별!$A10) * (일별!$A:$A < 월별!$A11), 0))} -> #REF! | AZ10: {=SUM(_xlfn._xlws.FILTER(일별!#REF!, (일별!$A:$A >= 월별!$A10) * (일별!$A:$A < 월별!$A11), 0))} -> #REF! | BA10: {=SUM(_xlfn._xlws.FILTER(일별!#REF!, (일별!$A:$A >= 월별!$A10) * (일별!$A:$A < 월별!$A11), 0))} -> #REF! | BB10: {=SUM(_xlfn._xlws.FILTER(일별!#REF!, (일별!$A:$A >= 월별!$A10) * (일별!$A:$A < 월별!$A11), 0))} -> #REF! | BC10: {=SUM(_xlfn._xlws.FILTER(일별!#REF!, (일별!$A:$A >= 월별!$A10) * (일별!$A:$A < 월별!$A11), 0))} -> #REF! | ... DI10: {=SUM(_xlfn._xlws.FILTER(일별!#REF!, (일별!$A:$A >= 월별!$A10) * (일별!$A:$A < 월별!$A11), 0))} -> #REF!
A11: 45839 | B11: =SUMIFS(일별!$C:$C, 일별!$A:$A, ">="&월별!$A11, 일별!$A:$A, "<"&월별!$A12) -> 241 | C11: =B11/(월별!$A12 - 월별!$A11) -> 7.7741935 | D11: =SUMIFS(일별!E:E, 일별!$A:$A, ">="&월별!$A11, 일별!$A:$A, "<"&월별!$A12) -> 710 | E11: =D11/(월별!$A12 - 월별!$A11) -> 22.903226 | F11: =SUMIFS(일별!G:G, 일별!$A:$A, ">="&월별!$A11, 일별!$A:$A, "<"&월별!$A12) -> 789 | G11: =F11/(월별!$A12 - 월별!$A11) -> 25.451613 | H11: =D11+F11 -> 1499 | I11: =E11+G11 -> 48.354839 | J11: =SUMIFS(일별!I:I, 일별!$A:$A, ">="&월별!$A11, 일별!$A:$A, "<"&월별!$A12) -> 755.67 | K11: =J11/(월별!$A12 - 월별!$A11) -> 24.376452 | L11: =SUMIFS(일별!K:K, 일별!$A:$A, ">="&월별!$A11, 일별!$A:$A, "<"&월별!$A12) -> 755.67 | M11: =L11/(월별!$A12 - 월별!$A11) -> 24.376452 | N11: =SUMIFS(일별!M:M, 일별!$A:$A, ">="&월별!$A11, 일별!$A:$A, "<"&월별!$A12) -> 17 | O11: =N11/(월별!$A12 - 월별!$A11) -> 0.5483871 | P11: =SUMIFS(일별!O:O, 일별!$A:$A, ">="&월별!$A11, 일별!$A:$A, "<"&월별!$A12) -> 1388 | Q11: =P11/(월별!$A12 - 월별!$A11) -> 44.774194 | R11: =SUMIFS(일별!Q:Q, 일별!$A:$A, ">="&월별!$A11, 일별!$A:$A, "<"&월별!$A12) -> 3218 | S11: =R11/(월별!$A12 - 월별!$A11) -> 103.80645 | T11: =SUMIFS(일별!S:S, 일별!$A:$A, ">="&월별!$A11, 일별!$A:$A, "<"&월별!$A12) -> 0.18 | U11: =T11/(월별!$A12 - 월별!$A11) -> 0.0058064516 | V11: =SUMIFS(일별!U:U, 일별!$A:$A, ">="&월별!$A11, 일별!$A:$A, "<"&월별!$A12) -> -0.2 | W11: =V11/(월별!$A12 - 월별!$A11) -> -0.0064516129 | X11: =SUMIFS(일별!W:W, 일별!$A:$A, ">="&월별!$A11, 일별!$A:$A, "<"&월별!$A12) -> -188 | Y11: =X11/(월별!$A12 - 월별!$A11) -> -6.0645161 | Z11: =SUMIFS(일별!X:X, 일별!$A:$A, ">="&월별!$A11, 일별!$A:$A, "<"&월별!$A12) -> 168601.71 | AA11: =SUMIFS(일별!Y:Y, 일별!$A:$A, ">="&월별!$A11, 일별!$A:$A, "<"&월별!$A12) -> 0 | AB11: =SUMIFS(일별!Z:Z, 일별!$A:$A, ">="&월별!$A11, 일별!$A:$A, "<"&월별!$A12) -> 0 | AC11: =SUMIFS(일별!AA:AA, 일별!$A:$A, ">="&월별!$A11, 일별!$A:$A, "<"&월별!$A12) -> 0 | AD11: =SUMIFS(일별!AB:AB, 일별!$A:$A, ">="&월별!$A11, 일별!$A:$A, "<"&월별!$A12) -> 0 | AE11: =SUMIFS(일별!AC:AC, 일별!$A:$A, ">="&월별!$A11, 일별!$A:$A, "<"&월별!$A12) -> 0 | AF11: =SUMIFS(일별!AD:AD, 일별!$A:$A, ">="&월별!$A11, 일별!$A:$A, "<"&월별!$A12) -> 71 | AG11: =SUMIFS(일별!AE:AE, 일별!$A:$A, ">="&월별!$A11, 일별!$A:$A, "<"&월별!$A12) -> 0 | AH11: =SUMIFS(일별!AF:AF, 일별!$A:$A, ">="&월별!$A11, 일별!$A:$A, "<"&월별!$A12) -> 0 | AI11: =SUMIFS(일별!AG:AG, 일별!$A:$A, ">="&월별!$A11, 일별!$A:$A, "<"&월별!$A12) -> 0 | AJ11: =SUMIFS(일별!AX:AX, 일별!$A:$A, ">="&월별!$A11, 일별!$A:$A, "<"&월별!$A12) -> 1063 | AK11: =SUMIFS(일별!AY:AY, 일별!$A:$A, ">="&월별!$A11, 일별!$A:$A, "<"&월별!$A12) -> 0 | AL11: =SUMIFS(일별!AZ:AZ, 일별!$A:$A, ">="&월별!$A11, 일별!$A:$A, "<"&월별!$A12) -> 0 | AM11: =SUMIFS(일별!BA:BA, 일별!$A:$A, ">="&월별!$A11, 일별!$A:$A, "<"&월별!$A12) -> 0 | AN11: =SUMIFS(일별!BB:BB, 일별!$A:$A, ">="&월별!$A11, 일별!$A:$A, "<"&월별!$A12) -> 0 | AO11: =SUMIFS(일별!BC:BC, 일별!$A:$A, ">="&월별!$A11, 일별!$A:$A, "<"&월별!$A12) -> 1063 | AP11: {=SUM(_xlfn._xlws.FILTER(일별!#REF!, (일별!$A:$A >= 월별!$A11) * (일별!$A:$A < 월별!$A12), 0))} -> #REF! | AQ11: =AP11/(월별!$A12 - 월별!$A11) -> #REF! | AR11: {=SUM(_xlfn._xlws.FILTER(일별!#REF!, (일별!$A:$A >= 월별!$A11) * (일별!$A:$A < 월별!$A12), 0))} -> #REF! | AS11: =AR11/(월별!$A12 - 월별!$A11) -> #REF! | AT11: {=SUM(_xlfn._xlws.FILTER(일별!#REF!, (일별!$A:$A >= 월별!$A11) * (일별!$A:$A < 월별!$A12), 0))} -> #REF! | AU11: =AT11/(월별!$A12 - 월별!$A11) -> #REF! | AV11: {=SUM(_xlfn._xlws.FILTER(일별!#REF!, (일별!$A:$A >= 월별!$A11) * (일별!$A:$A < 월별!$A12), 0))} -> #REF! | AW11: {=SUM(_xlfn._xlws.FILTER(일별!#REF!, (일별!$A:$A >= 월별!$A11) * (일별!$A:$A < 월별!$A12), 0))} -> #REF! | AX11: {=SUM(_xlfn._xlws.FILTER(일별!#REF!, (일별!$A:$A >= 월별!$A11) * (일별!$A:$A < 월별!$A12), 0))} -> #REF! | AY11: {=SUM(_xlfn._xlws.FILTER(일별!#REF!, (일별!$A:$A >= 월별!$A11) * (일별!$A:$A < 월별!$A12), 0))} -> #REF! | AZ11: {=SUM(_xlfn._xlws.FILTER(일별!#REF!, (일별!$A:$A >= 월별!$A11) * (일별!$A:$A < 월별!$A12), 0))} -> #REF! | BA11: {=SUM(_xlfn._xlws.FILTER(일별!#REF!, (일별!$A:$A >= 월별!$A11) * (일별!$A:$A < 월별!$A12), 0))} -> #REF! | BB11: {=SUM(_xlfn._xlws.FILTER(일별!#REF!, (일별!$A:$A >= 월별!$A11) * (일별!$A:$A < 월별!$A12), 0))} -> #REF! | BC11: {=SUM(_xlfn._xlws.FILTER(일별!#REF!, (일별!$A:$A >= 월별!$A11) * (일별!$A:$A < 월별!$A12), 0))} -> #REF! | ... DI11: {=SUM(_xlfn._xlws.FILTER(일별!#REF!, (일별!$A:$A >= 월별!$A11) * (일별!$A:$A < 월별!$A12), 0))} -> #REF!
A12: 45870 | B12: =SUMIFS(일별!$C:$C, 일별!$A:$A, ">="&월별!$A12, 일별!$A:$A, "<"&월별!$A13) -> 614 | C12: =B12/(월별!$A13 - 월별!$A12) -> 19.806452 | D12: =SUMIFS(일별!E:E, 일별!$A:$A, ">="&월별!$A12, 일별!$A:$A, "<"&월별!$A13) -> 1896 | E12: =D12/(월별!$A13 - 월별!$A12) -> 61.16129 | F12: =SUMIFS(일별!G:G, 일별!$A:$A, ">="&월별!$A12, 일별!$A:$A, "<"&월별!$A13) -> 1480 | G12: =F12/(월별!$A13 - 월별!$A12) -> 47.741935 | H12: =D12+F12 -> 3376 | I12: =E12+G12 -> 108.90323 | J12: =SUMIFS(일별!I:I, 일별!$A:$A, ">="&월별!$A12, 일별!$A:$A, "<"&월별!$A13) -> 610.92 | K12: =J12/(월별!$A13 - 월별!$A12) -> 19.707097 | L12: =SUMIFS(일별!K:K, 일별!$A:$A, ">="&월별!$A12, 일별!$A:$A, "<"&월별!$A13) -> 610.92 | M12: =L12/(월별!$A13 - 월별!$A12) -> 19.707097 | N12: =SUMIFS(일별!M:M, 일별!$A:$A, ">="&월별!$A12, 일별!$A:$A, "<"&월별!$A13) -> 18.5 | O12: =N12/(월별!$A13 - 월별!$A12) -> 0.59677419 | P12: =SUMIFS(일별!O:O, 일별!$A:$A, ">="&월별!$A12, 일별!$A:$A, "<"&월별!$A13) -> 1527 | Q12: =P12/(월별!$A13 - 월별!$A12) -> 49.258065 | R12: =SUMIFS(일별!Q:Q, 일별!$A:$A, ">="&월별!$A12, 일별!$A:$A, "<"&월별!$A13) -> 4819 | S12: =R12/(월별!$A13 - 월별!$A12) -> 155.45161 | T12: =SUMIFS(일별!S:S, 일별!$A:$A, ">="&월별!$A12, 일별!$A:$A, "<"&월별!$A13) -> -2.37 | U12: =T12/(월별!$A13 - 월별!$A12) -> -0.076451613 | V12: =SUMIFS(일별!U:U, 일별!$A:$A, ">="&월별!$A12, 일별!$A:$A, "<"&월별!$A13) -> -2.19 | W12: =V12/(월별!$A13 - 월별!$A12) -> -0.070645161 | X12: =SUMIFS(일별!W:W, 일별!$A:$A, ">="&월별!$A12, 일별!$A:$A, "<"&월별!$A13) -> -432 | Y12: =X12/(월별!$A13 - 월별!$A12) -> -13.935484 | Z12: =SUMIFS(일별!X:X, 일별!$A:$A, ">="&월별!$A12, 일별!$A:$A, "<"&월별!$A13) -> 134591.6 | AA12: =SUMIFS(일별!Y:Y, 일별!$A:$A, ">="&월별!$A12, 일별!$A:$A, "<"&월별!$A13) -> 0 | AB12: =SUMIFS(일별!Z:Z, 일별!$A:$A, ">="&월별!$A12, 일별!$A:$A, "<"&월별!$A13) -> 0 | AC12: =SUMIFS(일별!AA:AA, 일별!$A:$A, ">="&월별!$A12, 일별!$A:$A, "<"&월별!$A13) -> 0 | AD12: =SUMIFS(일별!AB:AB, 일별!$A:$A, ">="&월별!$A12, 일별!$A:$A, "<"&월별!$A13) -> 0 | AE12: =SUMIFS(일별!AC:AC, 일별!$A:$A, ">="&월별!$A12, 일별!$A:$A, "<"&월별!$A13) -> 0 | AF12: =SUMIFS(일별!AD:AD, 일별!$A:$A, ">="&월별!$A12, 일별!$A:$A, "<"&월별!$A13) -> 57 | AG12: =SUMIFS(일별!AE:AE, 일별!$A:$A, ">="&월별!$A12, 일별!$A:$A, "<"&월별!$A13) -> 0 | AH12: =SUMIFS(일별!AF:AF, 일별!$A:$A, ">="&월별!$A12, 일별!$A:$A, "<"&월별!$A13) -> 0 | AI12: =SUMIFS(일별!AG:AG, 일별!$A:$A, ">="&월별!$A12, 일별!$A:$A, "<"&월별!$A13) -> 0 | AJ12: =SUMIFS(일별!AX:AX, 일별!$A:$A, ">="&월별!$A12, 일별!$A:$A, "<"&월별!$A13) -> 840 | AK12: =SUMIFS(일별!AY:AY, 일별!$A:$A, ">="&월별!$A12, 일별!$A:$A, "<"&월별!$A13) -> 0 | AL12: =SUMIFS(일별!AZ:AZ, 일별!$A:$A, ">="&월별!$A12, 일별!$A:$A, "<"&월별!$A13) -> 0 | AM12: =SUMIFS(일별!BA:BA, 일별!$A:$A, ">="&월별!$A12, 일별!$A:$A, "<"&월별!$A13) -> 0 | AN12: =SUMIFS(일별!BB:BB, 일별!$A:$A, ">="&월별!$A12, 일별!$A:$A, "<"&월별!$A13) -> 0 | AO12: =SUMIFS(일별!BC:BC, 일별!$A:$A, ">="&월별!$A12, 일별!$A:$A, "<"&월별!$A13) -> 840 | AP12: {=SUM(_xlfn._xlws.FILTER(일별!#REF!, (일별!$A:$A >= 월별!$A12) * (일별!$A:$A < 월별!$A13), 0))} -> #REF! | AQ12: =AP12/(월별!$A13 - 월별!$A12) -> #REF! | AR12: {=SUM(_xlfn._xlws.FILTER(일별!#REF!, (일별!$A:$A >= 월별!$A12) * (일별!$A:$A < 월별!$A13), 0))} -> #REF! | AS12: =AR12/(월별!$A13 - 월별!$A12) -> #REF! | AT12: {=SUM(_xlfn._xlws.FILTER(일별!#REF!, (일별!$A:$A >= 월별!$A12) * (일별!$A:$A < 월별!$A13), 0))} -> #REF! | AU12: =AT12/(월별!$A13 - 월별!$A12) -> #REF! | AV12: {=SUM(_xlfn._xlws.FILTER(일별!#REF!, (일별!$A:$A >= 월별!$A12) * (일별!$A:$A < 월별!$A13), 0))} -> #REF! | AW12: {=SUM(_xlfn._xlws.FILTER(일별!#REF!, (일별!$A:$A >= 월별!$A12) * (일별!$A:$A < 월별!$A13), 0))} -> #REF! | AX12: {=SUM(_xlfn._xlws.FILTER(일별!#REF!, (일별!$A:$A >= 월별!$A12) * (일별!$A:$A < 월별!$A13), 0))} -> #REF! | AY12: {=SUM(_xlfn._xlws.FILTER(일별!#REF!, (일별!$A:$A >= 월별!$A12) * (일별!$A:$A < 월별!$A13), 0))} -> #REF! | AZ12: {=SUM(_xlfn._xlws.FILTER(일별!#REF!, (일별!$A:$A >= 월별!$A12) * (일별!$A:$A < 월별!$A13), 0))} -> #REF! | BA12: {=SUM(_xlfn._xlws.FILTER(일별!#REF!, (일별!$A:$A >= 월별!$A12) * (일별!$A:$A < 월별!$A13), 0))} -> #REF! | BB12: {=SUM(_xlfn._xlws.FILTER(일별!#REF!, (일별!$A:$A >= 월별!$A12) * (일별!$A:$A < 월별!$A13), 0))} -> #REF! | BC12: {=SUM(_xlfn._xlws.FILTER(일별!#REF!, (일별!$A:$A >= 월별!$A12) * (일별!$A:$A < 월별!$A13), 0))} -> #REF! | ... DI12: {=SUM(_xlfn._xlws.FILTER(일별!#REF!, (일별!$A:$A >= 월별!$A12) * (일별!$A:$A < 월별!$A13), 0))} -> #REF!
A13: 45901 | B13: =SUMIFS(일별!$C:$C, 일별!$A:$A, ">="&월별!$A13, 일별!$A:$A, "<"&월별!$A14) -> 567 | C13: =B13/(월별!$A14 - 월별!$A13) -> 18.9 | D13: =SUMIFS(일별!E:E, 일별!$A:$A, ">="&월별!$A13, 일별!$A:$A, "<"&월별!$A14) -> 2322 | E13: =D13/(월별!$A14 - 월별!$A13) -> 77.4 | F13: =SUMIFS(일별!G:G, 일별!$A:$A, ">="&월별!$A13, 일별!$A:$A, "<"&월별!$A14) -> 2115 | G13: =F13/(월별!$A14 - 월별!$A13) -> 70.5 | H13: =D13+F13 -> 4437 | I13: =E13+G13 -> 147.9 | J13: =SUMIFS(일별!I:I, 일별!$A:$A, ">="&월별!$A13, 일별!$A:$A, "<"&월별!$A14) -> 547.08 | K13: =J13/(월별!$A14 - 월별!$A13) -> 18.236 | L13: =SUMIFS(일별!K:K, 일별!$A:$A, ">="&월별!$A13, 일별!$A:$A, "<"&월별!$A14) -> 547.08 | M13: =L13/(월별!$A14 - 월별!$A13) -> 18.236 | N13: =SUMIFS(일별!M:M, 일별!$A:$A, ">="&월별!$A13, 일별!$A:$A, "<"&월별!$A14) -> 32.2 | O13: =N13/(월별!$A14 - 월별!$A13) -> 1.0733333 | P13: =SUMIFS(일별!O:O, 일별!$A:$A, ">="&월별!$A13, 일별!$A:$A, "<"&월별!$A14) -> 3136 | Q13: =P13/(월별!$A14 - 월별!$A13) -> 104.53333 | R13: =SUMIFS(일별!Q:Q, 일별!$A:$A, ">="&월별!$A13, 일별!$A:$A, "<"&월별!$A14) -> -283026 | S13: =R13/(월별!$A14 - 월별!$A13) -> -9434.2 | T13: =SUMIFS(일별!S:S, 일별!$A:$A, ">="&월별!$A13, 일별!$A:$A, "<"&월별!$A14) -> 2.4 | U13: =T13/(월별!$A14 - 월별!$A13) -> 0.08 | V13: =SUMIFS(일별!U:U, 일별!$A:$A, ">="&월별!$A13, 일별!$A:$A, "<"&월별!$A14) -> 2.49 | W13: =V13/(월별!$A14 - 월별!$A13) -> 0.083 | X13: =SUMIFS(일별!W:W, 일별!$A:$A, ">="&월별!$A13, 일별!$A:$A, "<"&월별!$A14) -> 585 | Y13: =X13/(월별!$A14 - 월별!$A13) -> 19.5 | Z13: =SUMIFS(일별!X:X, 일별!$A:$A, ">="&월별!$A13, 일별!$A:$A, "<"&월별!$A14) -> 20142.37 | AA13: =SUMIFS(일별!Y:Y, 일별!$A:$A, ">="&월별!$A13, 일별!$A:$A, "<"&월별!$A14) -> 0 | AB13: =SUMIFS(일별!Z:Z, 일별!$A:$A, ">="&월별!$A13, 일별!$A:$A, "<"&월별!$A14) -> 0 | AC13: =SUMIFS(일별!AA:AA, 일별!$A:$A, ">="&월별!$A13, 일별!$A:$A, "<"&월별!$A14) -> 0 | AD13: =SUMIFS(일별!AB:AB, 일별!$A:$A, ">="&월별!$A13, 일별!$A:$A, "<"&월별!$A14) -> 0 | AE13: =SUMIFS(일별!AC:AC, 일별!$A:$A, ">="&월별!$A13, 일별!$A:$A, "<"&월별!$A14) -> 0 | AF13: =SUMIFS(일별!AD:AD, 일별!$A:$A, ">="&월별!$A13, 일별!$A:$A, "<"&월별!$A14) -> 11 | AG13: =SUMIFS(일별!AE:AE, 일별!$A:$A, ">="&월별!$A13, 일별!$A:$A, "<"&월별!$A14) -> 0 | AH13: =SUMIFS(일별!AF:AF, 일별!$A:$A, ">="&월별!$A13, 일별!$A:$A, "<"&월별!$A14) -> 0 | AI13: =SUMIFS(일별!AG:AG, 일별!$A:$A, ">="&월별!$A13, 일별!$A:$A, "<"&월별!$A14) -> 0 | AJ13: =SUMIFS(일별!AX:AX, 일별!$A:$A, ">="&월별!$A13, 일별!$A:$A, "<"&월별!$A14) -> 115 | AK13: =SUMIFS(일별!AY:AY, 일별!$A:$A, ">="&월별!$A13, 일별!$A:$A, "<"&월별!$A14) -> 0 | AL13: =SUMIFS(일별!AZ:AZ, 일별!$A:$A, ">="&월별!$A13, 일별!$A:$A, "<"&월별!$A14) -> 0 | AM13: =SUMIFS(일별!BA:BA, 일별!$A:$A, ">="&월별!$A13, 일별!$A:$A, "<"&월별!$A14) -> 0 | AN13: =SUMIFS(일별!BB:BB, 일별!$A:$A, ">="&월별!$A13, 일별!$A:$A, "<"&월별!$A14) -> 0 | AO13: =SUMIFS(일별!BC:BC, 일별!$A:$A, ">="&월별!$A13, 일별!$A:$A, "<"&월별!$A14) -> 115 | AP13: {=SUM(_xlfn._xlws.FILTER(일별!#REF!, (일별!$A:$A >= 월별!$A13) * (일별!$A:$A < 월별!$A14), 0))} -> #REF! | AQ13: =AP13/(월별!$A14 - 월별!$A13) -> #REF! | AR13: {=SUM(_xlfn._xlws.FILTER(일별!#REF!, (일별!$A:$A >= 월별!$A13) * (일별!$A:$A < 월별!$A14), 0))} -> #REF! | AS13: =AR13/(월별!$A14 - 월별!$A13) -> #REF! | AT13: {=SUM(_xlfn._xlws.FILTER(일별!#REF!, (일별!$A:$A >= 월별!$A13) * (일별!$A:$A < 월별!$A14), 0))} -> #REF! | AU13: =AT13/(월별!$A14 - 월별!$A13) -> #REF! | AV13: {=SUM(_xlfn._xlws.FILTER(일별!#REF!, (일별!$A:$A >= 월별!$A13) * (일별!$A:$A < 월별!$A14), 0))} -> #REF! | AW13: {=SUM(_xlfn._xlws.FILTER(일별!#REF!, (일별!$A:$A >= 월별!$A13) * (일별!$A:$A < 월별!$A14), 0))} -> #REF! | AX13: {=SUM(_xlfn._xlws.FILTER(일별!#REF!, (일별!$A:$A >= 월별!$A13) * (일별!$A:$A < 월별!$A14), 0))} -> #REF! | AY13: {=SUM(_xlfn._xlws.FILTER(일별!#REF!, (일별!$A:$A >= 월별!$A13) * (일별!$A:$A < 월별!$A14), 0))} -> #REF! | AZ13: {=SUM(_xlfn._xlws.FILTER(일별!#REF!, (일별!$A:$A >= 월별!$A13) * (일별!$A:$A < 월별!$A14), 0))} -> #REF! | BA13: {=SUM(_xlfn._xlws.FILTER(일별!#REF!, (일별!$A:$A >= 월별!$A13) * (일별!$A:$A < 월별!$A14), 0))} -> #REF! | BB13: {=SUM(_xlfn._xlws.FILTER(일별!#REF!, (일별!$A:$A >= 월별!$A13) * (일별!$A:$A < 월별!$A14), 0))} -> #REF! | BC13: {=SUM(_xlfn._xlws.FILTER(일별!#REF!, (일별!$A:$A >= 월별!$A13) * (일별!$A:$A < 월별!$A14), 0))} -> #REF! | ... DI13: {=SUM(_xlfn._xlws.FILTER(일별!#REF!, (일별!$A:$A >= 월별!$A13) * (일별!$A:$A < 월별!$A14), 0))} -> #REF!
A14: 45931 | B14: =SUMIFS(일별!$C:$C, 일별!$A:$A, ">="&월별!$A14, 일별!$A:$A, "<"&월별!$A15) -> 210 | C14: =B14/(월별!$A15 - 월별!$A14) -> 6.7741935 | D14: =SUMIFS(일별!E:E, 일별!$A:$A, ">="&월별!$A14, 일별!$A:$A, "<"&월별!$A15) -> 1254 | E14: =D14/(월별!$A15 - 월별!$A14) -> 40.451613 | F14: =SUMIFS(일별!G:G, 일별!$A:$A, ">="&월별!$A14, 일별!$A:$A, "<"&월별!$A15) -> 981 | G14: =F14/(월별!$A15 - 월별!$A14) -> 31.645161 | H14: =D14+F14 -> 2235 | I14: =E14+G14 -> 72.096774 | J14: =SUMIFS(일별!I:I, 일별!$A:$A, ">="&월별!$A14, 일별!$A:$A, "<"&월별!$A15) -> 124.12 | K14: =J14/(월별!$A15 - 월별!$A14) -> 4.003871 | L14: =SUMIFS(일별!K:K, 일별!$A:$A, ">="&월별!$A14, 일별!$A:$A, "<"&월별!$A15) -> 124.12 | M14: =L14/(월별!$A15 - 월별!$A14) -> 4.003871 | N14: =SUMIFS(일별!M:M, 일별!$A:$A, ">="&월별!$A14, 일별!$A:$A, "<"&월별!$A15) -> 27.3 | O14: =N14/(월별!$A15 - 월별!$A14) -> 0.88064516 | P14: =SUMIFS(일별!O:O, 일별!$A:$A, ">="&월별!$A14, 일별!$A:$A, "<"&월별!$A15) -> 2907 | Q14: =P14/(월별!$A15 - 월별!$A14) -> 93.774194 | R14: =SUMIFS(일별!Q:Q, 일별!$A:$A, ">="&월별!$A14, 일별!$A:$A, "<"&월별!$A15) -> 2860 | S14: =R14/(월별!$A15 - 월별!$A14) -> 92.258065 | T14: =SUMIFS(일별!S:S, 일별!$A:$A, ">="&월별!$A14, 일별!$A:$A, "<"&월별!$A15) -> 0.06 | U14: =T14/(월별!$A15 - 월별!$A14) -> 0.0019354839 | V14: =SUMIFS(일별!U:U, 일별!$A:$A, ">="&월별!$A14, 일별!$A:$A, "<"&월별!$A15) -> -0.41 | W14: =V14/(월별!$A15 - 월별!$A14) -> -0.013225806 | X14: =SUMIFS(일별!W:W, 일별!$A:$A, ">="&월별!$A14, 일별!$A:$A, "<"&월별!$A15) -> -3816 | Y14: =X14/(월별!$A15 - 월별!$A14) -> -123.09677 | Z14: =SUMIFS(일별!X:X, 일별!$A:$A, ">="&월별!$A14, 일별!$A:$A, "<"&월별!$A15) -> 53261.56 | AA14: =SUMIFS(일별!Y:Y, 일별!$A:$A, ">="&월별!$A14, 일별!$A:$A, "<"&월별!$A15) -> 0 | AB14: =SUMIFS(일별!Z:Z, 일별!$A:$A, ">="&월별!$A14, 일별!$A:$A, "<"&월별!$A15) -> 0 | AC14: =SUMIFS(일별!AA:AA, 일별!$A:$A, ">="&월별!$A14, 일별!$A:$A, "<"&월별!$A15) -> 0 | AD14: =SUMIFS(일별!AB:AB, 일별!$A:$A, ">="&월별!$A14, 일별!$A:$A, "<"&월별!$A15) -> 0 | AE14: =SUMIFS(일별!AC:AC, 일별!$A:$A, ">="&월별!$A14, 일별!$A:$A, "<"&월별!$A15) -> 0 | AF14: =SUMIFS(일별!AD:AD, 일별!$A:$A, ">="&월별!$A14, 일별!$A:$A, "<"&월별!$A15) -> 14 | AG14: =SUMIFS(일별!AE:AE, 일별!$A:$A, ">="&월별!$A14, 일별!$A:$A, "<"&월별!$A15) -> 0 | AH14: =SUMIFS(일별!AF:AF, 일별!$A:$A, ">="&월별!$A14, 일별!$A:$A, "<"&월별!$A15) -> 0 | AI14: =SUMIFS(일별!AG:AG, 일별!$A:$A, ">="&월별!$A14, 일별!$A:$A, "<"&월별!$A15) -> 0 | AJ14: =SUMIFS(일별!AX:AX, 일별!$A:$A, ">="&월별!$A14, 일별!$A:$A, "<"&월별!$A15) -> 313 | AK14: =SUMIFS(일별!AY:AY, 일별!$A:$A, ">="&월별!$A14, 일별!$A:$A, "<"&월별!$A15) -> 0 | AL14: =SUMIFS(일별!AZ:AZ, 일별!$A:$A, ">="&월별!$A14, 일별!$A:$A, "<"&월별!$A15) -> 0 | AM14: =SUMIFS(일별!BA:BA, 일별!$A:$A, ">="&월별!$A14, 일별!$A:$A, "<"&월별!$A15) -> 0 | AN14: =SUMIFS(일별!BB:BB, 일별!$A:$A, ">="&월별!$A14, 일별!$A:$A, "<"&월별!$A15) -> 0 | AO14: =SUMIFS(일별!BC:BC, 일별!$A:$A, ">="&월별!$A14, 일별!$A:$A, "<"&월별!$A15) -> 313 | AP14: {=SUM(_xlfn._xlws.FILTER(일별!#REF!, (일별!$A:$A >= 월별!$A14) * (일별!$A:$A < 월별!$A15), 0))} -> #REF! | AQ14: =AP14/(월별!$A15 - 월별!$A14) -> #REF! | AR14: {=SUM(_xlfn._xlws.FILTER(일별!#REF!, (일별!$A:$A >= 월별!$A14) * (일별!$A:$A < 월별!$A15), 0))} -> #REF! | AS14: =AR14/(월별!$A15 - 월별!$A14) -> #REF! | AT14: {=SUM(_xlfn._xlws.FILTER(일별!#REF!, (일별!$A:$A >= 월별!$A14) * (일별!$A:$A < 월별!$A15), 0))} -> #REF! | AU14: =AT14/(월별!$A15 - 월별!$A14) -> #REF! | AV14: {=SUM(_xlfn._xlws.FILTER(일별!#REF!, (일별!$A:$A >= 월별!$A14) * (일별!$A:$A < 월별!$A15), 0))} -> #REF! | AW14: {=SUM(_xlfn._xlws.FILTER(일별!#REF!, (일별!$A:$A >= 월별!$A14) * (일별!$A:$A < 월별!$A15), 0))} -> #REF! | AX14: {=SUM(_xlfn._xlws.FILTER(일별!#REF!, (일별!$A:$A >= 월별!$A14) * (일별!$A:$A < 월별!$A15), 0))} -> #REF! | AY14: {=SUM(_xlfn._xlws.FILTER(일별!#REF!, (일별!$A:$A >= 월별!$A14) * (일별!$A:$A < 월별!$A15), 0))} -> #REF! | AZ14: {=SUM(_xlfn._xlws.FILTER(일별!#REF!, (일별!$A:$A >= 월별!$A14) * (일별!$A:$A < 월별!$A15), 0))} -> #REF! | BA14: {=SUM(_xlfn._xlws.FILTER(일별!#REF!, (일별!$A:$A >= 월별!$A14) * (일별!$A:$A < 월별!$A15), 0))} -> #REF! | BB14: {=SUM(_xlfn._xlws.FILTER(일별!#REF!, (일별!$A:$A >= 월별!$A14) * (일별!$A:$A < 월별!$A15), 0))} -> #REF! | BC14: {=SUM(_xlfn._xlws.FILTER(일별!#REF!, (일별!$A:$A >= 월별!$A14) * (일별!$A:$A < 월별!$A15), 0))} -> #REF! | ... DI14: {=SUM(_xlfn._xlws.FILTER(일별!#REF!, (일별!$A:$A >= 월별!$A14) * (일별!$A:$A < 월별!$A15), 0))} -> #REF!
A15: 45962 | B15: =SUMIFS(일별!$C:$C, 일별!$A:$A, ">="&월별!$A15, 일별!$A:$A, "<"&월별!$A16) -> 251 | C15: =B15/(월별!$A16 - 월별!$A15) -> 8.3666667 | D15: =SUMIFS(일별!E:E, 일별!$A:$A, ">="&월별!$A15, 일별!$A:$A, "<"&월별!$A16) -> 1617 | E15: =D15/(월별!$A16 - 월별!$A15) -> 53.9 | F15: =SUMIFS(일별!G:G, 일별!$A:$A, ">="&월별!$A15, 일별!$A:$A, "<"&월별!$A16) -> 1136 | G15: =F15/(월별!$A16 - 월별!$A15) -> 37.866667 | H15: =D15+F15 -> 2753 | I15: =E15+G15 -> 91.766667 | J15: =SUMIFS(일별!I:I, 일별!$A:$A, ">="&월별!$A15, 일별!$A:$A, "<"&월별!$A16) -> 150.71 | K15: =J15/(월별!$A16 - 월별!$A15) -> 5.0236667 | L15: =SUMIFS(일별!K:K, 일별!$A:$A, ">="&월별!$A15, 일별!$A:$A, "<"&월별!$A16) -> 150.71 | M15: =L15/(월별!$A16 - 월별!$A15) -> 5.0236667 | N15: =SUMIFS(일별!M:M, 일별!$A:$A, ">="&월별!$A15, 일별!$A:$A, "<"&월별!$A16) -> 29.2 | O15: =N15/(월별!$A16 - 월별!$A15) -> 0.97333333 | P15: =SUMIFS(일별!O:O, 일별!$A:$A, ">="&월별!$A15, 일별!$A:$A, "<"&월별!$A16) -> 2996 | Q15: =P15/(월별!$A16 - 월별!$A15) -> 99.866667 | R15: =SUMIFS(일별!Q:Q, 일별!$A:$A, ">="&월별!$A15, 일별!$A:$A, "<"&월별!$A16) -> 4193 | S15: =R15/(월별!$A16 - 월별!$A15) -> 139.76667 | T15: =SUMIFS(일별!S:S, 일별!$A:$A, ">="&월별!$A15, 일별!$A:$A, "<"&월별!$A16) -> -0.24 | U15: =T15/(월별!$A16 - 월별!$A15) -> -0.008 | V15: =SUMIFS(일별!U:U, 일별!$A:$A, ">="&월별!$A15, 일별!$A:$A, "<"&월별!$A16) -> 0 | W15: =V15/(월별!$A16 - 월별!$A15) -> 0 | X15: =SUMIFS(일별!W:W, 일별!$A:$A, ">="&월별!$A15, 일별!$A:$A, "<"&월별!$A16) -> 3408 | Y15: =X15/(월별!$A16 - 월별!$A15) -> 113.6 | Z15: =SUMIFS(일별!X:X, 일별!$A:$A, ">="&월별!$A15, 일별!$A:$A, "<"&월별!$A16) -> 1253170.9 | AA15: =SUMIFS(일별!Y:Y, 일별!$A:$A, ">="&월별!$A15, 일별!$A:$A, "<"&월별!$A16) -> 0 | AB15: =SUMIFS(일별!Z:Z, 일별!$A:$A, ">="&월별!$A15, 일별!$A:$A, "<"&월별!$A16) -> 0 | AC15: =SUMIFS(일별!AA:AA, 일별!$A:$A, ">="&월별!$A15, 일별!$A:$A, "<"&월별!$A16) -> 0 | AD15: =SUMIFS(일별!AB:AB, 일별!$A:$A, ">="&월별!$A15, 일별!$A:$A, "<"&월별!$A16) -> 0 | AE15: =SUMIFS(일별!AC:AC, 일별!$A:$A, ">="&월별!$A15, 일별!$A:$A, "<"&월별!$A16) -> 0 | AF15: =SUMIFS(일별!AD:AD, 일별!$A:$A, ">="&월별!$A15, 일별!$A:$A, "<"&월별!$A16) -> 189 | AG15: =SUMIFS(일별!AE:AE, 일별!$A:$A, ">="&월별!$A15, 일별!$A:$A, "<"&월별!$A16) -> 0 | AH15: =SUMIFS(일별!AF:AF, 일별!$A:$A, ">="&월별!$A15, 일별!$A:$A, "<"&월별!$A16) -> 0 | AI15: =SUMIFS(일별!AG:AG, 일별!$A:$A, ">="&월별!$A15, 일별!$A:$A, "<"&월별!$A16) -> 0 | AJ15: =SUMIFS(일별!AX:AX, 일별!$A:$A, ">="&월별!$A15, 일별!$A:$A, "<"&월별!$A16) -> 7865 | AK15: =SUMIFS(일별!AY:AY, 일별!$A:$A, ">="&월별!$A15, 일별!$A:$A, "<"&월별!$A16) -> 0 | AL15: =SUMIFS(일별!AZ:AZ, 일별!$A:$A, ">="&월별!$A15, 일별!$A:$A, "<"&월별!$A16) -> 0 | AM15: =SUMIFS(일별!BA:BA, 일별!$A:$A, ">="&월별!$A15, 일별!$A:$A, "<"&월별!$A16) -> 0 | AN15: =SUMIFS(일별!BB:BB, 일별!$A:$A, ">="&월별!$A15, 일별!$A:$A, "<"&월별!$A16) -> 0 | AO15: =SUMIFS(일별!BC:BC, 일별!$A:$A, ">="&월별!$A15, 일별!$A:$A, "<"&월별!$A16) -> 7865 | AP15: {=SUM(_xlfn._xlws.FILTER(일별!#REF!, (일별!$A:$A >= 월별!$A15) * (일별!$A:$A < 월별!$A16), 0))} -> #REF! | AQ15: =AP15/(월별!$A16 - 월별!$A15) -> #REF! | AR15: {=SUM(_xlfn._xlws.FILTER(일별!#REF!, (일별!$A:$A >= 월별!$A15) * (일별!$A:$A < 월별!$A16), 0))} -> #REF! | AS15: =AR15/(월별!$A16 - 월별!$A15) -> #REF! | AT15: {=SUM(_xlfn._xlws.FILTER(일별!#REF!, (일별!$A:$A >= 월별!$A15) * (일별!$A:$A < 월별!$A16), 0))} -> #REF! | AU15: =AT15/(월별!$A16 - 월별!$A15) -> #REF! | AV15: {=SUM(_xlfn._xlws.FILTER(일별!#REF!, (일별!$A:$A >= 월별!$A15) * (일별!$A:$A < 월별!$A16), 0))} -> #REF! | AW15: {=SUM(_xlfn._xlws.FILTER(일별!#REF!, (일별!$A:$A >= 월별!$A15) * (일별!$A:$A < 월별!$A16), 0))} -> #REF! | AX15: {=SUM(_xlfn._xlws.FILTER(일별!#REF!, (일별!$A:$A >= 월별!$A15) * (일별!$A:$A < 월별!$A16), 0))} -> #REF! | AY15: {=SUM(_xlfn._xlws.FILTER(일별!#REF!, (일별!$A:$A >= 월별!$A15) * (일별!$A:$A < 월별!$A16), 0))} -> #REF! | AZ15: {=SUM(_xlfn._xlws.FILTER(일별!#REF!, (일별!$A:$A >= 월별!$A15) * (일별!$A:$A < 월별!$A16), 0))} -> #REF! | BA15: {=SUM(_xlfn._xlws.FILTER(일별!#REF!, (일별!$A:$A >= 월별!$A15) * (일별!$A:$A < 월별!$A16), 0))} -> #REF! | BB15: {=SUM(_xlfn._xlws.FILTER(일별!#REF!, (일별!$A:$A >= 월별!$A15) * (일별!$A:$A < 월별!$A16), 0))} -> #REF! | BC15: {=SUM(_xlfn._xlws.FILTER(일별!#REF!, (일별!$A:$A >= 월별!$A15) * (일별!$A:$A < 월별!$A16), 0))} -> #REF! | ... DI15: {=SUM(_xlfn._xlws.FILTER(일별!#REF!, (일별!$A:$A >= 월별!$A15) * (일별!$A:$A < 월별!$A16), 0))} -> #REF!
A16: 45992 | B16: =SUMIFS(일별!$C:$C, 일별!$A:$A, ">="&월별!$A16, 일별!$A:$A, "<"&월별!$A4) -> 190.2 | C16: =B16/(월별!$A4 - 월별!$A16) -> 0.48030303 | D16: =SUMIFS(일별!E:E, 일별!$A:$A, ">="&월별!$A16, 일별!$A:$A, "<"&월별!$A17) -> 0 | E16: =D16/(월별!$A4 - 월별!$A16) -> 0 | F16: =SUMIFS(일별!G:G, 일별!$A:$A, ">="&월별!$A16, 일별!$A:$A, "<"&월별!$A17) -> 0 | G16: =F16/(월별!$A4 - 월별!$A16) -> 0 | H16: =D16+F16 -> 0 | I16: =E16+G16 -> 0 | J16: =SUMIFS(일별!I:I, 일별!$A:$A, ">="&월별!$A16, 일별!$A:$A, "<"&월별!$A17) -> 0 | K16: =J16/(월별!$A4 - 월별!$A16) -> 0 | L16: =SUMIFS(일별!K:K, 일별!$A:$A, ">="&월별!$A16, 일별!$A:$A, "<"&월별!$A17) -> 0 | M16: =L16/(월별!$A4 - 월별!$A16) -> 0 | N16: =SUMIFS(일별!M:M, 일별!$A:$A, ">="&월별!$A16, 일별!$A:$A, "<"&월별!$A17) -> 0 | O16: =N16/(월별!$A4 - 월별!$A16) -> 0 | P16: =SUMIFS(일별!O:O, 일별!$A:$A, ">="&월별!$A16, 일별!$A:$A, "<"&월별!$A17) -> 0 | Q16: =P16/(월별!$A4 - 월별!$A16) -> 0 | R16: =SUMIFS(일별!Q:Q, 일별!$A:$A, ">="&월별!$A16, 일별!$A:$A, "<"&월별!$A17) -> 0 | S16: =R16/(월별!$A4 - 월별!$A16) -> 0 | T16: =SUMIFS(일별!S:S, 일별!$A:$A, ">="&월별!$A16, 일별!$A:$A, "<"&월별!$A17) -> 0 | U16: =T16/(월별!$A4 - 월별!$A16) -> 0 | V16: =SUMIFS(일별!U:U, 일별!$A:$A, ">="&월별!$A16, 일별!$A:$A, "<"&월별!$A17) -> 0 | W16: =V16/(월별!$A4 - 월별!$A16) -> 0 | X16: =SUMIFS(일별!W:W, 일별!$A:$A, ">="&월별!$A16, 일별!$A:$A, "<"&월별!$A17) -> 0 | Y16: =X16/(월별!$A4 - 월별!$A16) -> 0 | Z16: =SUMIFS(일별!X:X, 일별!$A:$A, ">="&월별!$A16, 일별!$A:$A, "<"&월별!$A4) -> 4421582.2 | AA16: =SUMIFS(일별!Y:Y, 일별!$A:$A, ">="&월별!$A16, 일별!$A:$A, "<"&월별!$A4) -> 0 | AB16: =SUMIFS(일별!Z:Z, 일별!$A:$A, ">="&월별!$A16, 일별!$A:$A, "<"&월별!$A4) -> 0 | AC16: =SUMIFS(일별!AA:AA, 일별!$A:$A, ">="&월별!$A16, 일별!$A:$A, "<"&월별!$A4) -> 79246.8 | AD16: =SUMIFS(일별!AB:AB, 일별!$A:$A, ">="&월별!$A16, 일별!$A:$A, "<"&월별!$A4) -> 0 | AE16: =SUMIFS(일별!AC:AC, 일별!$A:$A, ">="&월별!$A16, 일별!$A:$A, "<"&월별!$A4) -> 79246.8 | AF16: =SUMIFS(일별!AD:AD, 일별!$A:$A, ">="&월별!$A16, 일별!$A:$A, "<"&월별!$A4) -> 592 | AG16: =SUMIFS(일별!AE:AE, 일별!$A:$A, ">="&월별!$A16, 일별!$A:$A, "<"&월별!$A4) -> 0 | AH16: =SUMIFS(일별!AF:AF, 일별!$A:$A, ">="&월별!$A16, 일별!$A:$A, "<"&월별!$A4) -> 0 | AI16: =SUMIFS(일별!AG:AG, 일별!$A:$A, ">="&월별!$A16, 일별!$A:$A, "<"&월별!$A4) -> 12 | AJ16: =SUMIFS(일별!AX:AX, 일별!$A:$A, ">="&월별!$A16, 일별!$A:$A, "<"&월별!$A4) -> 27963 | AK16: =SUMIFS(일별!AY:AY, 일별!$A:$A, ">="&월별!$A16, 일별!$A:$A, "<"&월별!$A4) -> 0 | AL16: =SUMIFS(일별!AZ:AZ, 일별!$A:$A, ">="&월별!$A16, 일별!$A:$A, "<"&월별!$A4) -> 0 | AM16: =SUMIFS(일별!BA:BA, 일별!$A:$A, ">="&월별!$A16, 일별!$A:$A, "<"&월별!$A4) -> 700 | AN16: =SUMIFS(일별!BB:BB, 일별!$A:$A, ">="&월별!$A16, 일별!$A:$A, "<"&월별!$A4) -> 700 | AO16: =SUMIFS(일별!BC:BC, 일별!$A:$A, ">="&월별!$A16, 일별!$A:$A, "<"&월별!$A4) -> 28663 | AP16: {=SUM(_xlfn._xlws.FILTER(일별!#REF!, (일별!$A:$A >= 월별!$A16) * (일별!$A:$A < $A4), 0))} -> #REF! | AQ16: =AP16/($A4 - 월별!$A16) -> #REF! | AR16: {=SUM(_xlfn._xlws.FILTER(일별!#REF!, (일별!$A:$A >= 월별!$A16) * (일별!$A:$A < $A4), 0))} -> #REF! | AS16: =AR16/($A4 - 월별!$A16) -> #REF! | AT16: {=SUM(_xlfn._xlws.FILTER(일별!#REF!, (일별!$A:$A >= 월별!$A16) * (일별!$A:$A < 월별!$A17), 0))} -> #REF! | AU16: =AT16/($A4 - 월별!$A16) -> #REF! | AV16: {=SUM(_xlfn._xlws.FILTER(일별!#REF!, (일별!$A:$A >= 월별!$A16) * (일별!$A:$A < 월별!$A17), 0))} -> #REF! | AW16: {=SUM(_xlfn._xlws.FILTER(일별!#REF!, (일별!$A:$A >= 월별!$A16) * (일별!$A:$A < 월별!$A17), 0))} -> #REF! | AX16: {=SUM(_xlfn._xlws.FILTER(일별!#REF!, (일별!$A:$A >= 월별!$A16) * (일별!$A:$A < 월별!$A17), 0))} -> #REF! | AY16: {=SUM(_xlfn._xlws.FILTER(일별!#REF!, (일별!$A:$A >= 월별!$A16) * (일별!$A:$A < 월별!$A17), 0))} -> #REF! | AZ16: {=SUM(_xlfn._xlws.FILTER(일별!#REF!, (일별!$A:$A >= 월별!$A16) * (일별!$A:$A < 월별!$A17), 0))} -> #REF! | BA16: {=SUM(_xlfn._xlws.FILTER(일별!#REF!, (일별!$A:$A >= 월별!$A16) * (일별!$A:$A < 월별!$A17), 0))} -> #REF! | BB16: {=SUM(_xlfn._xlws.FILTER(일별!#REF!, (일별!$A:$A >= 월별!$A16) * (일별!$A:$A < 월별!$A17), 0))} -> #REF! | BC16: {=SUM(_xlfn._xlws.FILTER(일별!#REF!, (일별!$A:$A >= 월별!$A16) * (일별!$A:$A < 월별!$A17), 0))} -> #REF! | ... DI16: {=SUM(_xlfn._xlws.FILTER(일별!#REF!, (일별!$A:$A >= 월별!$A16) * (일별!$A:$A < 월별!$A17), 0))} -> #REF!
A17: 計 | B17: =SUM(B5:B16) -> 5613.2 | C17: =AVERAGE(C5:C16) -> 14.963361 | D17: =SUM(D5:D16) -> 19724 | E17: =AVERAGE(E5:E16) -> 54.313294 | F17: =SUM(F5:F16) -> 17926 | G17: =AVERAGE(G5:G16) -> 49.426946 | H17: =SUM(H5:H16) -> 37650 | I17: =AVERAGE(I5:I16) -> 103.74024 | J17: =SUM(J5:J16) -> 3049.83 | K17: =AVERAGE(K5:K16) -> 8.322256 | L17: =SUM(L5:L16) -> 3049.83 | M17: =AVERAGE(M5:M16) -> 8.322256 | N17: =SUM(N5:N16) -> 262.2 | O17: =AVERAGE(O5:O16) -> 0.72135305 | P17: =SUM(P5:P16) -> 25486 | Q17: =AVERAGE(Q5:Q16) -> 70.166769 | R17: =SUM(R5:R16) -> -232220 | S17: =AVERAGE(S5:S16) -> -646.43057 | T17: =SUM(T5:T16) -> 2.53 | U17: =AVERAGE(U5:U16) -> 0.0073088838 | V17: =SUM(V5:V16) -> 2.853 | W17: =AVERAGE(W5:W16) -> 0.0079495008 | X17: =SUM(X5:X16) -> 8242 | Y17: =AVERAGE(Y5:Y16) -> 23.291935 | Z17: =SUM(Z5:Z16) -> 14906252 | AA17: =SUM(AA5:AA16) -> 591 | AB17: =SUM(AB5:AB16) -> 0 | AC17: =SUM(AC5:AC16) -> 219523.8 | AD17: =SUM(AD5:AD16) -> 0 | AE17: =SUM(AE5:AE16) -> 220114.8 | AF17: =SUM(AF5:AF16) -> 2211 | AG17: =SUM(AG5:AG16) -> 0 | ... AP17: =SUM(AP5:AP16) -> #REF! | AQ17: =AVERAGE(AQ5:AQ16) -> #REF! | AR17: =SUM(AR5:AR16) -> #REF! | AS17: =AVERAGE(AS5:AS16) -> #REF! | AT17: =SUM(AT5:AT16) -> #REF! | AU17: =AVERAGE(AU5:AU16) -> #REF! | AV17: =AVERAGE(AV5:AV16) -> #REF! | AW17: =AVERAGE(AW5:AW16) -> #REF! | AX17: =AVERAGE(AX5:AX16) -> #REF! | AY17: =AVERAGE(AY5:AY16) -> #REF! | AZ17: =AVERAGE(AZ5:AZ16) -> #REF! | BA17: =AVERAGE(BA5:BA16) -> #REF! | BB17: =AVERAGE(BB5:BB16) -> #REF! | ... DI17: =AVERAGE(DI5:DI16) -> #REF!

Sheet 일별
A2: 1 | B2: 2 | C2: 3 | D2: 4 | E2: 5 | F2: 6 | G2: 7 | H2: 8 | I2: 9 | J2: 10 | K2: 11 | L2: 12 | M2: 13 | N2: 14 | O2: 15 | P2: 16 | Q2: 17 | R2: 18 | S2: 19 | T2: 20 | U2: 21 | V2: 22 | W2: 23 | X2: 24 | Y2: 25 | Z2: 26 | AA2: 27 | AB2: 28 | AC2: 29 | AD2: 30 | AE2: 31 | AF2: 32 | AG2: 33 | AH2: 34 | AI2: 35 | AJ2: 36 | AK2: 37 | AL2: 38 | AM2: 39 | AN2: 40 | AO2: 41 | AP2: 42 | AQ2: 43 | AR2: 44 | AS2: 45 | AT2: 46 | AU2: 47 | AV2: 48 | AW2: 49 | AX2: 50 | AY2: 51 | AZ2: 52 | BA2: 53 | BB2: 54 | BC2: 55 | BD2: 56 | BE2: 57 | BF2: 58 | BG2: 59
A3: 단위 | B3: ㎥/d | D3: ㎥/d | F3: ㎥/d | H3: ㎥/d | J3: ㎥/d | L3: kWh | N3: ㎥/d | P3: ㎥Σ | R3: m | T3: m | V3: mm | X3: LNG사용량 | AD3: 운전시간(운전실적 기준) | AH3: 운전시간(가동시간 기준) | AL3: 가동시간 (기입!) | AX3: 생산량 | BD3: 시간당 생산량
A4: 구분 | B4: ACC 충수 | D4: A Train 생산 | F4: B Train 생산 | H4: 생활용수 | J4: 1차 냉각수 | L4: 폐수 전력 | N4: 방류수 | P4: 용수사용량 | R4: ACC LIT | T4: ACC WIT | V4: 순수 LIT | X4: W_CHP(사용량) | Y4: #1 PLB(L) | Z4: #2 PLB(L) | AA4: #3 PLB(L) | AB4: PLB가스 사용량오차 | AC4: W_PLB(사용량) | AD4: 주보일러 | AE4: PLB#1 | AF4: PLB#2 | AG4: PLB#3 | AH4: 주보일러 | AI4: PLB#1 | AJ4: PLB#2 | AK4: PLB#3 | AL4: 주보일러 | AR4: PLB#1 | AT4: PLB#2 | AV4: PLB#3 | AX4: W_CHP(H생산) | AY4: #1 PLB | AZ4: #2 PLB | BA4: #3 PLB | BB4: W_PLB(H생산) | BC4: 자체생산 | BD4: CHP | BE4: 51.39 | BF4: PLB | BG4: 68.8
A5: =운전실적_원본!A5 -> 45657 | B5: =운전실적_원본!B5 -> 3486 | D5: =운전실적_원본!C5 -> 226260 | F5: =운전실적_원본!D5 -> 220542 | H5: =운전실적_원본!E5 -> 13810 | J5: =운전실적_원본!E5 -> 13810 | L5: =운전실적_원본!G5 -> 3741.5 | N5: =운전실적_원본!H5 -> 3667 | P5: =운전실적_원본!I5 -> 241771 | R5: =운전실적_원본!J5 -> 30.97 | T5: =운전실적_원본!K5 -> 30.167 | V5: =운전실적_원본!L5 -> 0 | X5: =운전실적_원본!M5 -> 8660.3 | Y5: =운전실적_원본!N5 -> 0 | Z5: =운전실적_원본!O5 -> 0 | AA5: =운전실적_원본!P5 -> 0 | AB5: =운전실적_원본!Q5 -> 0 | AC5: =운전실적_원본!R5 -> 0 | AD5: =운전실적_원본!S5 -> 2 | AE5: =운전실적_원본!T5 -> 0 | ... AG5: =운전실적_원본!V5 -> 0 | AH5: =((AM5-AL5)+(AO5-AN5)+(AQ5-AP5))*24 -> 0 | AI5: =(AS5-AR5)*24 -> 0 | AJ5: =(AU5-AT5)*24 -> 0 | AK5: =(AW5-AV5)*24 -> 0 | AX5: =운전실적_원본!W5 -> 56.3 | AY5: =운전실적_원본!X5 -> 0 | AZ5: =운전실적_원본!Y5 -> 0 | BA5: =운전실적_원본!Z5 -> 0 | BB5: =운전실적_원본!AA5 -> 0 | BC5: =운전실적_원본!AB5 -> 56.3 | BD5: =IFERROR(AX5/AD6,"-") -> - | BE5: =IFERROR(BD5/$BE$4,"-") -> - | BF5: =IFERROR(BB5/AE6,"-") -> - | BG5: =IFERROR(BF5/$BG$4,"-") -> -
A6: =A5+1 -> 45658 | B6: =운전실적_원본!B6 -> 3536 | C6: =B6-B5 -> 50 | D6: =운전실적_원본!C6 -> 226305 | E6: =D6-D5 -> 45 | F6: =운전실적_원본!D6 -> 220548 | G6: =F6-F5 -> 6 | H6: =운전실적_원본!E6 -> 13811 | I6: =H6-H5 -> 1 | J6: =운전실적_원본!E6 -> 13811 | K6: =J6-J5 -> 1 | L6: =운전실적_원본!G6 -> 3742.4 | M6: =L6-L5 -> 0.9 | N6: =운전실적_원본!H6 -> 3739 | O6: =N6-N5 -> 72 | P6: =운전실적_원본!I6 -> 241878 | Q6: =P6-P5 -> 107 | R6: =운전실적_원본!J6 -> 30.74 | S6: =R6-R5 -> -0.23 | T6: =운전실적_원본!K6 -> 30.15 | U6: =T6-T5 -> -0.017 | V6: =운전실적_원본!L6 -> 0 | W6: =V6-V5 -> 0 | X6: =운전실적_원본!M6 -> 0 | Y6: =운전실적_원본!N6 -> 0 | Z6: =운전실적_원본!O6 -> 0 | AA6: =운전실적_원본!P6 -> 0 | AB6: =운전실적_원본!Q6 -> 0 | AC6: =운전실적_원본!R6 -> 0 | AD6: =운전실적_원본!S6 -> 0 | AE6: =운전실적_원본!T6 -> 0 | ... AG6: =운전실적_원본!V6 -> 0 | AH6: =((AM6-AL6)+(AO6-AN6)+(AQ6-AP6))*24 -> 8.75 | AI6: =(AS6-AR6)*24 -> 0 | AJ6: =(AU6-AT6)*24 -> 0 | AK6: =(AW6-AV6)*24 -> 0 | AL6: 45658 | AM6: 45658.083 | AN6: 45658.719 | AO6: =AL7 -> 45659 | AX6: =운전실적_원본!W6 -> 0 | AY6: =운전실적_원본!X6 -> 0 | AZ6: =운전실적_원본!Y6 -> 0 | BA6: =운전실적_원본!Z6 -> 0 | BB6: =운전실적_원본!AA6 -> 0 | BC6: =운전실적_원본!AB6 -> 0 | BD6: =IFERROR(AX6/#REF!,"-") -> - | BE6: =IFERROR(BD6/$BE$4,"-") -> - | BF6: =IFERROR(BB6/#REF!,"-") -> - | BG6: =IFERROR(BF6/$BG$4,"-") -> -
