Workbook
Name _10A_61: #N/A
Name _10A_62: #N/A
Name _10A_63: #N/A
Name _10A_64: #N/A
Name _10A_65: #N/A
Name _10A_66: #N/A
Name _10A_67: #N/A
Name _10A_68: #N/A
Name _10A_69: #N/A
Name _10A_70: #N/A
Name _10A_71: #N/A
Name _10A_72: #N/A
Name _10A_73: #N/A
Name _10A_74: #N/A
Name _10A_75: #N/A
Name _10A_76: #N/A
Name _10A_77: #N/A
Name _10A_78: #N/A
Name _10A_79: #N/A
Name _10A_80: #N/A
Name _10A_81: #N/A
Name _10A_82: #N/A
Name _10A_83: #N/A
Name _10A_84: #N/A
Name _10A_85: #N/A
Name _10A_86: #N/A
Name _10A_87: #N/A
Name _10A_88: #N/A
Name _10A_89: #N/A
Name _10A_90: #N/A
Name _10B_61: #N/A
Name _10B_62: #N/A
Name _10B_63: #N/A
Name _10B_64: #N/A
Name _10B_65: #N/A
Name _10B_66: #N/A
Name _10B_67: #N/A
Name _10B_68: #N/A
Name _10B_69: #N/A
Name _10B_70: #N/A
Name _10B_71: #N/A
Name _10B_72: #N/A
Name _10B_73: #N/A
Name _10B_74: #N/A
Name _10B_75: #N/A
Name _10B_76: #N/A
Name _10B_77: #N/A
Name _10B_78: #N/A
Name _10B_79: #N/A
Name _10B_80: #N/A
Name _10B_81: #N/A
Name _10B_82: #N/A
Name _10B_83: #N/A
Name _10B_84: #N/A
Name _10B_85: #N/A
Name _10B_86: #N/A
Name _10B_87: #N/A
Name _10B_88: #N/A
Name _10B_89: #N/A
Name _10B_90: #N/A

Sheet 2026년
A1: 2026
A2: 2026년 운영 현황
A4: 수질 | N4: 대기
A6: 총 상수도 사용 | D6: 순수 생산량 | G6: 방류수 | J6: 총 전력 사용 | N6: CHP 가동시간 | Q6: LNG 사용량 | T6: PLB#1 가동시간 | W6: LNG 사용량
A7: =월별!R17 -> 12550 | D7: =월별!D17+월별!F17 -> 5457 | G7: =월별!P17 -> 9381 | J7: =월별!N17 -> 83.2 | N7: =월별!AF17 -> 1427 | Q7: =월별!Z17 -> 10988127 | T7: =월별!AG17 -> 47 | W7: =월별!AA17 -> 262388.45
A8: ㎥ | D8: ㎥ | G8: ㎥ | J8: Kwh | N8: hr | Q8: N㎥ | T8: hr | W8: N㎥
A9: 💧 | D9: 💧 | G9: ♻️ | J9: ⚡ | N9: ⏰ | Q9: ⛽ | T9: ⏰ | W9: ⛽

Sheet 월별
B2: 합계 | C2: 평균
A3: 단위 | B3: ACC 충수 | D3: A Train 생산 | F3: B Train 생산 | H3: 순수생산 | J3: 생활용수 | L3: 1차 냉각수 | N3: 폐수 전력 | P3: 방류수 | R3: 용수사용량 | T3: ACC LIT | V3: ACC WIT | X3: 순수 LIT | Z3: LNG사용량 | AF3: 운전시간 | AJ3: 생산량 | AP3: 연료전지 (22기) | AV3: 연료전지 기기별 가동시간 | BR3: 연료전지 기기별 LNG 사용량 | CN3: 연료전지 기기별 발전량
A4: 46388 | B4: ㎥ | C4: ㎥/d | D4: ㎥ | E4: ㎥/d | F4: ㎥ | G4: ㎥/d | J4: ㎥ | K4: ㎥/d | L4: ㎥ | M4: ㎥/d | N4: Kwh | P4: ㎥ | Q4: ㎥/d | R4: ㎥ | S4: ㎥/d | Z4: W_CHP(사용량) | AA4: #1 PLB(L) | AB4: #2 PLB(L) | AC4: #3 PLB(L) | AD4: PLB가스 사용량오차 | AE4: W_PLB(사용량) | AF4: 주보일러 | AG4: PLB#1 | AH4: PLB#2 | AI4: PLB#3 | AJ4: W_CHP(H생산) | AK4: #1 PLB | AL4: #2 PLB | AM4: #3 PLB | AN4: W_PLB(H생산) | AO4: 자체생산 | AP4: 가동시간 | AQ4: 평균 | AR4: LNG 사용량 | AS4: 평균 | AT4: 발전량 | AU4: 평균 | AV4: 1 | AW4: 2 | AX4: 3 | AY4: 4 | AZ4: 5 | BA4: 6 | BB4: 7 | BC4: 8 | BD4: 9 | BE4: 10 | BF4: 11 | BG4: 12 | BH4: 13 | BI4: 14 | BJ4: 15 | BK4: 16 | BL4: 17 | BM4: 18 | BN4: 19 | BO4: 20 | BP4: 21 | BQ4: 22 | BR4: 1 | BS4: 2 | BT4: 3 | BU4: 4 | BV4: 5 | BW4: 6 | BX4: 7 | BY4: 8 | BZ4: 9 | CA4: 10 | CB4: 11 | CC4: 12 | CD4: 13 | CE4: 14 | CF4: 15 | CG4: 16 | CH4: 17 | CI4: 18 | CJ4: 19 | CK4: 20 | CL4: 21 | CM4: 22 | CN4: 1 | CO4: 2 | CP4: 3 | CQ4: 4 | CR4: 5 | CS4: 6 | CT4: 7 | CU4: 8 | CV4: 9 | CW4: 10 | CX4: 11 | CY4: 12 | CZ4: 13 | DA4: 14 | DB4: 15 | DC4: 16 | DD4: 17 | DE4: 18 | DF4: 19 | DG4: 20 | DH4: 21 | DI4: 22
A5: 46023 | B5: =SUMIFS(일별!C:C, 일별!$A:$A, ">="&월별!$A5, 일별!$A:$A, "<"&월별!$A6) -> 0 | C5: =B5/(월별!$A6 - 월별!$A5) -> 0 | D5: =SUMIFS(일별!E:E, 일별!$A:$A, ">="&월별!$A5, 일별!$A:$A, "<"&월별!$A6) -> 1214 | E5: =D5/(월별!$A6 - 월별!$A5) -> 39.16129 | F5: =SUMIFS(일별!G:G, 일별!$A:$A, ">="&월별!$A5, 일별!$A:$A, "<"&월별!$A6) -> 984 | G5: =F5/(월별!$A6 - 월별!$A5) -> 31.741935 | H5: =D5+F5 -> 2198 | I5: =E5+G5 -> 70.903226 | J5: =SUMIFS(일별!I:I, 일별!$A:$A, ">="&월별!$A5, 일별!$A:$A, "<"&월별!$A6) -> 159.72 | K5: =J5/(월별!$A6 - 월별!$A5) -> 5.1522581 | L5: =SUMIFS(일별!K:K, 일별!$A:$A, ">="&월별!$A5, 일별!$A:$A, "<"&월별!$A6) -> 614.84 | M5: =L5/(월별!$A6 - 월별!$A5) -> 19.833548 | N5: =SUMIFS(일별!M:M, 일별!$A:$A, ">="&월별!$A5, 일별!$A:$A, "<"&월별!$A6) -> 29 | O5: =N5/(월별!$A6 - 월별!$A5) -> 0.93548387 | P5: =SUMIFS(일별!O:O, 일별!$A:$A, ">="&월별!$A5, 일별!$A:$A, "<"&월별!$A6) -> 3892 | Q5: =P5/(월별!$A6 - 월별!$A5) -> 125.54839 | R5: =SUMIFS(일별!Q:Q, 일별!$A:$A, ">="&월별!$A5, 일별!$A:$A, "<"&월별!$A6) -> 5219 | S5: =R5/(월별!$A6 - 월별!$A5) -> 168.35484 | T5: =SUMIFS(일별!S:S, 일별!$A:$A, ">="&월별!$A5, 일별!$A:$A, "<"&월별!$A6) -> -0.88 | U5: =T5/(월별!$A6 - 월별!$A5) -> -0.028387097 | V5: =SUMIFS(일별!U:U, 일별!$A:$A, ">="&월별!$A5, 일별!$A:$A, "<"&월별!$A6) -> -0.68 | W5: =V5/(월별!$A6 - 월별!$A5) -> -0.021935484 | X5: =SUMIFS(일별!W:W, 일별!$A:$A, ">="&월별!$A5, 일별!$A:$A, "<"&월별!$A6) -> 474 | Y5: =X5/(월별!$A6 - 월별!$A5) -> 15.290323 | Z5: =SUMIFS(일별!X:X, 일별!$A:$A, ">="&월별!$A5, 일별!$A:$A, "<"&월별!$A6) -> 6035741.9 | AA5: =SUMIFS(일별!Y:Y, 일별!$A:$A, ">="&월별!$A5, 일별!$A:$A, "<"&월별!$A6) -> 262388.45 | AB5: =SUMIFS(일별!Z:Z, 일별!$A:$A, ">="&월별!$A5, 일별!$A:$A, "<"&월별!$A6) -> 0 | AC5: =SUMIFS(일별!AA:AA, 일별!$A:$A, ">="&월별!$A5, 일별!$A:$A, "<"&월별!$A6) -> 0 | AD5: =SUMIFS(일별!AB:AB, 일별!$A:$A, ">="&월별!$A5, 일별!$A:$A, "<"&월별!$A6) -> 0 | AE5: =SUMIFS(일별!AC:AC, 일별!$A:$A, ">="&월별!$A5, 일별!$A:$A, "<"&월별!$A6) -> 262388.45 | AF5: =SUMIFS(일별!AD:AD, 일별!$A:$A, ">="&월별!$A5, 일별!$A:$A, "<"&월별!$A6) -> 739 | AG5: =SUMIFS(일별!AE:AE, 일별!$A:$A, ">="&월별!$A5, 일별!$A:$A, "<"&월별!$A6) -> 47 | AH5: =SUMIFS(일별!AF:AF, 일별!$A:$A, ">="&월별!$A5, 일별!$A:$A, "<"&월별!$A6) -> 0 | AI5: =SUMIFS(일별!AG:AG, 일별!$A:$A, ">="&월별!$A5, 일별!$A:$A, "<"&월별!$A6) -> 0 | AJ5: =SUMIFS(일별!AX:AX, 일별!$A:$A, ">="&월별!$A5, 일별!$A:$A, "<"&월별!$A6) -> 38142 | AK5: =SUMIFS(일별!AY:AY, 일별!$A:$A, ">="&월별!$A5, 일별!$A:$A, "<"&월별!$A6) -> 2314 | AL5: =SUMIFS(일별!AZ:AZ, 일별!$A:$A, ">="&월별!$A5, 일별!$A:$A, "<"&월별!$A6) -> 0 | AM5: =SUMIFS(일별!BA:BA, 일별!$A:$A, ">="&월별!$A5, 일별!$A:$A, "<"&월별!$A6) -> 0 | AN5: =SUMIFS(일별!BB:BB, 일별!$A:$A, ">="&월별!$A5, 일별!$A:$A, "<"&월별!$A6) -> 2314 | AO5: =SUMIFS(일별!BC:BC, 일별!$A:$A, ">="&월별!$A5, 일별!$A:$A, "<"&월별!$A6) -> 40456 | AP5: {=SUM(_xlfn._xlws.FILTER(일별!BH:CC, (일별!$A:$A >= 월별!$A5) * (일별!$A:$A < 월별!$A6), 0))} -> 8532 | AQ5: =AP5/(월별!$A6 - 월별!$A5) -> 275.22581 | AR5: {=SUM(_xlfn._xlws.FILTER(일별!CD:CY, (일별!$A:$A >= 월별!$A5) * (일별!$A:$A < 월별!$A6), 0))} -> 532030.7 | AS5: =AR5/(월별!$A6 - 월별!$A5) -> 17162.281 | AT5: {=SUM(_xlfn._xlws.FILTER(일별!CZ:DU, (일별!$A:$A >= 월별!$A5) * (일별!$A:$A < 월별!$A6), 0))} -> 0 | AU5: =AT5/(월별!$A6 - 월별!$A5) -> 0 | AV5: {=SUM(_xlfn._xlws.FILTER(일별!BH:BH, (일별!$A:$A >= 월별!$A5) * (일별!$A:$A < 월별!$A6), 0))} -> 450 | AW5: {=SUM(_xlfn._xlws.FILTER(일별!BI:BI, (일별!$A:$A >= 월별!$A5) * (일별!$A:$A < 월별!$A6), 0))} -> 450 | AX5: {=SUM(_xlfn._xlws.FILTER(일별!BJ:BJ, (일별!$A:$A >= 월별!$A5) * (일별!$A:$A < 월별!$A6), 0))} -> 450 | AY5: {=SUM(_xlfn._xlws.FILTER(일별!BK:BK, (일별!$A:$A >= 월별!$A5) * (일별!$A:$A < 월별!$A6), 0))} -> 450 | AZ5: {=SUM(_xlfn._xlws.FILTER(일별!BL:BL, (일별!$A:$A >= 월별!$A5) * (일별!$A:$A < 월별!$A6), 0))} -> 450 | BA5: {=SUM(_xlfn._xlws.FILTER(일별!BM:BM, (일별!$A:$A >= 월별!$A5) * (일별!$A:$A < 월별!$A6), 0))} -> 450 | BB5: {=SUM(_xlfn._xlws.FILTER(일별!BN:BN, (일별!$A:$A >= 월별!$A5) * (일별!$A:$A < 월별!$A6), 0))} -> 450 | BC5: {=SUM(_xlfn._xlws.FILTER(일별!BO:BO, (일별!$A:$A >= 월별!$A5) * (일별!$A:$A < 월별!$A6), 0))} -> 450 | BD5: {=SUM(_xlfn._xlws.FILTER(일별!BP:BP, (일별!$A:$A >= 월별!$A5) * (일별!$A:$A < 월별!$A6), 0))} -> 450 | BE5: {=SUM(_xlfn._xlws.FILTER(일별!BQ:BQ, (일별!$A:$A >= 월별!$A5) * (일별!$A:$A < 월별!$A6), 0))} -> 450 | BF5: {=SUM(_xlfn._xlws.FILTER(일별!BR:BR, (일별!$A:$A >= 월별!$A5) * (일별!$A:$A < 월별!$A6), 0))} -> 426 | BG5: {=SUM(_xlfn._xlws.FILTER(일별!BS:BS, (일별!$A:$A >= 월별!$A5) * (일별!$A:$A < 월별!$A6), 0))} -> 426 | BH5: {=SUM(_xlfn._xlws.FILTER(일별!BT:BT, (일별!$A:$A >= 월별!$A5) * (일별!$A:$A < 월별!$A6), 0))} -> 426 | BI5: {=SUM(_xlfn._xlws.FILTER(일별!BU:BU, (일별!$A:$A >= 월별!$A5) * (일별!$A:$A < 월별!$A6), 0))} -> 402 | BJ5: {=SUM(_xlfn._xlws.FILTER(일별!BV:BV, (일별!$A:$A >= 월별!$A5) * (일별!$A:$A < 월별!$A6), 0))} -> 402 | BK5: {=SUM(_xlfn._xlws.FILTER(일별!BW:BW, (일별!$A:$A >= 월별!$A5) * (일별!$A:$A < 월별!$A6), 0))} -> 402 | BL5: {=SUM(_xlfn._xlws.FILTER(일별!BX:BX, (일별!$A:$A >= 월별!$A5) * (일별!$A:$A < 월별!$A6), 0))} -> 282 | BM5: {=SUM(_xlfn._xlws.FILTER(일별!BY:BY, (일별!$A:$A >= 월별!$A5) * (일별!$A:$A < 월별!$A6), 0))} -> 282 | BN5: {=SUM(_xlfn._xlws.FILTER(일별!BZ:BZ, (일별!$A:$A >= 월별!$A5) * (일별!$A:$A < 월별!$A6), 0))} -> 282 | BO5: {=SUM(_xlfn._xlws.FILTER(일별!CA:CA, (일별!$A:$A >= 월별!$A5) * (일별!$A:$A < 월별!$A6), 0))} -> 234 | BP5: {=SUM(_xlfn._xlws.FILTER(일별!CB:CB, (일별!$A:$A >= 월별!$A5) * (일별!$A:$A < 월별!$A6), 0))} -> 234 | BQ5: {=SUM(_xlfn._xlws.FILTER(일별!CC:CC, (일별!$A:$A >= 월별!$A5) * (일별!$A:$A < 월별!$A6), 0))} -> 234 | BR5: {=SUM(_xlfn._xlws.FILTER(일별!CD:CD, (일별!$A:$A >= 월별!$A5) * (일별!$A:$A < 월별!$A6), 0))} -> 27703.552 | BS5: {=SUM(_xlfn._xlws.FILTER(일별!CE:CE, (일별!$A:$A >= 월별!$A5) * (일별!$A:$A < 월별!$A6), 0))} -> 27703.552 | BT5: {=SUM(_xlfn._xlws.FILTER(일별!CF:CF, (일별!$A:$A >= 월별!$A5) * (일별!$A:$A < 월별!$A6), 0))} -> 27703.552 | BU5: {=SUM(_xlfn._xlws.FILTER(일별!CG:CG, (일별!$A:$A >= 월별!$A5) * (일별!$A:$A < 월별!$A6), 0))} -> 27703.552 | BV5: {=SUM(_xlfn._xlws.FILTER(일별!CH:CH, (일별!$A:$A >= 월별!$A5) * (일별!$A:$A < 월별!$A6), 0))} -> 27703.552 | BW5: {=SUM(_xlfn._xlws.FILTER(일별!CI:CI, (일별!$A:$A >= 월별!$A5) * (일별!$A:$A < 월별!$A6), 0))} -> 27703.552 | BX5: {=SUM(_xlfn._xlws.FILTER(일별!CJ:CJ, (일별!$A:$A >= 월별!$A5) * (일별!$A:$A < 월별!$A6), 0))} -> 27703.552 | BY5: {=SUM(_xlfn._xlws.FILTER(일별!CK:CK, (일별!$A:$A >= 월별!$A5) * (일별!$A:$A < 월별!$A6), 0))} -> 27703.552 | BZ5: {=SUM(_xlfn._xlws.FILTER(일별!CL:CL, (일별!$A:$A >= 월별!$A5) * (일별!$A:$A < 월별!$A6), 0))} -> 27703.552 | CA5: {=SUM(_xlfn._xlws.FILTER(일별!CM:CM, (일별!$A:$A >= 월별!$A5) * (일별!$A:$A < 월별!$A6), 0))} -> 27703.552 | CB5: {=SUM(_xlfn._xlws.FILTER(일별!CN:CN, (일별!$A:$A >= 월별!$A5) * (일별!$A:$A < 월별!$A6), 0))} -> 25870.841 | CC5: {=SUM(_xlfn._xlws.FILTER(일별!CO:CO, (일별!$A:$A >= 월별!$A5) * (일별!$A:$A < 월별!$A6), 0))} -> 25870.841 | CD5: {=SUM(_xlfn._xlws.FILTER(일별!CP:CP, (일별!$A:$A >= 월별!$A5) * (일별!$A:$A < 월별!$A6), 0))} -> 25870.841 | CE5: {=SUM(_xlfn._xlws.FILTER(일별!CQ:CQ, (일별!$A:$A >= 월별!$A5) * (일별!$A:$A < 월별!$A6), 0))} -> 24870.555 | CF5: {=SUM(_xlfn._xlws.FILTER(일별!CR:CR, (일별!$A:$A >= 월별!$A5) * (일별!$A:$A < 월별!$A6), 0))} -> 24870.555 | CG5: {=SUM(_xlfn._xlws.FILTER(일별!CS:CS, (일별!$A:$A >= 월별!$A5) * (일별!$A:$A < 월별!$A6), 0))} -> 24870.555 | CH5: {=SUM(_xlfn._xlws.FILTER(일별!CT:CT, (일별!$A:$A >= 월별!$A5) * (일별!$A:$A < 월별!$A6), 0))} -> 18699.623 | CI5: {=SUM(_xlfn._xlws.FILTER(일별!CU:CU, (일별!$A:$A >= 월별!$A5) * (일별!$A:$A < 월별!$A6), 0))} -> 18699.623 | CJ5: {=SUM(_xlfn._xlws.FILTER(일별!CV:CV, (일별!$A:$A >= 월별!$A5) * (일별!$A:$A < 월별!$A6), 0))} -> 18699.623 | CK5: {=SUM(_xlfn._xlws.FILTER(일별!CW:CW, (일별!$A:$A >= 월별!$A5) * (일별!$A:$A < 월별!$A6), 0))} -> 15557.374 | CL5: {=SUM(_xlfn._xlws.FILTER(일별!CX:CX, (일별!$A:$A >= 월별!$A5) * (일별!$A:$A < 월별!$A6), 0))} -> 15557.374 | CM5: {=SUM(_xlfn._xlws.FILTER(일별!CY:CY, (일별!$A:$A >= 월별!$A5) * (일별!$A:$A < 월별!$A6), 0))} -> 15557.374 | CN5: {=SUM(_xlfn._xlws.FILTER(일별!CZ:CZ, (일별!$A:$A >= 월별!$A5) * (일별!$A:$A < 월별!$A6), 0))} -> 0 | CO5: {=SUM(_xlfn._xlws.FILTER(일별!DA:DA, (일별!$A:$A >= 월별!$A5) * (일별!$A:$A < 월별!$A6), 0))} -> 0 | CP5: {=SUM(_xlfn._xlws.FILTER(일별!DB:DB, (일별!$A:$A >= 월별!$A5) * (일별!$A:$A < 월별!$A6), 0))} -> 0 | CQ5: {=SUM(_xlfn._xlws.FILTER(일별!DC:DC, (일별!$A:$A >= 월별!$A5) * (일별!$A:$A < 월별!$A6), 0))} -> 0 | CR5: {=SUM(_xlfn._xlws.FILTER(일별!DD:DD, (일별!$A:$A >= 월별!$A5) * (일별!$A:$A < 월별!$A6), 0))} -> 0 | CS5: {=SUM(_xlfn._xlws.FILTER(일별!DE:DE, (일별!$A:$A >= 월별!$A5) * (일별!$A:$A < 월별!$A6), 0))} -> 0 | CT5: {=SUM(_xlfn._xlws.FILTER(일별!DF:DF, (일별!$A:$A >= 월별!$A5) * (일별!$A:$A < 월별!$A6), 0))} -> 0 | CU5: {=SUM(_xlfn._xlws.FILTER(일별!DG:DG, (일별!$A:$A >= 월별!$A5) * (일별!$A:$A < 월별!$A6), 0))} -> 0 | CV5: {=SUM(_xlfn._xlws.FILTER(일별!DH:DH, (일별!$A:$A >= 월별!$A5) * (일별!$A:$A < 월별!$A6), 0))} -> 0 | CW5: {=SUM(_xlfn._xlws.FILTER(일별!DI:DI, (일별!$A:$A >= 월별!$A5) * (일별!$A:$A < 월별!$A6), 0))} -> 0 | CX5: {=SUM(_xlfn._xlws.FILTER(일별!DJ:DJ, (일별!$A:$A >= 월별!$A5) * (일별!$A:$A < 월별!$A6), 0))} -> 0 | CY5: {=SUM(_xlfn._xlws.FILTER(일별!DK:DK, (일별!$A:$A >= 월별!$A5) * (일별!$A:$A < 월별!$A6), 0))} -> 0 | CZ5: {=SUM(_xlfn._xlws.FILTER(일별!DL:DL, (일별!$A:$A >= 월별!$A5) * (일별!$A:$A < 월별!$A6), 0))} -> 0 | DA5: {=SUM(_xlfn._xlws.FILTER(일별!DM:DM, (일별!$A:$A >= 월별!$A5) * (일별!$A:$A < 월별!$A6), 0))} -> 0 | DB5: {=SUM(_xlfn._xlws.FILTER(일별!DN:DN, (일별!$A:$A >= 월별!$A5) * (일별!$A:$A < 월별!$A6), 0))} -> 0 | DC5: {=SUM(_xlfn._xlws.FILTER(일별!DO:DO, (일별!$A:$A >= 월별!$A5) * (일별!$A:$A < 월별!$A6), 0))} -> 0 | DD5: {=SUM(_xlfn._xlws.FILTER(일별!DP:DP, (일별!$A:$A >= 월별!$A5) * (일별!$A:$A < 월별!$A6), 0))} -> 0 | DE5: {=SUM(_xlfn._xlws.FILTER(일별!DQ:DQ, (일별!$A:$A >= 월별!$A5) * (일별!$A:$A < 월별!$A6), 0))} -> 0 | DF5: {=SUM(_xlfn._xlws.FILTER(일별!DR:DR, (일별!$A:$A >= 월별!$A5) * (일별!$A:$A < 월별!$A6), 0))} -> 0 | DG5: {=SUM(_xlfn._xlws.FILTER(일별!DS:DS, (일별!$A:$A >= 월별!$A5) * (일별!$A:$A < 월별!$A6), 0))} -> 0 | DH5: {=SUM(_xlfn._xlws.FILTER(일별!DT:DT, (일별!$A:$A >= 월별!$A5) * (일별!$A:$A < 월별!$A6), 0))} -> 0 | DI5: {=SUM(_xlfn._xlws.FILTER(일별!DU:DU, (일별!$A:$A >= 월별!$A5) * (일별!$A:$A < 월별!$A6), 0))} -> 0
A6: 46054 | B6: =SUMIFS(일별!$C:$C, 일별!$A:$A, ">="&월별!$A6, 일별!$A:$A, "<"&월별!$A7) -> 0 | C6: =B6/(월별!$A7 - 월별!$A6) -> 0 | D6: =SUMIFS(일별!E:E, 일별!$A:$A, ">="&월별!$A6, 일별!$A:$A, "<"&월별!$A7) -> 1002 | E6: =D6/(월별!$A7 - 월별!$A6) -> 35.785714 | F6: =SUMIFS(일별!G:G, 일별!$A:$A, ">="&월별!$A6, 일별!$A:$A, "<"&월별!$A7) -> 820 | G6: =F6/(월별!$A7 - 월별!$A6) -> 29.285714 | H6: =D6+F6 -> 1822 | I6: =E6+G6 -> 65.071429 | J6: =SUMIFS(일별!I:I, 일별!$A:$A, ">="&월별!$A6, 일별!$A:$A, "<"&월별!$A7) -> 110.69 | K6: =J6/(월별!$A7 - 월별!$A6) -> 3.9532143 | L6: =SUMIFS(일별!K:K, 일별!$A:$A, ">="&월별!$A6, 일별!$A:$A, "<"&월별!$A7) -> 467.3 | M6: =L6/(월별!$A7 - 월별!$A6) -> 16.689286 | N6: =SUMIFS(일별!M:M, 일별!$A:$A, ">="&월별!$A6, 일별!$A:$A, "<"&월별!$A7) -> 25.2 | O6: =N6/(월별!$A7 - 월별!$A6) -> 0.9 | P6: =SUMIFS(일별!O:O, 일별!$A:$A, ">="&월별!$A6, 일별!$A:$A, "<"&월별!$A7) -> 2847 | Q6: =P6/(월별!$A7 - 월별!$A6) -> 101.67857 | R6: =SUMIFS(일별!Q:Q, 일별!$A:$A, ">="&월별!$A6, 일별!$A:$A, "<"&월별!$A7) -> 4036 | S6: =R6/(월별!$A7 - 월별!$A6) -> 144.14286 | T6: =SUMIFS(일별!S:S, 일별!$A:$A, ">="&월별!$A6, 일별!$A:$A, "<"&월별!$A7) -> 1.08 | U6: =T6/(월별!$A7 - 월별!$A6) -> 0.038571429 | V6: =SUMIFS(일별!U:U, 일별!$A:$A, ">="&월별!$A6, 일별!$A:$A, "<"&월별!$A7) -> 0.62 | W6: =V6/(월별!$A7 - 월별!$A6) -> 0.022142857 | X6: =SUMIFS(일별!W:W, 일별!$A:$A, ">="&월별!$A6, 일별!$A:$A, "<"&월별!$A7) -> -129 | Y6: =X6/(월별!$A7 - 월별!$A6) -> -4.6071429 | Z6: =SUMIFS(일별!X:X, 일별!$A:$A, ">="&월별!$A6, 일별!$A:$A, "<"&월별!$A7) -> 3820113.9 | AA6: =SUMIFS(일별!Y:Y, 일별!$A:$A, ">="&월별!$A6, 일별!$A:$A, "<"&월별!$A7) -> 0 | AB6: =SUMIFS(일별!Z:Z, 일별!$A:$A, ">="&월별!$A6, 일별!$A:$A, "<"&월별!$A7) -> 0 | AC6: =SUMIFS(일별!AA:AA, 일별!$A:$A, ">="&월별!$A6, 일별!$A:$A, "<"&월별!$A7) -> 0 | AD6: =SUMIFS(일별!AB:AB, 일별!$A:$A, ">="&월별!$A6, 일별!$A:$A, "<"&월별!$A7) -> 0 | AE6: =SUMIFS(일별!AC:AC, 일별!$A:$A, ">="&월별!$A6, 일별!$A:$A, "<"&월별!$A7) -> 0 | AF6: =SUMIFS(일별!AD:AD, 일별!$A:$A, ">="&월별!$A6, 일별!$A:$A, "<"&월별!$A7) -> 500 | AG6: =SUMIFS(일별!AE:AE, 일별!$A:$A, ">="&월별!$A6, 일별!$A:$A, "<"&월별!$A7) -> 0 | AH6: =SUMIFS(일별!AF:AF, 일별!$A:$A, ">="&월별!$A6, 일별!$A:$A, "<"&월별!$A7) -> 0 | AI6: =SUMIFS(일별!AG:AG, 일별!$A:$A, ">="&월별!$A6, 일별!$A:$A, "<"&월별!$A7) -> 0 | AJ6: =SUMIFS(일별!AX:AX, 일별!$A:$A, ">="&월별!$A6, 일별!$A:$A, "<"&월별!$A7) -> 24488.286 | AK6: =SUMIFS(일별!AY:AY, 일별!$A:$A, ">="&월별!$A6, 일별!$A:$A, "<"&월별!$A7) -> 0 | AL6: =SUMIFS(일별!AZ:AZ, 일별!$A:$A, ">="&월별!$A6, 일별!$A:$A, "<"&월별!$A7) -> 0 | AM6: =SUMIFS(일별!BA:BA, 일별!$A:$A, ">="&월별!$A6, 일별!$A:$A, "<"&월별!$A7) -> 0 | AN6: =SUMIFS(일별!BB:BB, 일별!$A:$A, ">="&월별!$A6, 일별!$A:$A, "<"&월별!$A7) -> 0 | AO6: =SUMIFS(일별!BC:BC, 일별!$A:$A, ">="&월별!$A6, 일별!$A:$A, "<"&월별!$A7) -> 24488.286 | AP6: {=SUM(_xlfn._xlws.FILTER(일별!BH:CC, (일별!$A:$A >= 월별!$A6) * (일별!$A:$A < 월별!$A7), 0))} -> 14330.833 | AQ6: =AP6/(월별!$A7 - 월별!$A6) -> 511.81548 | AR6: {=SUM(_xlfn._xlws.FILTER(일별!CD:CY, (일별!$A:$A >= 월별!$A6) * (일별!$A:$A < 월별!$A7), 0))} -> 1248591 | AS6: =AR6/(월별!$A7 - 월별!$A6) -> 44592.536 | AT6: {=SUM(_xlfn._xlws.FILTER(일별!CZ:DU, (일별!$A:$A >= 월별!$A6) * (일별!$A:$A < 월별!$A7), 0))} -> 5931.432 | AU6: =AT6/(월별!$A7 - 월별!$A6) -> 211.83686 | AV6: {=SUM(_xlfn._xlws.FILTER(일별!BH:BH, (일별!$A:$A >= 월별!$A6) * (일별!$A:$A < 월별!$A7), 0))} -> 672 | AW6: {=SUM(_xlfn._xlws.FILTER(일별!BI:BI, (일별!$A:$A >= 월별!$A6) * (일별!$A:$A < 월별!$A7), 0))} -> 581.5 | AX6: {=SUM(_xlfn._xlws.FILTER(일별!BJ:BJ, (일별!$A:$A >= 월별!$A6) * (일별!$A:$A < 월별!$A7), 0))} -> 672 | AY6: {=SUM(_xlfn._xlws.FILTER(일별!BK:BK, (일별!$A:$A >= 월별!$A6) * (일별!$A:$A < 월별!$A7), 0))} -> 672 | AZ6: {=SUM(_xlfn._xlws.FILTER(일별!BL:BL, (일별!$A:$A >= 월별!$A6) * (일별!$A:$A < 월별!$A7), 0))} -> 672 | BA6: {=SUM(_xlfn._xlws.FILTER(일별!BM:BM, (일별!$A:$A >= 월별!$A6) * (일별!$A:$A < 월별!$A7), 0))} -> 672 | BB6: {=SUM(_xlfn._xlws.FILTER(일별!BN:BN, (일별!$A:$A >= 월별!$A6) * (일별!$A:$A < 월별!$A7), 0))} -> 672 | BC6: {=SUM(_xlfn._xlws.FILTER(일별!BO:BO, (일별!$A:$A >= 월별!$A6) * (일별!$A:$A < 월별!$A7), 0))} -> 672 | BD6: {=SUM(_xlfn._xlws.FILTER(일별!BP:BP, (일별!$A:$A >= 월별!$A6) * (일별!$A:$A < 월별!$A7), 0))} -> 622 | BE6: {=SUM(_xlfn._xlws.FILTER(일별!BQ:BQ, (일별!$A:$A >= 월별!$A6) * (일별!$A:$A < 월별!$A7), 0))} -> 672 | BF6: {=SUM(_xlfn._xlws.FILTER(일별!BR:BR, (일별!$A:$A >= 월별!$A6) * (일별!$A:$A < 월별!$A7), 0))} -> 628.83333 | BG6: {=SUM(_xlfn._xlws.FILTER(일별!BS:BS, (일별!$A:$A >= 월별!$A6) * (일별!$A:$A < 월별!$A7), 0))} -> 672 | BH6: {=SUM(_xlfn._xlws.FILTER(일별!BT:BT, (일별!$A:$A >= 월별!$A6) * (일별!$A:$A < 월별!$A7), 0))} -> 662.83333 | BI6: {=SUM(_xlfn._xlws.FILTER(일별!BU:BU, (일별!$A:$A >= 월별!$A6) * (일별!$A:$A < 월별!$A7), 0))} -> 672 | BJ6: {=SUM(_xlfn._xlws.FILTER(일별!BV:BV, (일별!$A:$A >= 월별!$A6) * (일별!$A:$A < 월별!$A7), 0))} -> 662.5 | BK6: {=SUM(_xlfn._xlws.FILTER(일별!BW:BW, (일별!$A:$A >= 월별!$A6) * (일별!$A:$A < 월별!$A7), 0))} -> 672 | BL6: {=SUM(_xlfn._xlws.FILTER(일별!BX:BX, (일별!$A:$A >= 월별!$A6) * (일별!$A:$A < 월별!$A7), 0))} -> 672 | BM6: {=SUM(_xlfn._xlws.FILTER(일별!BY:BY, (일별!$A:$A >= 월별!$A6) * (일별!$A:$A < 월별!$A7), 0))} -> 650.33333 | BN6: {=SUM(_xlfn._xlws.FILTER(일별!BZ:BZ, (일별!$A:$A >= 월별!$A6) * (일별!$A:$A < 월별!$A7), 0))} -> 663.16667 | BO6: {=SUM(_xlfn._xlws.FILTER(일별!CA:CA, (일별!$A:$A >= 월별!$A6) * (일별!$A:$A < 월별!$A7), 0))} -> 498.5 | BP6: {=SUM(_xlfn._xlws.FILTER(일별!CB:CB, (일별!$A:$A >= 월별!$A6) * (일별!$A:$A < 월별!$A7), 0))} -> 672 | BQ6: {=SUM(_xlfn._xlws.FILTER(일별!CC:CC, (일별!$A:$A >= 월별!$A6) * (일별!$A:$A < 월별!$A7), 0))} -> 625.16667 | BR6: {=SUM(_xlfn._xlws.FILTER(일별!CD:CD, (일별!$A:$A >= 월별!$A6) * (일별!$A:$A < 월별!$A7), 0))} -> 59020 | BS6: {=SUM(_xlfn._xlws.FILTER(일별!CE:CE, (일별!$A:$A >= 월별!$A6) * (일별!$A:$A < 월별!$A7), 0))} -> 51233 | BT6: {=SUM(_xlfn._xlws.FILTER(일별!CF:CF, (일별!$A:$A >= 월별!$A6) * (일별!$A:$A < 월별!$A7), 0))} -> 58842 | BU6: {=SUM(_xlfn._xlws.FILTER(일별!CG:CG, (일별!$A:$A >= 월별!$A6) * (일별!$A:$A < 월별!$A7), 0))} -> 58890 | BV6: {=SUM(_xlfn._xlws.FILTER(일별!CH:CH, (일별!$A:$A >= 월별!$A6) * (일별!$A:$A < 월별!$A7), 0))} -> 58981 | BW6: {=SUM(_xlfn._xlws.FILTER(일별!CI:CI, (일별!$A:$A >= 월별!$A6) * (일별!$A:$A < 월별!$A7), 0))} -> 58977 | BX6: {=SUM(_xlfn._xlws.FILTER(일별!CJ:CJ, (일별!$A:$A >= 월별!$A6) * (일별!$A:$A < 월별!$A7), 0))} -> 58774 | BY6: {=SUM(_xlfn._xlws.FILTER(일별!CK:CK, (일별!$A:$A >= 월별!$A6) * (일별!$A:$A < 월별!$A7), 0))} -> 58866 | BZ6: {=SUM(_xlfn._xlws.FILTER(일별!CL:CL, (일별!$A:$A >= 월별!$A6) * (일별!$A:$A < 월별!$A7), 0))} -> 54820 | CA6: {=SUM(_xlfn._xlws.FILTER(일별!CM:CM, (일별!$A:$A >= 월별!$A6) * (일별!$A:$A < 월별!$A7), 0))} -> 56748 | CB6: {=SUM(_xlfn._xlws.FILTER(일별!CN:CN, (일별!$A:$A >= 월별!$A6) * (일별!$A:$A < 월별!$A7), 0))} -> 55260 | CC6: {=SUM(_xlfn._xlws.FILTER(일별!CO:CO, (일별!$A:$A >= 월별!$A6) * (일별!$A:$A < 월별!$A7), 0))} -> 59109 | CD6: {=SUM(_xlfn._xlws.FILTER(일별!CP:CP, (일별!$A:$A >= 월별!$A6) * (일별!$A:$A < 월별!$A7), 0))} -> 57990 | CE6: {=SUM(_xlfn._xlws.FILTER(일별!CQ:CQ, (일별!$A:$A >= 월별!$A6) * (일별!$A:$A < 월별!$A7), 0))} -> 58905 | CF6: {=SUM(_xlfn._xlws.FILTER(일별!CR:CR, (일별!$A:$A >= 월별!$A6) * (일별!$A:$A < 월별!$A7), 0))} -> 57983 | CG6: {=SUM(_xlfn._xlws.FILTER(일별!CS:CS, (일별!$A:$A >= 월별!$A6) * (일별!$A:$A < 월별!$A7), 0))} -> 57877 | CH6: {=SUM(_xlfn._xlws.FILTER(일별!CT:CT, (일별!$A:$A >= 월별!$A6) * (일별!$A:$A < 월별!$A7), 0))} -> 57830 | CI6: {=SUM(_xlfn._xlws.FILTER(일별!CU:CU, (일별!$A:$A >= 월별!$A6) * (일별!$A:$A < 월별!$A7), 0))} -> 55560 | CJ6: {=SUM(_xlfn._xlws.FILTER(일별!CV:CV, (일별!$A:$A >= 월별!$A6) * (일별!$A:$A < 월별!$A7), 0))} -> 56868 | CK6: {=SUM(_xlfn._xlws.FILTER(일별!CW:CW, (일별!$A:$A >= 월별!$A6) * (일별!$A:$A < 월별!$A7), 0))} -> 42103 | CL6: {=SUM(_xlfn._xlws.FILTER(일별!CX:CX, (일별!$A:$A >= 월별!$A6) * (일별!$A:$A < 월별!$A7), 0))} -> 59385 | CM6: {=SUM(_xlfn._xlws.FILTER(일별!CY:CY, (일별!$A:$A >= 월별!$A6) * (일별!$A:$A < 월별!$A7), 0))} -> 54570 | CN6: {=SUM(_xlfn._xlws.FILTER(일별!CZ:CZ, (일별!$A:$A >= 월별!$A6) * (일별!$A:$A < 월별!$A7), 0))} -> 280.376 | CO6: {=SUM(_xlfn._xlws.FILTER(일별!DA:DA, (일별!$A:$A >= 월별!$A6) * (일별!$A:$A < 월별!$A7), 0))} -> 243.153 | CP6: {=SUM(_xlfn._xlws.FILTER(일별!DB:DB, (일별!$A:$A >= 월별!$A6) * (일별!$A:$A < 월별!$A7), 0))} -> 279.526 | CQ6: {=SUM(_xlfn._xlws.FILTER(일별!DC:DC, (일별!$A:$A >= 월별!$A6) * (일별!$A:$A < 월별!$A7), 0))} -> 279.775 | CR6: {=SUM(_xlfn._xlws.FILTER(일별!DD:DD, (일별!$A:$A >= 월별!$A6) * (일별!$A:$A < 월별!$A7), 0))} -> 280.201 | CS6: {=SUM(_xlfn._xlws.FILTER(일별!DE:DE, (일별!$A:$A >= 월별!$A6) * (일별!$A:$A < 월별!$A7), 0))} -> 280.189 | CT6: {=SUM(_xlfn._xlws.FILTER(일별!DF:DF, (일별!$A:$A >= 월별!$A6) * (일별!$A:$A < 월별!$A7), 0))} -> 279.223 | CU6: {=SUM(_xlfn._xlws.FILTER(일별!DG:DG, (일별!$A:$A >= 월별!$A6) * (일별!$A:$A < 월별!$A7), 0))} -> 279.664 | CV6: {=SUM(_xlfn._xlws.FILTER(일별!DH:DH, (일별!$A:$A >= 월별!$A6) * (일별!$A:$A < 월별!$A7), 0))} -> 260.513 | CW6: {=SUM(_xlfn._xlws.FILTER(일별!DI:DI, (일별!$A:$A >= 월별!$A6) * (일별!$A:$A < 월별!$A7), 0))} -> 269.602 | CX6: {=SUM(_xlfn._xlws.FILTER(일별!DJ:DJ, (일별!$A:$A >= 월별!$A6) * (일별!$A:$A < 월별!$A7), 0))} -> 262.502 | CY6: {=SUM(_xlfn._xlws.FILTER(일별!DK:DK, (일별!$A:$A >= 월별!$A6) * (일별!$A:$A < 월별!$A7), 0))} -> 280.803 | CZ6: {=SUM(_xlfn._xlws.FILTER(일별!DL:DL, (일별!$A:$A >= 월별!$A6) * (일별!$A:$A < 월별!$A7), 0))} -> 275.445 | DA6: {=SUM(_xlfn._xlws.FILTER(일별!DM:DM, (일별!$A:$A >= 월별!$A6) * (일별!$A:$A < 월별!$A7), 0))} -> 279.841 | DB6: {=SUM(_xlfn._xlws.FILTER(일별!DN:DN, (일별!$A:$A >= 월별!$A6) * (일별!$A:$A < 월별!$A7), 0))} -> 275.413 | DC6: {=SUM(_xlfn._xlws.FILTER(일별!DO:DO, (일별!$A:$A >= 월별!$A6) * (일별!$A:$A < 월별!$A7), 0))} -> 274.962 | DD6: {=SUM(_xlfn._xlws.FILTER(일별!DP:DP, (일별!$A:$A >= 월별!$A6) * (일별!$A:$A < 월별!$A7), 0))} -> 274.731 | DE6: {=SUM(_xlfn._xlws.FILTER(일별!DQ:DQ, (일별!$A:$A >= 월별!$A6) * (일별!$A:$A < 월별!$A7), 0))} -> 264.031 | DF6: {=SUM(_xlfn._xlws.FILTER(일별!DR:DR, (일별!$A:$A >= 월별!$A6) * (일별!$A:$A < 월별!$A7), 0))} -> 270.22 | DG6: {=SUM(_xlfn._xlws.FILTER(일별!DS:DS, (일별!$A:$A >= 월별!$A6) * (일별!$A:$A < 월별!$A7), 0))} -> 199.917 | DH6: {=SUM(_xlfn._xlws.FILTER(일별!DT:DT, (일별!$A:$A >= 월별!$A6) * (일별!$A:$A < 월별!$A7), 0))} -> 282.116 | DI6: {=SUM(_xlfn._xlws.FILTER(일별!DU:DU, (일별!$A:$A >= 월별!$A6) * (일별!$A:$A < 월별!$A7), 0))} -> 259.229
A7: 46082 | B7: =SUMIFS(일별!$C:$C, 일별!$A:$A, ">="&월별!$A7, 일별!$A:$A, "<"&월별!$A8) -> 0 | C7: =B7/(월별!$A8 - 월별!$A7) -> 0 | D7: =SUMIFS(일별!E:E, 일별!$A:$A, ">="&월별!$A7, 일별!$A:$A, "<"&월별!$A8) -> 690 | E7: =D7/(월별!$A8 - 월별!$A7) -> 22.258065 | F7: =SUMIFS(일별!G:G, 일별!$A:$A, ">="&월별!$A7, 일별!$A:$A, "<"&월별!$A8) -> 508 | G7: =F7/(월별!$A8 - 월별!$A7) -> 16.387097 | H7: =D7+F7 -> 1198 | I7: =E7+G7 -> 38.645161 | J7: =SUMIFS(일별!I:I, 일별!$A:$A, ">="&월별!$A7, 일별!$A:$A, "<"&월별!$A8) -> 94.85 | K7: =J7/(월별!$A8 - 월별!$A7) -> 3.0596774 | L7: =SUMIFS(일별!K:K, 일별!$A:$A, ">="&월별!$A7, 일별!$A:$A, "<"&월별!$A8) -> 199.23 | M7: =L7/(월별!$A8 - 월별!$A7) -> 6.4267742 | N7: =SUMIFS(일별!M:M, 일별!$A:$A, ">="&월별!$A7, 일별!$A:$A, "<"&월별!$A8) -> 23.3 | O7: =N7/(월별!$A8 - 월별!$A7) -> 0.7516129 | P7: =SUMIFS(일별!O:O, 일별!$A:$A, ">="&월별!$A7, 일별!$A:$A, "<"&월별!$A8) -> 2140 | Q7: =P7/(월별!$A8 - 월별!$A7) -> 69.032258 | R7: =SUMIFS(일별!Q:Q, 일별!$A:$A, ">="&월별!$A7, 일별!$A:$A, "<"&월별!$A8) -> 2737 | S7: =R7/(월별!$A8 - 월별!$A7) -> 88.290323 | T7: =SUMIFS(일별!S:S, 일별!$A:$A, ">="&월별!$A7, 일별!$A:$A, "<"&월별!$A8) -> 0.31 | U7: =T7/(월별!$A8 - 월별!$A7) -> 0.01 | V7: =SUMIFS(일별!U:U, 일별!$A:$A, ">="&월별!$A7, 일별!$A:$A, "<"&월별!$A8) -> 0.39 | W7: =V7/(월별!$A8 - 월별!$A7) -> 0.012580645 | X7: =SUMIFS(일별!W:W, 일별!$A:$A, ">="&월별!$A7, 일별!$A:$A, "<"&월별!$A8) -> -70 | Y7: =X7/(월별!$A8 - 월별!$A7) -> -2.2580645 | Z7: =SUMIFS(일별!X:X, 일별!$A:$A, ">="&월별!$A7, 일별!$A:$A, "<"&월별!$A8) -> 1110819.6 | AA7: =SUMIFS(일별!Y:Y, 일별!$A:$A, ">="&월별!$A7, 일별!$A:$A, "<"&월별!$A8) -> 0 | AB7: =SUMIFS(일별!Z:Z, 일별!$A:$A, ">="&월별!$A7, 일별!$A:$A, "<"&월별!$A8) -> 0 | AC7: =SUMIFS(일별!AA:AA, 일별!$A:$A, ">="&월별!$A7, 일별!$A:$A, "<"&월별!$A8) -> 0 | AD7: =SUMIFS(일별!AB:AB, 일별!$A:$A, ">="&월별!$A7, 일별!$A:$A, "<"&월별!$A8) -> 0 | AE7: =SUMIFS(일별!AC:AC, 일별!$A:$A, ">="&월별!$A7, 일별!$A:$A, "<"&월별!$A8) -> 0 | AF7: =SUMIFS(일별!AD:AD, 일별!$A:$A, ">="&월별!$A7, 일별!$A:$A, "<"&월별!$A8) -> 176 | AG7: =SUMIFS(일별!AE:AE, 일별!$A:$A, ">="&월별!$A7, 일별!$A:$A, "<"&월별!$A8) -> 0 | AH7: =SUMIFS(일별!AF:AF, 일별!$A:$A, ">="&월별!$A7, 일별!$A:$A, "<"&월별!$A8) -> 0 | AI7: =SUMIFS(일별!AG:AG, 일별!$A:$A, ">="&월별!$A7, 일별!$A:$A, "<"&월별!$A8) -> 0 | AJ7: =SUMIFS(일별!AX:AX, 일별!$A:$A, ">="&월별!$A7, 일별!$A:$A, "<"&월별!$A8) -> 7059.714 | AK7: =SUMIFS(일별!AY:AY, 일별!$A:$A, ">="&월별!$A7, 일별!$A:$A, "<"&월별!$A8) -> 0 | AL7: =SUMIFS(일별!AZ:AZ, 일별!$A:$A, ">="&월별!$A7, 일별!$A:$A, "<"&월별!$A8) -> 0 | AM7: =SUMIFS(일별!BA:BA, 일별!$A:$A, ">="&월별!$A7, 일별!$A:$A, "<"&월별!$A8) -> 0 | AN7: =SUMIFS(일별!BB:BB, 일별!$A:$A, ">="&월별!$A7, 일별!$A:$A, "<"&월별!$A8) -> 0 | AO7: =SUMIFS(일별!BC:BC, 일별!$A:$A, ">="&월별!$A7, 일별!$A:$A, "<"&월별!$A8) -> 7059.714 | AP7: {=SUM(_xlfn._xlws.FILTER(일별!BH:CC, (일별!$A:$A >= 월별!$A7) * (일별!$A:$A < 월별!$A8), 0))} -> 0 | AQ7: =AP7/(월별!$A8 - 월별!$A7) -> 0 | AR7: {=SUM(_xlfn._xlws.FILTER(일별!CD:CY, (일별!$A:$A >= 월별!$A7) * (일별!$A:$A < 월별!$A8), 0))} -> #N/A | AS7: =AR7/(월별!$A8 - 월별!$A7) -> #N/A | AT7: {=SUM(_xlfn._xlws.FILTER(일별!CZ:DU, (일별!$A:$A >= 월별!$A7) * (일별!$A:$A < 월별!$A8), 0))} -> 0 | AU7: =AT7/(월별!$A8 - 월별!$A7) -> 0 | AV7: {=SUM(_xlfn._xlws.FILTER(일별!BH:BH, (일별!$A:$A >= 월별!$A7) * (일별!$A:$A < 월별!$A8), 0))} -> 0 | AW7: {=SUM(_xlfn._xlws.FILTER(일별!BI:BI, (일별!$A:$A >= 월별!$A7) * (일별!$A:$A < 월별!$A8), 0))} -> 0 | AX7: {=SUM(_xlfn._xlws.FILTER(일별!BJ:BJ, (일별!$A:$A >= 월별!$A7) * (일별!$A:$A < 월별!$A8), 0))} -> 0 | AY7: {=SUM(_xlfn._xlws.FILTER(일별!BK:BK, (일별!$A:$A >= 월별!$A7) * (일별!$A:$A < 월별!$A8), 0))} -> 0 | AZ7: {=SUM(_xlfn._xlws.FILTER(일별!BL:BL, (일별!$A:$A >= 월별!$A7) * (일별!$A:$A < 월별!$A8), 0))} -> 0 | BA7: {=SUM(_xlfn._xlws.FILTER(일별!BM:BM, (일별!$A:$A >= 월별!$A7) * (일별!$A:$A < 월별!$A8), 0))} -> 0 | BB7: {=SUM(_xlfn._xlws.FILTER(일별!BN:BN, (일별!$A:$A >= 월별!$A7) * (일별!$A:$A < 월별!$A8), 0))} -> 0 | BC7: {=SUM(_xlfn._xlws.FILTER(일별!BO:BO, (일별!$A:$A >= 월별!$A7) * (일별!$A:$A < 월별!$A8), 0))} -> 0 | BD7: {=SUM(_xlfn._xlws.FILTER(일별!BP:BP, (일별!$A:$A >= 월별!$A7) * (일별!$A:$A < 월별!$A8), 0))} -> 0 | BE7: {=SUM(_xlfn._xlws.FILTER(일별!BQ:BQ, (일별!$A:$A >= 월별!$A7) * (일별!$A:$A < 월별!$A8), 0))} -> 0 | BF7: {=SUM(_xlfn._xlws.FILTER(일별!BR:BR, (일별!$A:$A >= 월별!$A7) * (일별!$A:$A < 월별!$A8), 0))} -> 0 | BG7: {=SUM(_xlfn._xlws.FILTER(일별!BS:BS, (일별!$A:$A >= 월별!$A7) * (일별!$A:$A < 월별!$A8), 0))} -> 0 | BH7: {=SUM(_xlfn._xlws.FILTER(일별!BT:BT, (일별!$A:$A >= 월별!$A7) * (일별!$A:$A < 월별!$A8), 0))} -> 0 | BI7: {=SUM(_xlfn._xlws.FILTER(일별!BU:BU, (일별!$A:$A >= 월별!$A7) * (일별!$A:$A < 월별!$A8), 0))} -> 0 | BJ7: {=SUM(_xlfn._xlws.FILTER(일별!BV:BV, (일별!$A:$A >= 월별!$A7) * (일별!$A:$A < 월별!$A8), 0))} -> 0 | BK7: {=SUM(_xlfn._xlws.FILTER(일별!BW:BW, (일별!$A:$A >= 월별!$A7) * (일별!$A:$A < 월별!$A8), 0))} -> 0 | BL7: {=SUM(_xlfn._xlws.FILTER(일별!BX:BX, (일별!$A:$A >= 월별!$A7) * (일별!$A:$A < 월별!$A8), 0))} -> 0 | BM7: {=SUM(_xlfn._xlws.FILTER(일별!BY:BY, (일별!$A:$A >= 월별!$A7) * (일별!$A:$A < 월별!$A8), 0))} -> 0 | BN7: {=SUM(_xlfn._xlws.FILTER(일별!BZ:BZ, (일별!$A:$A >= 월별!$A7) * (일별!$A:$A < 월별!$A8), 0))} -> 0 | BO7: {=SUM(_xlfn._xlws.FILTER(일별!CA:CA, (일별!$A:$A >= 월별!$A7) * (일별!$A:$A < 월별!$A8), 0))} -> 0 | BP7: {=SUM(_xlfn._xlws.FILTER(일별!CB:CB, (일별!$A:$A >= 월별!$A7) * (일별!$A:$A < 월별!$A8), 0))} -> 0 | BQ7: {=SUM(_xlfn._xlws.FILTER(일별!CC:CC, (일별!$A:$A >= 월별!$A7) * (일별!$A:$A < 월별!$A8), 0))} -> 0 | BR7: {=SUM(_xlfn._xlws.FILTER(일별!CD:CD, (일별!$A:$A >= 월별!$A7) * (일별!$A:$A < 월별!$A8), 0))} -> #N/A | BS7: {=SUM(_xlfn._xlws.FILTER(일별!CE:CE, (일별!$A:$A >= 월별!$A7) * (일별!$A:$A < 월별!$A8), 0))} -> #N/A | BT7: {=SUM(_xlfn._xlws.FILTER(일별!CF:CF, (일별!$A:$A >= 월별!$A7) * (일별!$A:$A < 월별!$A8), 0))} -> #N/A | BU7: {=SUM(_xlfn._xlws.FILTER(일별!CG:CG, (일별!$A:$A >= 월별!$A7) * (일별!$A:$A < 월별!$A8), 0))} -> #N/A | BV7: {=SUM(_xlfn._xlws.FILTER(일별!CH:CH, (일별!$A:$A >= 월별!$A7) * (일별!$A:$A < 월별!$A8), 0))} -> #N/A | BW7: {=SUM(_xlfn._xlws.FILTER(일별!CI:CI, (일별!$A:$A >= 월별!$A7) * (일별!$A:$A < 월별!$A8), 0))} -> #N/A | BX7: {=SUM(_xlfn._xlws.FILTER(일별!CJ:CJ, (일별!$A:$A >= 월별!$A7) * (일별!$A:$A < 월별!$A8), 0))} -> #N/A | BY7: {=SUM(_xlfn._xlws.FILTER(일별!CK:CK, (일별!$A:$A >= 월별!$A7) * (일별!$A:$A < 월별!$A8), 0))} -> #N/A | BZ7: {=SUM(_xlfn._xlws.FILTER(일별!CL:CL, (일별!$A:$A >= 월별!$A7) * (일별!$A:$A < 월별!$A8), 0))} -> #N/A | CA7: {=SUM(_xlfn._xlws.FILTER(일별!CM:CM, (일별!$A:$A >= 월별!$A7) * (일별!$A:$A < 월별!$A8), 0))} -> #N/A | CB7: {=SUM(_xlfn._xlws.FILTER(일별!CN:CN, (일별!$A:$A >= 월별!$A7) * (일별!$A:$A < 월별!$A8), 0))} -> #N/A | CC7: {=SUM(_xlfn._xlws.FILTER(일별!CO:CO, (일별!$A:$A >= 월별!$A7) * (일별!$A:$A < 월별!$A8), 0))} -> #N/A | CD7: {=SUM(_xlfn._xlws.FILTER(일별!CP:CP, (일별!$A:$A >= 월별!$A7) * (일별!$A:$A < 월별!$A8), 0))} -> #N/A | CE7: {=SUM(_xlfn._xlws.FILTER(일별!CQ:CQ, (일별!$A:$A >= 월별!$A7) * (일별!$A:$A < 월별!$A8), 0))} -> #N/A | CF7: {=SUM(_xlfn._xlws.FILTER(일별!CR:CR, (일별!$A:$A >= 월별!$A7) * (일별!$A:$A < 월별!$A8), 0))} -> #N/A | CG7: {=SUM(_xlfn._xlws.FILTER(일별!CS:CS, (일별!$A:$A >= 월별!$A7) * (일별!$A:$A < 월별!$A8), 0))} -> #N/A | CH7: {=SUM(_xlfn._xlws.FILTER(일별!CT:CT, (일별!$A:$A >= 월별!$A7) * (일별!$A:$A < 월별!$A8), 0))} -> #N/A | CI7: {=SUM(_xlfn._xlws.FILTER(일별!CU:CU, (일별!$A:$A >= 월별!$A7) * (일별!$A:$A < 월별!$A8), 0))} -> #N/A | CJ7: {=SUM(_xlfn._xlws.FILTER(일별!CV:CV, (일별!$A:$A >= 월별!$A7) * (일별!$A:$A < 월별!$A8), 0))} -> #N/A | CK7: {=SUM(_xlfn._xlws.FILTER(일별!CW:CW, (일별!$A:$A >= 월별!$A7) * (일별!$A:$A < 월별!$A8), 0))} -> #N/A | CL7: {=SUM(_xlfn._xlws.FILTER(일별!CX:CX, (일별!$A:$A >= 월별!$A7) * (일별!$A:$A < 월별!$A8), 0))} -> #N/A | CM7: {=SUM(_xlfn._xlws.FILTER(일별!CY:CY, (일별!$A:$A >= 월별!$A7) * (일별!$A:$A < 월별!$A8), 0))} -> #N/A | CN7: {=SUM(_xlfn._xlws.FILTER(일별!CZ:CZ, (일별!$A:$A >= 월별!$A7) * (일별!$A:$A < 월별!$A8), 0))} -> 0 | CO7: {=SUM(_xlfn._xlws.FILTER(일별!DA:DA, (일별!$A:$A >= 월별!$A7) * (일별!$A:$A < 월별!$A8), 0))} -> 0 | CP7: {=SUM(_xlfn._xlws.FILTER(일별!DB:DB, (일별!$A:$A >= 월별!$A7) * (일별!$A:$A < 월별!$A8), 0))} -> 0 | CQ7: {=SUM(_xlfn._xlws.FILTER(일별!DC:DC, (일별!$A:$A >= 월별!$A7) * (일별!$A:$A < 월별!$A8), 0))} -> 0 | CR7: {=SUM(_xlfn._xlws.FILTER(일별!DD:DD, (일별!$A:$A >= 월별!$A7) * (일별!$A:$A < 월별!$A8), 0))} -> 0 | CS7: {=SUM(_xlfn._xlws.FILTER(일별!DE:DE, (일별!$A:$A >= 월별!$A7) * (일별!$A:$A < 월별!$A8), 0))} -> 0 | CT7: {=SUM(_xlfn._xlws.FILTER(일별!DF:DF, (일별!$A:$A >= 월별!$A7) * (일별!$A:$A < 월별!$A8), 0))} -> 0 | CU7: {=SUM(_xlfn._xlws.FILTER(일별!DG:DG, (일별!$A:$A >= 월별!$A7) * (일별!$A:$A < 월별!$A8), 0))} -> 0 | CV7: {=SUM(_xlfn._xlws.FILTER(일별!DH:DH, (일별!$A:$A >= 월별!$A7) * (일별!$A:$A < 월별!$A8), 0))} -> 0 | CW7: {=SUM(_xlfn._xlws.FILTER(일별!DI:DI, (일별!$A:$A >= 월별!$A7) * (일별!$A:$A < 월별!$A8), 0))} -> 0 | CX7: {=SUM(_xlfn._xlws.FILTER(일별!DJ:DJ, (일별!$A:$A >= 월별!$A7) * (일별!$A:$A < 월별!$A8), 0))} -> 0 | CY7: {=SUM(_xlfn._xlws.FILTER(일별!DK:DK, (일별!$A:$A >= 월별!$A7) * (일별!$A:$A < 월별!$A8), 0))} -> 0 | CZ7: {=SUM(_xlfn._xlws.FILTER(일별!DL:DL, (일별!$A:$A >= 월별!$A7) * (일별!$A:$A < 월별!$A8), 0))} -> 0 | DA7: {=SUM(_xlfn._xlws.FILTER(일별!DM:DM, (일별!$A:$A >= 월별!$A7) * (일별!$A:$A < 월별!$A8), 0))} -> 0 | DB7: {=SUM(_xlfn._xlws.FILTER(일별!DN:DN, (일별!$A:$A >= 월별!$A7) * (일별!$A:$A < 월별!$A8), 0))} -> 0 | DC7: {=SUM(_xlfn._xlws.FILTER(일별!DO:DO, (일별!$A:$A >= 월별!$A7) * (일별!$A:$A < 월별!$A8), 0))} -> 0 | DD7: {=SUM(_xlfn._xlws.FILTER(일별!DP:DP, (일별!$A:$A >= 월별!$A7) * (일별!$A:$A < 월별!$A8), 0))} -> 0 | DE7: {=SUM(_xlfn._xlws.FILTER(일별!DQ:DQ, (일별!$A:$A >= 월별!$A7) * (일별!$A:$A < 월별!$A8), 0))} -> 0 | DF7: {=SUM(_xlfn._xlws.FILTER(일별!DR:DR, (일별!$A:$A >= 월별!$A7) * (일별!$A:$A < 월별!$A8), 0))} -> 0 | DG7: {=SUM(_xlfn._xlws.FILTER(일별!DS:DS, (일별!$A:$A >= 월별!$A7) * (일별!$A:$A < 월별!$A8), 0))} -> 0 | DH7: {=SUM(_xlfn._xlws.FILTER(일별!DT:DT, (일별!$A:$A >= 월별!$A7) * (일별!$A:$A < 월별!$A8), 0))} -> 0 | DI7: {=SUM(_xlfn._xlws.FILTER(일별!DU:DU, (일별!$A:$A >= 월별!$A7) * (일별!$A:$A < 월별!$A8), 0))} -> 0
A8: 46113 | B8: =SUMIFS(일별!$C:$C, 일별!$A:$A, ">="&월별!$A8, 일별!$A:$A, "<"&월별!$A9) -> 0 | C8: =B8/(월별!$A9 - 월별!$A8) -> 0 | D8: =SUMIFS(일별!E:E, 일별!$A:$A, ">="&월별!$A8, 일별!$A:$A, "<"&월별!$A9) -> 122 | E8: =D8/(월별!$A9 - 월별!$A8) -> 4.0666667 | F8: =SUMIFS(일별!G:G, 일별!$A:$A, ">="&월별!$A8, 일별!$A:$A, "<"&월별!$A9) -> 117 | G8: =F8/(월별!$A9 - 월별!$A8) -> 3.9 | H8: =D8+F8 -> 239 | I8: =E8+G8 -> 7.9666667 | J8: =SUMIFS(일별!I:I, 일별!$A:$A, ">="&월별!$A8, 일별!$A:$A, "<"&월별!$A9) -> 23.19 | K8: =J8/(월별!$A9 - 월별!$A8) -> 0.773 | L8: =SUMIFS(일별!K:K, 일별!$A:$A, ">="&월별!$A8, 일별!$A:$A, "<"&월별!$A9) -> 7.89 | M8: =L8/(월별!$A9 - 월별!$A8) -> 0.263 | N8: =SUMIFS(일별!M:M, 일별!$A:$A, ">="&월별!$A8, 일별!$A:$A, "<"&월별!$A9) -> 5.7 | O8: =N8/(월별!$A9 - 월별!$A8) -> 0.19 | P8: =SUMIFS(일별!O:O, 일별!$A:$A, ">="&월별!$A8, 일별!$A:$A, "<"&월별!$A9) -> 502 | Q8: =P8/(월별!$A9 - 월별!$A8) -> 16.733333 | R8: =SUMIFS(일별!Q:Q, 일별!$A:$A, ">="&월별!$A8, 일별!$A:$A, "<"&월별!$A9) -> 558 | S8: =R8/(월별!$A9 - 월별!$A8) -> 18.6 | T8: =SUMIFS(일별!S:S, 일별!$A:$A, ">="&월별!$A8, 일별!$A:$A, "<"&월별!$A9) -> -0.01 | U8: =T8/(월별!$A9 - 월별!$A8) -> -0.00033333333 | V8: =SUMIFS(일별!U:U, 일별!$A:$A, ">="&월별!$A8, 일별!$A:$A, "<"&월별!$A9) -> 0.15 | W8: =V8/(월별!$A9 - 월별!$A8) -> 0.005 | X8: =SUMIFS(일별!W:W, 일별!$A:$A, ">="&월별!$A8, 일별!$A:$A, "<"&월별!$A9) -> -577 | Y8: =X8/(월별!$A9 - 월별!$A8) -> -19.233333 | Z8: =SUMIFS(일별!X:X, 일별!$A:$A, ">="&월별!$A8, 일별!$A:$A, "<"&월별!$A9) -> 21451.94 | AA8: =SUMIFS(일별!Y:Y, 일별!$A:$A, ">="&월별!$A8, 일별!$A:$A, "<"&월별!$A9) -> 0 | AB8: =SUMIFS(일별!Z:Z, 일별!$A:$A, ">="&월별!$A8, 일별!$A:$A, "<"&월별!$A9) -> 0 | AC8: =SUMIFS(일별!AA:AA, 일별!$A:$A, ">="&월별!$A8, 일별!$A:$A, "<"&월별!$A9) -> 0 | AD8: =SUMIFS(일별!AB:AB, 일별!$A:$A, ">="&월별!$A8, 일별!$A:$A, "<"&월별!$A9) -> 0 | AE8: =SUMIFS(일별!AC:AC, 일별!$A:$A, ">="&월별!$A8, 일별!$A:$A, "<"&월별!$A9) -> 0 | AF8: =SUMIFS(일별!AD:AD, 일별!$A:$A, ">="&월별!$A8, 일별!$A:$A, "<"&월별!$A9) -> 12 | AG8: =SUMIFS(일별!AE:AE, 일별!$A:$A, ">="&월별!$A8, 일별!$A:$A, "<"&월별!$A9) -> 0 | AH8: =SUMIFS(일별!AF:AF, 일별!$A:$A, ">="&월별!$A8, 일별!$A:$A, "<"&월별!$A9) -> 0 | AI8: =SUMIFS(일별!AG:AG, 일별!$A:$A, ">="&월별!$A8, 일별!$A:$A, "<"&월별!$A9) -> 0 | AJ8: =SUMIFS(일별!AX:AX, 일별!$A:$A, ">="&월별!$A8, 일별!$A:$A, "<"&월별!$A9) -> 114 | AK8: =SUMIFS(일별!AY:AY, 일별!$A:$A, ">="&월별!$A8, 일별!$A:$A, "<"&월별!$A9) -> 0 | AL8: =SUMIFS(일별!AZ:AZ, 일별!$A:$A, ">="&월별!$A8, 일별!$A:$A, "<"&월별!$A9) -> 0 | AM8: =SUMIFS(일별!BA:BA, 일별!$A:$A, ">="&월별!$A8, 일별!$A:$A, "<"&월별!$A9) -> 0 | AN8: =SUMIFS(일별!BB:BB, 일별!$A:$A, ">="&월별!$A8, 일별!$A:$A, "<"&월별!$A9) -> 0 | AO8: =SUMIFS(일별!BC:BC, 일별!$A:$A, ">="&월별!$A8, 일별!$A:$A, "<"&월별!$A9) -> 114 | AP8: {=SUM(_xlfn._xlws.FILTER(일별!BH:CC, (일별!$A:$A >= 월별!$A8) * (일별!$A:$A < 월별!$A9), 0))} -> 0 | AQ8: =AP8/(월별!$A9 - 월별!$A8) -> 0 | AR8: {=SUM(_xlfn._xlws.FILTER(일별!CD:CY, (일별!$A:$A >= 월별!$A8) * (일별!$A:$A < 월별!$A9), 0))} -> 0 | AS8: =AR8/(월별!$A9 - 월별!$A8) -> 0 | AT8: {=SUM(_xlfn._xlws.FILTER(일별!CZ:DU, (일별!$A:$A >= 월별!$A8) * (일별!$A:$A < 월별!$A9), 0))} -> 0 | AU8: =AT8/(월별!$A9 - 월별!$A8) -> 0 | AV8: {=SUM(_xlfn._xlws.FILTER(일별!BH:BH, (일별!$A:$A >= 월별!$A8) * (일별!$A:$A < 월별!$A9), 0))} -> 0 | AW8: {=SUM(_xlfn._xlws.FILTER(일별!BI:BI, (일별!$A:$A >= 월별!$A8) * (일별!$A:$A < 월별!$A9), 0))} -> 0 | AX8: {=SUM(_xlfn._xlws.FILTER(일별!BJ:BJ, (일별!$A:$A >= 월별!$A8) * (일별!$A:$A < 월별!$A9), 0))} -> 0 | AY8: {=SUM(_xlfn._xlws.FILTER(일별!BK:BK, (일별!$A:$A >= 월별!$A8) * (일별!$A:$A < 월별!$A9), 0))} -> 0 | AZ8: {=SUM(_xlfn._xlws.FILTER(일별!BL:BL, (일별!$A:$A >= 월별!$A8) * (일별!$A:$A < 월별!$A9), 0))} -> 0 | BA8: {=SUM(_xlfn._xlws.FILTER(일별!BM:BM, (일별!$A:$A >= 월별!$A8) * (일별!$A:$A < 월별!$A9), 0))} -> 0 | BB8: {=SUM(_xlfn._xlws.FILTER(일별!BN:BN, (일별!$A:$A >= 월별!$A8) * (일별!$A:$A < 월별!$A9), 0))} -> 0 | BC8: {=SUM(_xlfn._xlws.FILTER(일별!BO:BO, (일별!$A:$A >= 월별!$A8) * (일별!$A:$A < 월별!$A9), 0))} -> 0 | BD8: {=SUM(_xlfn._xlws.FILTER(일별!BP:BP, (일별!$A:$A >= 월별!$A8) * (일별!$A:$A < 월별!$A9), 0))} -> 0 | BE8: {=SUM(_xlfn._xlws.FILTER(일별!BQ:BQ, (일별!$A:$A >= 월별!$A8) * (일별!$A:$A < 월별!$A9), 0))} -> 0 | BF8: {=SUM(_xlfn._xlws.FILTER(일별!BR:BR, (일별!$A:$A >= 월별!$A8) * (일별!$A:$A < 월별!$A9), 0))} -> 0 | BG8: {=SUM(_xlfn._xlws.FILTER(일별!BS:BS, (일별!$A:$A >= 월별!$A8) * (일별!$A:$A < 월별!$A9), 0))} -> 0 | BH8: {=SUM(_xlfn._xlws.FILTER(일별!BT:BT, (일별!$A:$A >= 월별!$A8) * (일별!$A:$A < 월별!$A9), 0))} -> 0 | BI8: {=SUM(_xlfn._xlws.FILTER(일별!BU:BU, (일별!$A:$A >= 월별!$A8) * (일별!$A:$A < 월별!$A9), 0))} -> 0 | BJ8: {=SUM(_xlfn._xlws.FILTER(일별!BV:BV, (일별!$A:$A >= 월별!$A8) * (일별!$A:$A < 월별!$A9), 0))} -> 0 | BK8: {=SUM(_xlfn._xlws.FILTER(일별!BW:BW, (일별!$A:$A >= 월별!$A8) * (일별!$A:$A < 월별!$A9), 0))} -> 0 | BL8: {=SUM(_xlfn._xlws.FILTER(일별!BX:BX, (일별!$A:$A >= 월별!$A8) * (일별!$A:$A < 월별!$A9), 0))} -> 0 | BM8: {=SUM(_xlfn._xlws.FILTER(일별!BY:BY, (일별!$A:$A >= 월별!$A8) * (일별!$A:$A < 월별!$A9), 0))} -> 0 | BN8: {=SUM(_xlfn._xlws.FILTER(일별!BZ:BZ, (일별!$A:$A >= 월별!$A8) * (일별!$A:$A < 월별!$A9), 0))} -> 0 | BO8: {=SUM(_xlfn._xlws.FILTER(일별!CA:CA, (일별!$A:$A >= 월별!$A8) * (일별!$A:$A < 월별!$A9), 0))} -> 0 | BP8: {=SUM(_xlfn._xlws.FILTER(일별!CB:CB, (일별!$A:$A >= 월별!$A8) * (일별!$A:$A < 월별!$A9), 0))} -> 0 | BQ8: {=SUM(_xlfn._xlws.FILTER(일별!CC:CC, (일별!$A:$A >= 월별!$A8) * (일별!$A:$A < 월별!$A9), 0))} -> 0 | BR8: {=SUM(_xlfn._xlws.FILTER(일별!CD:CD, (일별!$A:$A >= 월별!$A8) * (일별!$A:$A < 월별!$A9), 0))} -> 0 | BS8: {=SUM(_xlfn._xlws.FILTER(일별!CE:CE, (일별!$A:$A >= 월별!$A8) * (일별!$A:$A < 월별!$A9), 0))} -> 0 | BT8: {=SUM(_xlfn._xlws.FILTER(일별!CF:CF, (일별!$A:$A >= 월별!$A8) * (일별!$A:$A < 월별!$A9), 0))} -> 0 | BU8: {=SUM(_xlfn._xlws.FILTER(일별!CG:CG, (일별!$A:$A >= 월별!$A8) * (일별!$A:$A < 월별!$A9), 0))} -> 0 | BV8: {=SUM(_xlfn._xlws.FILTER(일별!CH:CH, (일별!$A:$A >= 월별!$A8) * (일별!$A:$A < 월별!$A9), 0))} -> 0 | BW8: {=SUM(_xlfn._xlws.FILTER(일별!CI:CI, (일별!$A:$A >= 월별!$A8) * (일별!$A:$A < 월별!$A9), 0))} -> 0 | BX8: {=SUM(_xlfn._xlws.FILTER(일별!CJ:CJ, (일별!$A:$A >= 월별!$A8) * (일별!$A:$A < 월별!$A9), 0))} -> 0 | BY8: {=SUM(_xlfn._xlws.FILTER(일별!CK:CK, (일별!$A:$A >= 월별!$A8) * (일별!$A:$A < 월별!$A9), 0))} -> 0 | BZ8: {=SUM(_xlfn._xlws.FILTER(일별!CL:CL, (일별!$A:$A >= 월별!$A8) * (일별!$A:$A < 월별!$A9), 0))} -> 0 | CA8: {=SUM(_xlfn._xlws.FILTER(일별!CM:CM, (일별!$A:$A >= 월별!$A8) * (일별!$A:$A < 월별!$A9), 0))} -> 0 | CB8: {=SUM(_xlfn._xlws.FILTER(일별!CN:CN, (일별!$A:$A >= 월별!$A8) * (일별!$A:$A < 월별!$A9), 0))} -> 0 | CC8: {=SUM(_xlfn._xlws.FILTER(일별!CO:CO, (일별!$A:$A >= 월별!$A8) * (일별!$A:$A < 월별!$A9), 0))} -> 0 | CD8: {=SUM(_xlfn._xlws.FILTER(일별!CP:CP, (일별!$A:$A >= 월별!$A8) * (일별!$A:$A < 월별!$A9), 0))} -> 0 | CE8: {=SUM(_xlfn._xlws.FILTER(일별!CQ:CQ, (일별!$A:$A >= 월별!$A8) * (일별!$A:$A < 월별!$A9), 0))} -> 0 | CF8: {=SUM(_xlfn._xlws.FILTER(일별!CR:CR, (일별!$A:$A >= 월별!$A8) * (일별!$A:$A < 월별!$A9), 0))} -> 0 | CG8: {=SUM(_xlfn._xlws.FILTER(일별!CS:CS, (일별!$A:$A >= 월별!$A8) * (일별!$A:$A < 월별!$A9), 0))} -> 0 | CH8: {=SUM(_xlfn._xlws.FILTER(일별!CT:CT, (일별!$A:$A >= 월별!$A8) * (일별!$A:$A < 월별!$A9), 0))} -> 0 | CI8: {=SUM(_xlfn._xlws.FILTER(일별!CU:CU, (일별!$A:$A >= 월별!$A8) * (일별!$A:$A < 월별!$A9), 0))} -> 0 | CJ8: {=SUM(_xlfn._xlws.FILTER(일별!CV:CV, (일별!$A:$A >= 월별!$A8) * (일별!$A:$A < 월별!$A9), 0))} -> 0 | CK8: {=SUM(_xlfn._xlws.FILTER(일별!CW:CW, (일별!$A:$A >= 월별!$A8) * (일별!$A:$A < 월별!$A9), 0))} -> 0 | CL8: {=SUM(_xlfn._xlws.FILTER(일별!CX:CX, (일별!$A:$A >= 월별!$A8) * (일별!$A:$A < 월별!$A9), 0))} -> 0 | CM8: {=SUM(_xlfn._xlws.FILTER(일별!CY:CY, (일별!$A:$A >= 월별!$A8) * (일별!$A:$A < 월별!$A9), 0))} -> 0 | CN8: {=SUM(_xlfn._xlws.FILTER(일별!CZ:CZ, (일별!$A:$A >= 월별!$A8) * (일별!$A:$A < 월별!$A9), 0))} -> 0 | CO8: {=SUM(_xlfn._xlws.FILTER(일별!DA:DA, (일별!$A:$A >= 월별!$A8) * (일별!$A:$A < 월별!$A9), 0))} -> 0 | CP8: {=SUM(_xlfn._xlws.FILTER(일별!DB:DB, (일별!$A:$A >= 월별!$A8) * (일별!$A:$A < 월별!$A9), 0))} -> 0 | CQ8: {=SUM(_xlfn._xlws.FILTER(일별!DC:DC, (일별!$A:$A >= 월별!$A8) * (일별!$A:$A < 월별!$A9), 0))} -> 0 | CR8: {=SUM(_xlfn._xlws.FILTER(일별!DD:DD, (일별!$A:$A >= 월별!$A8) * (일별!$A:$A < 월별!$A9), 0))} -> 0 | CS8: {=SUM(_xlfn._xlws.FILTER(일별!DE:DE, (일별!$A:$A >= 월별!$A8) * (일별!$A:$A < 월별!$A9), 0))} -> 0 | CT8: {=SUM(_xlfn._xlws.FILTER(일별!DF:DF, (일별!$A:$A >= 월별!$A8) * (일별!$A:$A < 월별!$A9), 0))} -> 0 | CU8: {=SUM(_xlfn._xlws.FILTER(일별!DG:DG, (일별!$A:$A >= 월별!$A8) * (일별!$A:$A < 월별!$A9), 0))} -> 0 | CV8: {=SUM(_xlfn._xlws.FILTER(일별!DH:DH, (일별!$A:$A >= 월별!$A8) * (일별!$A:$A < 월별!$A9), 0))} -> 0 | CW8: {=SUM(_xlfn._xlws.FILTER(일별!DI:DI, (일별!$A:$A >= 월별!$A8) * (일별!$A:$A < 월별!$A9), 0))} -> 0 | CX8: {=SUM(_xlfn._xlws.FILTER(일별!DJ:DJ, (일별!$A:$A >= 월별!$A8) * (일별!$A:$A < 월별!$A9), 0))} -> 0 | CY8: {=SUM(_xlfn._xlws.FILTER(일별!DK:DK, (일별!$A:$A >= 월별!$A8) * (일별!$A:$A < 월별!$A9), 0))} -> 0 | CZ8: {=SUM(_xlfn._xlws.FILTER(일별!DL:DL, (일별!$A:$A >= 월별!$A8) * (일별!$A:$A < 월별!$A9), 0))} -> 0 | DA8: {=SUM(_xlfn._xlws.FILTER(일별!DM:DM, (일별!$A:$A >= 월별!$A8) * (일별!$A:$A < 월별!$A9), 0))} -> 0 | DB8: {=SUM(_xlfn._xlws.FILTER(일별!DN:DN, (일별!$A:$A >= 월별!$A8) * (일별!$A:$A < 월별!$A9), 0))} -> 0 | DC8: {=SUM(_xlfn._xlws.FILTER(일별!DO:DO, (일별!$A:$A >= 월별!$A8) * (일별!$A:$A < 월별!$A9), 0))} -> 0 | DD8: {=SUM(_xlfn._xlws.FILTER(일별!DP:DP, (일별!$A:$A >= 월별!$A8) * (일별!$A:$A < 월별!$A9), 0))} -> 0 | DE8: {=SUM(_xlfn._xlws.FILTER(일별!DQ:DQ, (일별!$A:$A >= 월별!$A8) * (일별!$A:$A < 월별!$A9), 0))} -> 0 | DF8: {=SUM(_xlfn._xlws.FILTER(일별!DR:DR, (일별!$A:$A >= 월별!$A8) * (일별!$A:$A < 월별!$A9), 0))} -> 0 | DG8: {=SUM(_xlfn._xlws.FILTER(일별!DS:DS, (일별!$A:$A >= 월별!$A8) * (일별!$A:$A < 월별!$A9), 0))} -> 0 | DH8: {=SUM(_xlfn._xlws.FILTER(일별!DT:DT, (일별!$A:$A >= 월별!$A8) * (일별!$A:$A < 월별!$A9), 0))} -> 0 | DI8: {=SUM(_xlfn._xlws.FILTER(일별!DU:DU, (일별!$A:$A >= 월별!$A8) * (일별!$A:$A < 월별!$A9), 0))} -> 0
A9: 46143 | B9: =SUMIFS(일별!$C:$C, 일별!$A:$A, ">="&월별!$A9, 일별!$A:$A, "<"&월별!$A10) -> 0 | C9: =B9/(월별!$A10 - 월별!$A9) -> 0 | D9: =SUMIFS(일별!E:E, 일별!$A:$A, ">="&월별!$A9, 일별!$A:$A, "<"&월별!$A10) -> 0 | E9: =D9/(월별!$A10 - 월별!$A9) -> 0 | F9: =SUMIFS(일별!G:G, 일별!$A:$A, ">="&월별!$A9, 일별!$A:$A, "<"&월별!$A10) -> 0 | G9: =F9/(월별!$A10 - 월별!$A9) -> 0 | H9: =D9+F9 -> 0 | I9: =E9+G9 -> 0 | J9: =SUMIFS(일별!I:I, 일별!$A:$A, ">="&월별!$A9, 일별!$A:$A, "<"&월별!$A10) -> 0 | K9: =J9/(월별!$A10 - 월별!$A9) -> 0 | L9: =SUMIFS(일별!K:K, 일별!$A:$A, ">="&월별!$A9, 일별!$A:$A, "<"&월별!$A10) -> 0 | M9: =L9/(월별!$A10 - 월별!$A9) -> 0 | N9: =SUMIFS(일별!M:M, 일별!$A:$A, ">="&월별!$A9, 일별!$A:$A, "<"&월별!$A10) -> 0 | O9: =N9/(월별!$A10 - 월별!$A9) -> 0 | P9: =SUMIFS(일별!O:O, 일별!$A:$A, ">="&월별!$A9, 일별!$A:$A, "<"&월별!$A10) -> 0 | Q9: =P9/(월별!$A10 - 월별!$A9) -> 0 | R9: =SUMIFS(일별!Q:Q, 일별!$A:$A, ">="&월별!$A9, 일별!$A:$A, "<"&월별!$A10) -> 0 | S9: =R9/(월별!$A10 - 월별!$A9) -> 0 | T9: =SUMIFS(일별!S:S, 일별!$A:$A, ">="&월별!$A9, 일별!$A:$A, "<"&월별!$A10) -> 0 | U9: =T9/(월별!$A10 - 월별!$A9) -> 0 | V9: =SUMIFS(일별!U:U, 일별!$A:$A, ">="&월별!$A9, 일별!$A:$A, "<"&월별!$A10) -> 0 | W9: =V9/(월별!$A10 - 월별!$A9) -> 0 | X9: =SUMIFS(일별!W:W, 일별!$A:$A, ">="&월별!$A9, 일별!$A:$A, "<"&월별!$A10) -> 0 | Y9: =X9/(월별!$A10 - 월별!$A9) -> 0 | Z9: =SUMIFS(일별!X:X, 일별!$A:$A, ">="&월별!$A9, 일별!$A:$A, "<"&월별!$A10) -> 0 | AA9: =SUMIFS(일별!Y:Y, 일별!$A:$A, ">="&월별!$A9, 일별!$A:$A, "<"&월별!$A10) -> 0 | AB9: =SUMIFS(일별!Z:Z, 일별!$A:$A, ">="&월별!$A9, 일별!$A:$A, "<"&월별!$A10) -> 0 | AC9: =SUMIFS(일별!AA:AA, 일별!$A:$A, ">="&월별!$A9, 일별!$A:$A, "<"&월별!$A10) -> 0 | AD9: =SUMIFS(일별!AB:AB, 일별!$A:$A, ">="&월별!$A9, 일별!$A:$A, "<"&월별!$A10) -> 0 | AE9: =SUMIFS(일별!AC:AC, 일별!$A:$A, ">="&월별!$A9, 일별!$A:$A, "<"&월별!$A10) -> 0 | AF9: =SUMIFS(일별!AD:AD, 일별!$A:$A, ">="&월별!$A9, 일별!$A:$A, "<"&월별!$A10) -> 0 | AG9: =SUMIFS(일별!AE:AE, 일별!$A:$A, ">="&월별!$A9, 일별!$A:$A, "<"&월별!$A10) -> 0 | AH9: =SUMIFS(일별!AF:AF, 일별!$A:$A, ">="&월별!$A9, 일별!$A:$A, "<"&월별!$A10) -> 0 | AI9: =SUMIFS(일별!AG:AG, 일별!$A:$A, ">="&월별!$A9, 일별!$A:$A, "<"&월별!$A10) -> 0 | AJ9: =SUMIFS(일별!AX:AX, 일별!$A:$A, ">="&월별!$A9, 일별!$A:$A, "<"&월별!$A10) -> 0 | AK9: =SUMIFS(일별!AY:AY, 일별!$A:$A, ">="&월별!$A9, 일별!$A:$A, "<"&월별!$A10) -> 0 | AL9: =SUMIFS(일별!AZ:AZ, 일별!$A:$A, ">="&월별!$A9, 일별!$A:$A, "<"&월별!$A10) -> 0 | AM9: =SUMIFS(일별!BA:BA, 일별!$A:$A, ">="&월별!$A9, 일별!$A:$A, "<"&월별!$A10) -> 0 | AN9: =SUMIFS(일별!BB:BB, 일별!$A:$A, ">="&월별!$A9, 일별!$A:$A, "<"&월별!$A10) -> 0 | AO9: =SUMIFS(일별!BC:BC, 일별!$A:$A, ">="&월별!$A9, 일별!$A:$A, "<"&월별!$A10) -> 0 | AP9: {=SUM(_xlfn._xlws.FILTER(일별!BH:CC, (일별!$A:$A >= 월별!$A9) * (일별!$A:$A < 월별!$A10), 0))} -> 0 | AQ9: =AP9/(월별!$A10 - 월별!$A9) -> 0 | AR9: {=SUM(_xlfn._xlws.FILTER(일별!CD:CY, (일별!$A:$A >= 월별!$A9) * (일별!$A:$A < 월별!$A10), 0))} -> 0 | AS9: =AR9/(월별!$A10 - 월별!$A9) -> 0 | AT9: {=SUM(_xlfn._xlws.FILTER(일별!CZ:DU, (일별!$A:$A >= 월별!$A9) * (일별!$A:$A < 월별!$A10), 0))} -> 0 | AU9: =AT9/(월별!$A10 - 월별!$A9) -> 0 | AV9: {=SUM(_xlfn._xlws.FILTER(일별!BH:BH, (일별!$A:$A >= 월별!$A9) * (일별!$A:$A < 월별!$A10), 0))} -> 0 | AW9: {=SUM(_xlfn._xlws.FILTER(일별!BI:BI, (일별!$A:$A >= 월별!$A9) * (일별!$A:$A < 월별!$A10), 0))} -> 0 | AX9: {=SUM(_xlfn._xlws.FILTER(일별!BJ:BJ, (일별!$A:$A >= 월별!$A9) * (일별!$A:$A < 월별!$A10), 0))} -> 0 | AY9: {=SUM(_xlfn._xlws.FILTER(일별!BK:BK, (일별!$A:$A >= 월별!$A9) * (일별!$A:$A < 월별!$A10), 0))} -> 0 | AZ9: {=SUM(_xlfn._xlws.FILTER(일별!BL:BL, (일별!$A:$A >= 월별!$A9) * (일별!$A:$A < 월별!$A10), 0))} -> 0 | BA9: {=SUM(_xlfn._xlws.FILTER(일별!BM:BM, (일별!$A:$A >= 월별!$A9) * (일별!$A:$A < 월별!$A10), 0))} -> 0 | BB9: {=SUM(_xlfn._xlws.FILTER(일별!BN:BN, (일별!$A:$A >= 월별!$A9) * (일별!$A:$A < 월별!$A10), 0))} -> 0 | BC9: {=SUM(_xlfn._xlws.FILTER(일별!BO:BO, (일별!$A:$A >= 월별!$A9) * (일별!$A:$A < 월별!$A10), 0))} -> 0 | BD9: {=SUM(_xlfn._xlws.FILTER(일별!BP:BP, (일별!$A:$A >= 월별!$A9) * (일별!$A:$A < 월별!$A10), 0))} -> 0 | BE9: {=SUM(_xlfn._xlws.FILTER(일별!BQ:BQ, (일별!$A:$A >= 월별!$A9) * (일별!$A:$A < 월별!$A10), 0))} -> 0 | BF9: {=SUM(_xlfn._xlws.FILTER(일별!BR:BR, (일별!$A:$A >= 월별!$A9) * (일별!$A:$A < 월별!$A10), 0))} -> 0 | BG9: {=SUM(_xlfn._xlws.FILTER(일별!BS:BS, (일별!$A:$A >= 월별!$A9) * (일별!$A:$A < 월별!$A10), 0))} -> 0 | BH9: {=SUM(_xlfn._xlws.FILTER(일별!BT:BT, (일별!$A:$A >= 월별!$A9) * (일별!$A:$A < 월별!$A10), 0))} -> 0 | BI9: {=SUM(_xlfn._xlws.FILTER(일별!BU:BU, (일별!$A:$A >= 월별!$A9) * (일별!$A:$A < 월별!$A10), 0))} -> 0 | BJ9: {=SUM(_xlfn._xlws.FILTER(일별!BV:BV, (일별!$A:$A >= 월별!$A9) * (일별!$A:$A < 월별!$A10), 0))} -> 0 | BK9: {=SUM(_xlfn._xlws.FILTER(일별!BW:BW, (일별!$A:$A >= 월별!$A9) * (일별!$A:$A < 월별!$A10), 0))} -> 0 | BL9: {=SUM(_xlfn._xlws.FILTER(일별!BX:BX, (일별!$A:$A >= 월별!$A9) * (일별!$A:$A < 월별!$A10), 0))} -> 0 | BM9: {=SUM(_xlfn._xlws.FILTER(일별!BY:BY, (일별!$A:$A >= 월별!$A9) * (일별!$A:$A < 월별!$A10), 0))} -> 0 | BN9: {=SUM(_xlfn._xlws.FILTER(일별!BZ:BZ, (일별!$A:$A >= 월별!$A9) * (일별!$A:$A < 월별!$A10), 0))} -> 0 | BO9: {=SUM(_xlfn._xlws.FILTER(일별!CA:CA, (일별!$A:$A >= 월별!$A9) * (일별!$A:$A < 월별!$A10), 0))} -> 0 | BP9: {=SUM(_xlfn._xlws.FILTER(일별!CB:CB, (일별!$A:$A >= 월별!$A9) * (일별!$A:$A < 월별!$A10), 0))} -> 0 | BQ9: {=SUM(_xlfn._xlws.FILTER(일별!CC:CC, (일별!$A:$A >= 월별!$A9) * (일별!$A:$A < 월별!$A10), 0))} -> 0 | BR9: {=SUM(_xlfn._xlws.FILTER(일별!CD:CD, (일별!$A:$A >= 월별!$A9) * (일별!$A:$A < 월별!$A10), 0))} -> 0 | BS9: {=SUM(_xlfn._xlws.FILTER(일별!CE:CE, (일별!$A:$A >= 월별!$A9) * (일별!$A:$A < 월별!$A10), 0))} -> 0 | BT9: {=SUM(_xlfn._xlws.FILTER(일별!CF:CF, (일별!$A:$A >= 월별!$A9) * (일별!$A:$A < 월별!$A10), 0))} -> 0 | BU9: {=SUM(_xlfn._xlws.FILTER(일별!CG:CG, (일별!$A:$A >= 월별!$A9) * (일별!$A:$A < 월별!$A10), 0))} -> 0 | BV9: {=SUM(_xlfn._xlws.FILTER(일별!CH:CH, (일별!$A:$A >= 월별!$A9) * (일별!$A:$A < 월별!$A10), 0))} -> 0 | BW9: {=SUM(_xlfn._xlws.FILTER(일별!CI:CI, (일별!$A:$A >= 월별!$A9) * (일별!$A:$A < 월별!$A10), 0))} -> 0 | BX9: {=SUM(_xlfn._xlws.FILTER(일별!CJ:CJ, (일별!$A:$A >= 월별!$A9) * (일별!$A:$A < 월별!$A10), 0))} -> 0 | BY9: {=SUM(_xlfn._xlws.FILTER(일별!CK:CK, (일별!$A:$A >= 월별!$A9) * (일별!$A:$A < 월별!$A10), 0))} -> 0 | BZ9: {=SUM(_xlfn._xlws.FILTER(일별!CL:CL, (일별!$A:$A >= 월별!$A9) * (일별!$A:$A < 월별!$A10), 0))} -> 0 | CA9: {=SUM(_xlfn._xlws.FILTER(일별!CM:CM, (일별!$A:$A >= 월별!$A9) * (일별!$A:$A < 월별!$A10), 0))} -> 0 | CB9: {=SUM(_xlfn._xlws.FILTER(일별!CN:CN, (일별!$A:$A >= 월별!$A9) * (일별!$A:$A < 월별!$A10), 0))} -> 0 | CC9: {=SUM(_xlfn._xlws.FILTER(일별!CO:CO, (일별!$A:$A >= 월별!$A9) * (일별!$A:$A < 월별!$A10), 0))} -> 0 | CD9: {=SUM(_xlfn._xlws.FILTER(일별!CP:CP, (일별!$A:$A >= 월별!$A9) * (일별!$A:$A < 월별!$A10), 0))} -> 0 | CE9: {=SUM(_xlfn._xlws.FILTER(일별!CQ:CQ, (일별!$A:$A >= 월별!$A9) * (일별!$A:$A < 월별!$A10), 0))} -> 0 | CF9: {=SUM(_xlfn._xlws.FILTER(일별!CR:CR, (일별!$A:$A >= 월별!$A9) * (일별!$A:$A < 월별!$A10), 0))} -> 0 | CG9: {=SUM(_xlfn._xlws.FILTER(일별!CS:CS, (일별!$A:$A >= 월별!$A9) * (일별!$A:$A < 월별!$A10), 0))} -> 0 | CH9: {=SUM(_xlfn._xlws.FILTER(일별!CT:CT, (일별!$A:$A >= 월별!$A9) * (일별!$A:$A < 월별!$A10), 0))} -> 0 | CI9: {=SUM(_xlfn._xlws.FILTER(일별!CU:CU, (일별!$A:$A >= 월별!$A9) * (일별!$A:$A < 월별!$A10), 0))} -> 0 | CJ9: {=SUM(_xlfn._xlws.FILTER(일별!CV:CV, (일별!$A:$A >= 월별!$A9) * (일별!$A:$A < 월별!$A10), 0))} -> 0 | CK9: {=SUM(_xlfn._xlws.FILTER(일별!CW:CW, (일별!$A:$A >= 월별!$A9) * (일별!$A:$A < 월별!$A10), 0))} -> 0 | CL9: {=SUM(_xlfn._xlws.FILTER(일별!CX:CX, (일별!$A:$A >= 월별!$A9) * (일별!$A:$A < 월별!$A10), 0))} -> 0 | CM9: {=SUM(_xlfn._xlws.FILTER(일별!CY:CY, (일별!$A:$A >= 월별!$A9) * (일별!$A:$A < 월별!$A10), 0))} -> 0 | CN9: {=SUM(_xlfn._xlws.FILTER(일별!CZ:CZ, (일별!$A:$A >= 월별!$A9) * (일별!$A:$A < 월별!$A10), 0))} -> 0 | CO9: {=SUM(_xlfn._xlws.FILTER(일별!DA:DA, (일별!$A:$A >= 월별!$A9) * (일별!$A:$A < 월별!$A10), 0))} -> 0 | CP9: {=SUM(_xlfn._xlws.FILTER(일별!DB:DB, (일별!$A:$A >= 월별!$A9) * (일별!$A:$A < 월별!$A10), 0))} -> 0 | CQ9: {=SUM(_xlfn._xlws.FILTER(일별!DC:DC, (일별!$A:$A >= 월별!$A9) * (일별!$A:$A < 월별!$A10), 0))} -> 0 | CR9: {=SUM(_xlfn._xlws.FILTER(일별!DD:DD, (일별!$A:$A >= 월별!$A9) * (일별!$A:$A < 월별!$A10), 0))} -> 0 | CS9: {=SUM(_xlfn._xlws.FILTER(일별!DE:DE, (일별!$A:$A >= 월별!$A9) * (일별!$A:$A < 월별!$A10), 0))} -> 0 | CT9: {=SUM(_xlfn._xlws.FILTER(일별!DF:DF, (일별!$A:$A >= 월별!$A9) * (일별!$A:$A < 월별!$A10), 0))} -> 0 | CU9: {=SUM(_xlfn._xlws.FILTER(일별!DG:DG, (일별!$A:$A >= 월별!$A9) * (일별!$A:$A < 월별!$A10), 0))} -> 0 | CV9: {=SUM(_xlfn._xlws.FILTER(일별!DH:DH, (일별!$A:$A >= 월별!$A9) * (일별!$A:$A < 월별!$A10), 0))} -> 0 | CW9: {=SUM(_xlfn._xlws.FILTER(일별!DI:DI, (일별!$A:$A >= 월별!$A9) * (일별!$A:$A < 월별!$A10), 0))} -> 0 | CX9: {=SUM(_xlfn._xlws.FILTER(일별!DJ:DJ, (일별!$A:$A >= 월별!$A9) * (일별!$A:$A < 월별!$A10), 0))} -> 0 | CY9: {=SUM(_xlfn._xlws.FILTER(일별!DK:DK, (일별!$A:$A >= 월별!$A9) * (일별!$A:$A < 월별!$A10), 0))} -> 0 | CZ9: {=SUM(_xlfn._xlws.FILTER(일별!DL:DL, (일별!$A:$A >= 월별!$A9) * (일별!$A:$A < 월별!$A10), 0))} -> 0 | DA9: {=SUM(_xlfn._xlws.FILTER(일별!DM:DM, (일별!$A:$A >= 월별!$A9) * (일별!$A:$A < 월별!$A10), 0))} -> 0 | DB9: {=SUM(_xlfn._xlws.FILTER(일별!DN:DN, (일별!$A:$A >= 월별!$A9) * (일별!$A:$A < 월별!$A10), 0))} -> 0 | DC9: {=SUM(_xlfn._xlws.FILTER(일별!DO:DO, (일별!$A:$A >= 월별!$A9) * (일별!$A:$A < 월별!$A10), 0))} -> 0 | DD9: {=SUM(_xlfn._xlws.FILTER(일별!DP:DP, (일별!$A:$A >= 월별!$A9) * (일별!$A:$A < 월별!$A10), 0))} -> 0 | DE9: {=SUM(_xlfn._xlws.FILTER(일별!DQ:DQ, (일별!$A:$A >= 월별!$A9) * (일별!$A:$A < 월별!$A10), 0))} -> 0 | DF9: {=SUM(_xlfn._xlws.FILTER(일별!DR:DR, (일별!$A:$A >= 월별!$A9) * (일별!$A:$A < 월별!$A10), 0))} -> 0 | DG9: {=SUM(_xlfn._xlws.FILTER(일별!DS:DS, (일별!$A:$A >= 월별!$A9) * (일별!$A:$A < 월별!$A10), 0))} -> 0 | DH9: {=SUM(_xlfn._xlws.FILTER(일별!DT:DT, (일별!$A:$A >= 월별!$A9) * (일별!$A:$A < 월별!$A10), 0))} -> 0 | DI9: {=SUM(_xlfn._xlws.FILTER(일별!DU:DU, (일별!$A:$A >= 월별!$A9) * (일별!$A:$A < 월별!$A10), 0))} -> 0
A10: 46174 | B10: =SUMIFS(일별!$C:$C, 일별!$A:$A, ">="&월별!$A10, 일별!$A:$A, "<"&월별!$A11) -> 0 | C10: =B10/(월별!$A11 - 월별!$A10) -> 0 | D10: =SUMIFS(일별!E:E, 일별!$A:$A, ">="&월별!$A10, 일별!$A:$A, "<"&월별!$A11) -> 0 | E10: =D10/(월별!$A11 - 월별!$A10) -> 0 | F10: =SUMIFS(일별!G:G, 일별!$A:$A, ">="&월별!$A10, 일별!$A:$A, "<"&월별!$A11) -> 0 | G10: =F10/(월별!$A11 - 월별!$A10) -> 0 | H10: =D10+F10 -> 0 | I10: =E10+G10 -> 0 | J10: =SUMIFS(일별!I:I, 일별!$A:$A, ">="&월별!$A10, 일별!$A:$A, "<"&월별!$A11) -> 0 | K10: =J10/(월별!$A11 - 월별!$A10) -> 0 | L10: =SUMIFS(일별!K:K, 일별!$A:$A, ">="&월별!$A10, 일별!$A:$A, "<"&월별!$A11) -> 0 | M10: =L10/(월별!$A11 - 월별!$A10) -> 0 | N10: =SUMIFS(일별!M:M, 일별!$A:$A, ">="&월별!$A10, 일별!$A:$A, "<"&월별!$A11) -> 0 | O10: =N10/(월별!$A11 - 월별!$A10) -> 0 | P10: =SUMIFS(일별!O:O, 일별!$A:$A, ">="&월별!$A10, 일별!$A:$A, "<"&월별!$A11) -> 0 | Q10: =P10/(월별!$A11 - 월별!$A10) -> 0 | R10: =SUMIFS(일별!Q:Q, 일별!$A:$A, ">="&월별!$A10, 일별!$A:$A, "<"&월별!$A11) -> 0 | S10: =R10/(월별!$A11 - 월별!$A10) -> 0 | T10: =SUMIFS(일별!S:S, 일별!$A:$A, ">="&월별!$A10, 일별!$A:$A, "<"&월별!$A11) -> 0 | U10: =T10/(월별!$A11 - 월별!$A10) -> 0 | V10: =SUMIFS(일별!U:U, 일별!$A:$A, ">="&월별!$A10, 일별!$A:$A, "<"&월별!$A11) -> 0 | W10: =V10/(월별!$A11 - 월별!$A10) -> 0 | X10: =SUMIFS(일별!W:W, 일별!$A:$A, ">="&월별!$A10, 일별!$A:$A, "<"&월별!$A11) -> 0 | Y10: =X10/(월별!$A11 - 월별!$A10) -> 0 | Z10: =SUMIFS(일별!X:X, 일별!$A:$A, ">="&월별!$A10, 일별!$A:$A, "<"&월별!$A11) -> 0 | AA10: =SUMIFS(일별!Y:Y, 일별!$A:$A, ">="&월별!$A10, 일별!$A:$A, "<"&월별!$A11) -> 0 | AB10: =SUMIFS(일별!Z:Z, 일별!$A:$A, ">="&월별!$A10, 일별!$A:$A, "<"&월별!$A11) -> 0 | AC10: =SUMIFS(일별!AA:AA, 일별!$A:$A, ">="&월별!$A10, 일별!$A:$A, "<"&월별!$A11) -> 0 | AD10: =SUMIFS(일별!AB:AB, 일별!$A:$A, ">="&월별!$A10, 일별!$A:$A, "<"&월별!$A11) -> 0 | AE10: =SUMIFS(일별!AC:AC, 일별!$A:$A, ">="&월별!$A10, 일별!$A:$A, "<"&월별!$A11) -> 0 | AF10: =SUMIFS(일별!AD:AD, 일별!$A:$A, ">="&월별!$A10, 일별!$A:$A, "<"&월별!$A11) -> 0 | AG10: =SUMIFS(일별!AE:AE, 일별!$A:$A, ">="&월별!$A10, 일별!$A:$A, "<"&월별!$A11) -> 0 | AH10: =SUMIFS(일별!AF:AF, 일별!$A:$A, ">="&월별!$A10, 일별!$A:$A, "<"&월별!$A11) -> 0 | AI10: =SUMIFS(일별!AG:AG, 일별!$A:$A, ">="&월별!$A10, 일별!$A:$A, "<"&월별!$A11) -> 0 | AJ10: =SUMIFS(일별!AX:AX, 일별!$A:$A, ">="&월별!$A10, 일별!$A:$A, "<"&월별!$A11) -> 0 | AK10: =SUMIFS(일별!AY:AY, 일별!$A:$A, ">="&월별!$A10, 일별!$A:$A, "<"&월별!$A11) -> 0 | AL10: =SUMIFS(일별!AZ:AZ, 일별!$A:$A, ">="&월별!$A10, 일별!$A:$A, "<"&월별!$A11) -> 0 | AM10: =SUMIFS(일별!BA:BA, 일별!$A:$A, ">="&월별!$A10, 일별!$A:$A, "<"&월별!$A11) -> 0 | AN10: =SUMIFS(일별!BB:BB, 일별!$A:$A, ">="&월별!$A10, 일별!$A:$A, "<"&월별!$A11) -> 0 | AO10: =SUMIFS(일별!BC:BC, 일별!$A:$A, ">="&월별!$A10, 일별!$A:$A, "<"&월별!$A11) -> 0 | AP10: {=SUM(_xlfn._xlws.FILTER(일별!BH:CC, (일별!$A:$A >= 월별!$A10) * (일별!$A:$A < 월별!$A11), 0))} -> 0 | AQ10: =AP10/(월별!$A11 - 월별!$A10) -> 0 | AR10: {=SUM(_xlfn._xlws.FILTER(일별!CD:CY, (일별!$A:$A >= 월별!$A10) * (일별!$A:$A < 월별!$A11), 0))} -> 0 | AS10: =AR10/(월별!$A11 - 월별!$A10) -> 0 | AT10: {=SUM(_xlfn._xlws.FILTER(일별!CZ:DU, (일별!$A:$A >= 월별!$A10) * (일별!$A:$A < 월별!$A11), 0))} -> 0 | AU10: =AT10/(월별!$A11 - 월별!$A10) -> 0 | AV10: {=SUM(_xlfn._xlws.FILTER(일별!BH:BH, (일별!$A:$A >= 월별!$A10) * (일별!$A:$A < 월별!$A11), 0))} -> 0 | AW10: {=SUM(_xlfn._xlws.FILTER(일별!BI:BI, (일별!$A:$A >= 월별!$A10) * (일별!$A:$A < 월별!$A11), 0))} -> 0 | AX10: {=SUM(_xlfn._xlws.FILTER(일별!BJ:BJ, (일별!$A:$A >= 월별!$A10) * (일별!$A:$A < 월별!$A11), 0))} -> 0 | AY10: {=SUM(_xlfn._xlws.FILTER(일별!BK:BK, (일별!$A:$A >= 월별!$A10) * (일별!$A:$A < 월별!$A11), 0))} -> 0 | AZ10: {=SUM(_xlfn._xlws.FILTER(일별!BL:BL, (일별!$A:$A >= 월별!$A10) * (일별!$A:$A < 월별!$A11), 0))} -> 0 | BA10: {=SUM(_xlfn._xlws.FILTER(일별!BM:BM, (일별!$A:$A >= 월별!$A10) * (일별!$A:$A < 월별!$A11), 0))} -> 0 | BB10: {=SUM(_xlfn._xlws.FILTER(일별!BN:BN, (일별!$A:$A >= 월별!$A10) * (일별!$A:$A < 월별!$A11), 0))} -> 0 | BC10: {=SUM(_xlfn._xlws.FILTER(일별!BO:BO, (일별!$A:$A >= 월별!$A10) * (일별!$A:$A < 월별!$A11), 0))} -> 0 | BD10: {=SUM(_xlfn._xlws.FILTER(일별!BP:BP, (일별!$A:$A >= 월별!$A10) * (일별!$A:$A < 월별!$A11), 0))} -> 0 | BE10: {=SUM(_xlfn._xlws.FILTER(일별!BQ:BQ, (일별!$A:$A >= 월별!$A10) * (일별!$A:$A < 월별!$A11), 0))} -> 0 | BF10: {=SUM(_xlfn._xlws.FILTER(일별!BR:BR, (일별!$A:$A >= 월별!$A10) * (일별!$A:$A < 월별!$A11), 0))} -> 0 | BG10: {=SUM(_xlfn._xlws.FILTER(일별!BS:BS, (일별!$A:$A >= 월별!$A10) * (일별!$A:$A < 월별!$A11), 0))} -> 0 | BH10: {=SUM(_xlfn._xlws.FILTER(일별!BT:BT, (일별!$A:$A >= 월별!$A10) * (일별!$A:$A < 월별!$A11), 0))} -> 0 | BI10: {=SUM(_xlfn._xlws.FILTER(일별!BU:BU, (일별!$A:$A >= 월별!$A10) * (일별!$A:$A < 월별!$A11), 0))} -> 0 | BJ10: {=SUM(_xlfn._xlws.FILTER(일별!BV:BV, (일별!$A:$A >= 월별!$A10) * (일별!$A:$A < 월별!$A11), 0))} -> 0 | BK10: {=SUM(_xlfn._xlws.FILTER(일별!BW:BW, (일별!$A:$A >= 월별!$A10) * (일별!$A:$A < 월별!$A11), 0))} -> 0 | BL10: {=SUM(_xlfn._xlws.FILTER(일별!BX:BX, (일별!$A:$A >= 월별!$A10) * (일별!$A:$A < 월별!$A11), 0))} -> 0 | BM10: {=SUM(_xlfn._xlws.FILTER(일별!BY:BY, (일별!$A:$A >= 월별!$A10) * (일별!$A:$A < 월별!$A11), 0))} -> 0 | BN10: {=SUM(_xlfn._xlws.FILTER(일별!BZ:BZ, (일별!$A:$A >= 월별!$A10) * (일별!$A:$A < 월별!$A11), 0))} -> 0 | BO10: {=SUM(_xlfn._xlws.FILTER(일별!CA:CA, (일별!$A:$A >= 월별!$A10) * (일별!$A:$A < 월별!$A11), 0))} -> 0 | BP10: {=SUM(_xlfn._xlws.FILTER(일별!CB:CB, (일별!$A:$A >= 월별!$A10) * (일별!$A:$A < 월별!$A11), 0))} -> 0 | BQ10: {=SUM(_xlfn._xlws.FILTER(일별!CC:CC, (일별!$A:$A >= 월별!$A10) * (일별!$A:$A < 월별!$A11), 0))} -> 0 | BR10: {=SUM(_xlfn._xlws.FILTER(일별!CD:CD, (일별!$A:$A >= 월별!$A10) * (일별!$A:$A < 월별!$A11), 0))} -> 0 | BS10: {=SUM(_xlfn._xlws.FILTER(일별!CE:CE, (일별!$A:$A >= 월별!$A10) * (일별!$A:$A < 월별!$A11), 0))} -> 0 | BT10: {=SUM(_xlfn._xlws.FILTER(일별!CF:CF, (일별!$A:$A >= 월별!$A10) * (일별!$A:$A < 월별!$A11), 0))} -> 0 | BU10: {=SUM(_xlfn._xlws.FILTER(일별!CG:CG, (일별!$A:$A >= 월별!$A10) * (일별!$A:$A < 월별!$A11), 0))} -> 0 | BV10: {=SUM(_xlfn._xlws.FILTER(일별!CH:CH, (일별!$A:$A >= 월별!$A10) * (일별!$A:$A < 월별!$A11), 0))} -> 0 | BW10: {=SUM(_xlfn._xlws.FILTER(일별!CI:CI, (일별!$A:$A >= 월별!$A10) * (일별!$A:$A < 월별!$A11), 0))} -> 0 | BX10: {=SUM(_xlfn._xlws.FILTER(일별!CJ:CJ, (일별!$A:$A >= 월별!$A10) * (일별!$A:$A < 월별!$A11), 0))} -> 0 | BY10: {=SUM(_xlfn._xlws.FILTER(일별!CK:CK, (일별!$A:$A >= 월별!$A10) * (일별!$A:$A < 월별!$A11), 0))} -> 0 | BZ10: {=SUM(_xlfn._xlws.FILTER(일별!CL:CL, (일별!$A:$A >= 월별!$A10) * (일별!$A:$A < 월별!$A11), 0))} -> 0 | CA10: {=SUM(_xlfn._xlws.FILTER(일별!CM:CM, (일별!$A:$A >= 월별!$A10) * (일별!$A:$A < 월별!$A11), 0))} -> 0 | CB10: {=SUM(_xlfn._xlws.FILTER(일별!CN:CN, (일별!$A:$A >= 월별!$A10) * (일별!$A:$A < 월별!$A11), 0))} -> 0 | CC10: {=SUM(_xlfn._xlws.FILTER(일별!CO:CO, (일별!$A:$A >= 월별!$A10) * (일별!$A:$A < 월별!$A11), 0))} -> 0 | CD10: {=SUM(_xlfn._xlws.FILTER(일별!CP:CP, (일별!$A:$A >= 월별!$A10) * (일별!$A:$A < 월별!$A11), 0))} -> 0 | CE10: {=SUM(_xlfn._xlws.FILTER(일별!CQ:CQ, (일별!$A:$A >= 월별!$A10) * (일별!$A:$A < 월별!$A11), 0))} -> 0 | CF10: {=SUM(_xlfn._xlws.FILTER(일별!CR:CR, (일별!$A:$A >= 월별!$A10) * (일별!$A:$A < 월별!$A11), 0))} -> 0 | CG10: {=SUM(_xlfn._xlws.FILTER(일별!CS:CS, (일별!$A:$A >= 월별!$A10) * (일별!$A:$A < 월별!$A11), 0))} -> 0 | CH10: {=SUM(_xlfn._xlws.FILTER(일별!CT:CT, (일별!$A:$A >= 월별!$A10) * (일별!$A:$A < 월별!$A11), 0))} -> 0 | CI10: {=SUM(_xlfn._xlws.FILTER(일별!CU:CU, (일별!$A:$A >= 월별!$A10) * (일별!$A:$A < 월별!$A11), 0))} -> 0 | CJ10: {=SUM(_xlfn._xlws.FILTER(일별!CV:CV, (일별!$A:$A >= 월별!$A10) * (일별!$A:$A < 월별!$A11), 0))} -> 0 | CK10: {=SUM(_xlfn._xlws.FILTER(일별!CW:CW, (일별!$A:$A >= 월별!$A10) * (일별!$A:$A < 월별!$A11), 0))} -> 0 | CL10: {=SUM(_xlfn._xlws.FILTER(일별!CX:CX, (일별!$A:$A >= 월별!$A10) * (일별!$A:$A < 월별!$A11), 0))} -> 0 | CM10: {=SUM(_xlfn._xlws.FILTER(일별!CY:CY, (일별!$A:$A >= 월별!$A10) * (일별!$A:$A < 월별!$A11), 0))} -> 0 | CN10: {=SUM(_xlfn._xlws.FILTER(일별!CZ:CZ, (일별!$A:$A >= 월별!$A10) * (일별!$A:$A < 월별!$A11), 0))} -> 0 | CO10: {=SUM(_xlfn._xlws.FILTER(일별!DA:DA, (일별!$A:$A >= 월별!$A10) * (일별!$A:$A < 월별!$A11), 0))} -> 0 | CP10: {=SUM(_xlfn._xlws.FILTER(일별!DB:DB, (일별!$A:$A >= 월별!$A10) * (일별!$A:$A < 월별!$A11), 0))} -> 0 | CQ10: {=SUM(_xlfn._xlws.FILTER(일별!DC:DC, (일별!$A:$A >= 월별!$A10) * (일별!$A:$A < 월별!$A11), 0))} -> 0 | CR10: {=SUM(_xlfn._xlws.FILTER(일별!DD:DD, (일별!$A:$A >= 월별!$A10) * (일별!$A:$A < 월별!$A11), 0))} -> 0 | CS10: {=SUM(_xlfn._xlws.FILTER(일별!DE:DE, (일별!$A:$A >= 월별!$A10) * (일별!$A:$A < 월별!$A11), 0))} -> 0 | CT10: {=SUM(_xlfn._xlws.FILTER(일별!DF:DF, (일별!$A:$A >= 월별!$A10) * (일별!$A:$A < 월별!$A11), 0))} -> 0 | CU10: {=SUM(_xlfn._xlws.FILTER(일별!DG:DG, (일별!$A:$A >= 월별!$A10) * (일별!$A:$A < 월별!$A11), 0))} -> 0 | CV10: {=SUM(_xlfn._xlws.FILTER(일별!DH:DH, (일별!$A:$A >= 월별!$A10) * (일별!$A:$A < 월별!$A11), 0))} -> 0 | CW10: {=SUM(_xlfn._xlws.FILTER(일별!DI:DI, (일별!$A:$A >= 월별!$A10) * (일별!$A:$A < 월별!$A11), 0))} -> 0 | CX10: {=SUM(_xlfn._xlws.FILTER(일별!DJ:DJ, (일별!$A:$A >= 월별!$A10) * (일별!$A:$A < 월별!$A11), 0))} -> 0 | CY10: {=SUM(_xlfn._xlws.FILTER(일별!DK:DK, (일별!$A:$A >= 월별!$A10) * (일별!$A:$A < 월별!$A11), 0))} -> 0 | CZ10: {=SUM(_xlfn._xlws.FILTER(일별!DL:DL, (일별!$A:$A >= 월별!$A10) * (일별!$A:$A < 월별!$A11), 0))} -> 0 | DA10: {=SUM(_xlfn._xlws.FILTER(일별!DM:DM, (일별!$A:$A >= 월별!$A10) * (일별!$A:$A < 월별!$A11), 0))} -> 0 | DB10: {=SUM(_xlfn._xlws.FILTER(일별!DN:DN, (일별!$A:$A >= 월별!$A10) * (일별!$A:$A < 월별!$A11), 0))} -> 0 | DC10: {=SUM(_xlfn._xlws.FILTER(일별!DO:DO, (일별!$A:$A >= 월별!$A10) * (일별!$A:$A < 월별!$A11), 0))} -> 0 | DD10: {=SUM(_xlfn._xlws.FILTER(일별!DP:DP, (일별!$A:$A >= 월별!$A10) * (일별!$A:$A < 월별!$A11), 0))} -> 0 | DE10: {=SUM(_xlfn._xlws.FILTER(일별!DQ:DQ, (일별!$A:$A >= 월별!$A10) * (일별!$A:$A < 월별!$A11), 0))} -> 0 | DF10: {=SUM(_xlfn._xlws.FILTER(일별!DR:DR, (일별!$A:$A >= 월별!$A10) * (일별!$A:$A < 월별!$A11), 0))} -> 0 | DG10: {=SUM(_xlfn._xlws.FILTER(일별!DS:DS, (일별!$A:$A >= 월별!$A10) * (일별!$A:$A < 월별!$A11), 0))} -> 0 | DH10: {=SUM(_xlfn._xlws.FILTER(일별!DT:DT, (일별!$A:$A >= 월별!$A10) * (일별!$A:$A < 월별!$A11), 0))} -> 0 | DI10: {=SUM(_xlfn._xlws.FILTER(일별!DU:DU, (일별!$A:$A >= 월별!$A10) * (일별!$A:$A < 월별!$A11), 0))} -> 0
